Workbook

Sheet 00_Summary
A1: AI Finance Forum mockup - QC summary
A2: Reviewed 28 July 2026 against the live API. 47 findings raised, 62 calculations reconciled, 31 manual tests to run.
A3: All counts below recalculate from 01_Findings. Update that sheet and this page follows.
A5: Headline
A6: Total findings | D6: Demo blockers | G6: Critical | J6: Still open
A7: =COUNTA('01_Findings'!$F$5:$F$66) | D7: =COUNTIF('01_Findings'!$G$5:$G$66,"Yes") | G7: =COUNTIF('01_Findings'!$F$5:$F$66,"Critical") | J7: =COUNTIF('01_Findings'!$N$5:$N$66,"Open")
A8: of 47 | D8: of 47 | G8: of 47 | J8: of 47
A10: By severity | G10: By agent
A11: Severity | B11: Total | C11: Blockers | D11: Open | E11: Closed | G11: Agent | H11: Total | I11: Blockers | J11: Open
A12: Critical | B12: =COUNTIF('01_Findings'!$F$5:$F$66,A12) | C12: =COUNTIFS('01_Findings'!$F$5:$F$66,A12,'01_Findings'!$G$5:$G$66,"Yes") | D12: =COUNTIFS('01_Findings'!$F$5:$F$66,A12,'01_Findings'!$N$5:$N$66,"Open") | E12: =COUNTIFS('01_Findings'!$F$5:$F$66,A12,'01_Findings'!$N$5:$N$66,"Closed") | G12: Finance | H12: =COUNTIF('01_Findings'!$C$5:$C$66,G12) | I12: =COUNTIFS('01_Findings'!$C$5:$C$66,G12,'01_Findings'!$G$5:$G$66,"Yes") | J12: =COUNTIFS('01_Findings'!$C$5:$C$66,G12,'01_Findings'!$N$5:$N$66,"Open")
A13: High | B13: =COUNTIF('01_Findings'!$F$5:$F$66,A13) | C13: =COUNTIFS('01_Findings'!$F$5:$F$66,A13,'01_Findings'!$G$5:$G$66,"Yes") | D13: =COUNTIFS('01_Findings'!$F$5:$F$66,A13,'01_Findings'!$N$5:$N$66,"Open") | E13: =COUNTIFS('01_Findings'!$F$5:$F$66,A13,'01_Findings'!$N$5:$N$66,"Closed") | G13: Collection | H13: =COUNTIF('01_Findings'!$C$5:$C$66,G13) | I13: =COUNTIFS('01_Findings'!$C$5:$C$66,G13,'01_Findings'!$G$5:$G$66,"Yes") | J13: =COUNTIFS('01_Findings'!$C$5:$C$66,G13,'01_Findings'!$N$5:$N$66,"Open")
A14: Medium | B14: =COUNTIF('01_Findings'!$F$5:$F$66,A14) | C14: =COUNTIFS('01_Findings'!$F$5:$F$66,A14,'01_Findings'!$G$5:$G$66,"Yes") | D14: =COUNTIFS('01_Findings'!$F$5:$F$66,A14,'01_Findings'!$N$5:$N$66,"Open") | E14: =COUNTIFS('01_Findings'!$F$5:$F$66,A14,'01_Findings'!$N$5:$N$66,"Closed") | G14: Leakage | H14: =COUNTIF('01_Findings'!$C$5:$C$66,G14) | I14: =COUNTIFS('01_Findings'!$C$5:$C$66,G14,'01_Findings'!$G$5:$G$66,"Yes") | J14: =COUNTIFS('01_Findings'!$C$5:$C$66,G14,'01_Findings'!$N$5:$N$66,"Open")
A15: Low | B15: =COUNTIF('01_Findings'!$F$5:$F$66,A15) | C15: =COUNTIFS('01_Findings'!$F$5:$F$66,A15,'01_Findings'!$G$5:$G$66,"Yes") | D15: =COUNTIFS('01_Findings'!$F$5:$F$66,A15,'01_Findings'!$N$5:$N$66,"Open") | E15: =COUNTIFS('01_Findings'!$F$5:$F$66,A15,'01_Findings'!$N$5:$N$66,"Closed") | G15: Treasury | H15: =COUNTIF('01_Findings'!$C$5:$C$66,G15) | I15: =COUNTIFS('01_Findings'!$C$5:$C$66,G15,'01_Findings'!$G$5:$G$66,"Yes") | J15: =COUNTIFS('01_Findings'!$C$5:$C$66,G15,'01_Findings'!$N$5:$N$66,"Open")
A16: Total | B16: =SUM(B12:B15) | C16: =SUM(C12:C15) | D16: =SUM(D12:D15) | E16: =SUM(E12:E15) | G16: All | H16: =COUNTIF('01_Findings'!$C$5:$C$66,G16) | I16: =COUNTIFS('01_Findings'!$C$5:$C$66,G16,'01_Findings'!$G$5:$G$66,"Yes") | J16: =COUNTIFS('01_Findings'!$C$5:$C$66,G16,'01_Findings'!$N$5:$N$66,"Open")
G17: Finance + Collection | H17: =COUNTIF('01_Findings'!$C$5:$C$66,G17) | I17: =COUNTIFS('01_Findings'!$C$5:$C$66,G17,'01_Findings'!$G$5:$G$66,"Yes") | J17: =COUNTIFS('01_Findings'!$C$5:$C$66,G17,'01_Findings'!$N$5:$N$66,"Open")
G18: Collection + Treasury | H18: =COUNTIF('01_Findings'!$C$5:$C$66,G18) | I18: =COUNTIFS('01_Findings'!$C$5:$C$66,G18,'01_Findings'!$G$5:$G$66,"Yes") | J18: =COUNTIFS('01_Findings'!$C$5:$C$66,G18,'01_Findings'!$N$5:$N$66,"Open")
A19: By QC area from the brief
A20: QC area | B20: Total | C20: Blockers | D20: Open
A21: a. Formula consistency | B21: =COUNTIF('01_Findings'!$D$5:$D$66,A21) | C21: =COUNTIFS('01_Findings'!$D$5:$D$66,A21,'01_Findings'!$G$5:$G$66,"Yes") | D21: =COUNTIFS('01_Findings'!$D$5:$D$66,A21,'01_Findings'!$N$5:$N$66,"Open")
A22: b. Chart accuracy | B22: =COUNTIF('01_Findings'!$D$5:$D$66,A22) | C22: =COUNTIFS('01_Findings'!$D$5:$D$66,A22,'01_Findings'!$G$5:$G$66,"Yes") | D22: =COUNTIFS('01_Findings'!$D$5:$D$66,A22,'01_Findings'!$N$5:$N$66,"Open")
A23: c. Button / menu / function | B23: =COUNTIF('01_Findings'!$D$5:$D$66,A23) | C23: =COUNTIFS('01_Findings'!$D$5:$D$66,A23,'01_Findings'!$G$5:$G$66,"Yes") | D23: =COUNTIFS('01_Findings'!$D$5:$D$66,A23,'01_Findings'!$N$5:$N$66,"Open")
A24: d. Prompt & response | B24: =COUNTIF('01_Findings'!$D$5:$D$66,A24) | C24: =COUNTIFS('01_Findings'!$D$5:$D$66,A24,'01_Findings'!$G$5:$G$66,"Yes") | D24: =COUNTIFS('01_Findings'!$D$5:$D$66,A24,'01_Findings'!$N$5:$N$66,"Open")
A25: f. Dataset | B25: =COUNTIF('01_Findings'!$D$5:$D$66,A25) | C25: =COUNTIFS('01_Findings'!$D$5:$D$66,A25,'01_Findings'!$G$5:$G$66,"Yes") | D25: =COUNTIFS('01_Findings'!$D$5:$D$66,A25,'01_Findings'!$N$5:$N$66,"Open")
A26: g. Filters | B26: =COUNTIF('01_Findings'!$D$5:$D$66,A26) | C26: =COUNTIFS('01_Findings'!$D$5:$D$66,A26,'01_Findings'!$G$5:$G$66,"Yes") | D26: =COUNTIFS('01_Findings'!$D$5:$D$66,A26,'01_Findings'!$N$5:$N$66,"Open")
A29: Progress
A30: Status | B30: Count | C30: % of all
A31: Terbuka | B31: =COUNTIF('01B_Findings_ID'!$N$5:$N$66,A31) | C31: =IFERROR(B31/COUNTA('01_Findings'!$F$5:$F$66),0)
A32: Sedang dikerjakan | B32: =COUNTIF('01B_Findings_ID'!$N$5:$N$66,A32) | C32: =IFERROR(B32/COUNTA('01_Findings'!$F$5:$F$66),0)
A33: Sudah diperbaiki - menunggu uji ulang | B33: =COUNTIF('01B_Findings_ID'!$N$5:$N$66,A33) | C33: =IFERROR(B33/COUNTA('01_Findings'!$F$5:$F$66),0)
A34: Uji ulang lulus | B34: =COUNTIF('01B_Findings_ID'!$N$5:$N$66,A34) | C34: =IFERROR(B34/COUNTA('01_Findings'!$F$5:$F$66),0)
A35: Selesai | B35: =COUNTIF('01B_Findings_ID'!$N$5:$N$66,A35) | C35: =IFERROR(B35/COUNTA('01_Findings'!$F$5:$F$66),0)
A36: Ditunda | B36: =COUNTIF('01B_Findings_ID'!$N$5:$N$66,A36) | C36: =IFERROR(B36/COUNTA('01_Findings'!$F$5:$F$66),0)
A37: Bukan cacat | B37: =COUNTIF('01B_Findings_ID'!$N$5:$N$66,A37) | C37: =IFERROR(B37/COUNTA('01_Findings'!$F$5:$F$66),0)
A38: Blockers cleared | B38: =COUNTIFS('01B_Findings_ID'!$G$5:$G$66,"Ya",'01B_Findings_ID'!$N$5:$N$66,"Selesai")+COUNTIFS('01B_Findings_ID'!$G$5:$G$66,"Ya",'01B_Findings_ID'!$N$5:$N$66,"Uji ulang lulus") | C38: =IFERROR(B38/COUNTIF('01_Findings'!$G$5:$G$66,"Yes"),0)
A39: Demo ready when this reaches 100%
A42: How to use this workbook
A43: 01_Findings every defect, with evidence, expected behaviour, likely root cause, owner, target date and status. Yellow columns are QC Tester result to fill in.
A44: 02_Manual_Test_Checklist 31 tests from outside the app. Buttons, menus, sliders, chat and stability. Run these before the event.
A45: 03_Formula_Checks every calculation that reconciled, including the ones that PASS or FAIL.
A46: 04_Dataset_Requirements the client's data volumes against what the mockup has, and where the replacement sits.
...

Sheet 0A_Cari_Cepat
A1: Cari cepat temuan QC
A2: Ketik atau pilih nomor QC di kotak kuning. Seluruh detailnya muncul di bawah. Daftar ringkas semua temuan ada di sebelah kanan.
E4: Daftar ringkas 47 temuan
A5: Nomor QC | B5: QC-062 | C5: =IF(COUNTIF('01_Findings'!$A$5:$A$66,$B$5)=0,"Nomor tidak ada. Isi antara QC-001 sampai QC-047.","Ditemukan di 01_Findings baris "&(MATCH($B$5,'01_Findings'!$A$5:$A$66,0)+4)) | E5: No QC | F5: Tingkat | G5: Blocker | H5: Agent | I5: Judul temuan
E6: ='01B_Findings_ID'!A5 | F6: ='01B_Findings_ID'!F5 | G6: ='01B_Findings_ID'!G5 | H6: ='01B_Findings_ID'!C5 | I6: ='01B_Findings_ID'!H5
A7: Ringkasan | E7: ='01B_Findings_ID'!A6 | F7: ='01B_Findings_ID'!F6 | G7: ='01B_Findings_ID'!G6 | H7: ='01B_Findings_ID'!C6 | I7: ='01B_Findings_ID'!H6
B8: Bahasa Indonesia | C8: English | E8: ='01B_Findings_ID'!A7 | F8: ='01B_Findings_ID'!F7 | G8: ='01B_Findings_ID'!G7 | H8: ='01B_Findings_ID'!C7 | I8: ='01B_Findings_ID'!H7
A9: Tingkat keparahan | B9: =IFERROR(INDEX('01B_Findings_ID'!$F$5:$F$66,MATCH($B$5,'01B_Findings_ID'!$A$5:$A$66,0)),"tidak ditemukan") | C9: =IFERROR(INDEX('01_Findings'!$F$5:$F$66,MATCH($B$5,'01_Findings'!$A$5:$A$66,0)),"tidak ditemukan") | E9: ='01B_Findings_ID'!A8 | F9: ='01B_Findings_ID'!F8 | G9: ='01B_Findings_ID'!G8 | H9: ='01B_Findings_ID'!C8 | I9: ='01B_Findings_ID'!H8
A10: Penghambat demo | B10: =IFERROR(INDEX('01B_Findings_ID'!$G$5:$G$66,MATCH($B$5,'01B_Findings_ID'!$A$5:$A$66,0)),"tidak ditemukan") | C10: =IFERROR(INDEX('01_Findings'!$G$5:$G$66,MATCH($B$5,'01_Findings'!$A$5:$A$66,0)),"tidak ditemukan") | E10: ='01B_Findings_ID'!A9 | F10: ='01B_Findings_ID'!F9 | G10: ='01B_Findings_ID'!G9 | H10: ='01B_Findings_ID'!C9 | I10: ='01B_Findings_ID'!H9
A11: Agent | B11: =IFERROR(INDEX('01B_Findings_ID'!$C$5:$C$66,MATCH($B$5,'01B_Findings_ID'!$A$5:$A$66,0)),"tidak ditemukan") | C11: =IFERROR(INDEX('01_Findings'!$C$5:$C$66,MATCH($B$5,'01_Findings'!$A$5:$A$66,0)),"tidak ditemukan") | E11: ='01B_Findings_ID'!A10 | F11: ='01B_Findings_ID'!F10 | G11: ='01B_Findings_ID'!G10 | H11: ='01B_Findings_ID'!C10 | I11: ='01B_Findings_ID'!H10
A12: Area QC | B12: =IFERROR(INDEX('01B_Findings_ID'!$D$5:$D$66,MATCH($B$5,'01B_Findings_ID'!$A$5:$A$66,0)),"tidak ditemukan") | C12: =IFERROR(INDEX('01_Findings'!$D$5:$D$66,MATCH($B$5,'01_Findings'!$A$5:$A$66,0)),"tidak ditemukan") | E12: ='01B_Findings_ID'!A11 | F12: ='01B_Findings_ID'!F11 | G12: ='01B_Findings_ID'!G11 | H12: ='01B_Findings_ID'!C11 | I12: ='01B_Findings_ID'!H11
A13: Jenis | B13: =IFERROR(INDEX('01B_Findings_ID'!$E$5:$E$66,MATCH($B$5,'01B_Findings_ID'!$A$5:$A$66,0)),"tidak ditemukan") | C13: =IFERROR(INDEX('01_Findings'!$E$5:$E$66,MATCH($B$5,'01_Findings'!$A$5:$A$66,0)),"tidak ditemukan") | E13: ='01B_Findings_ID'!A12 | F13: ='01B_Findings_ID'!F12 | G13: ='01B_Findings_ID'!G12 | H13: ='01B_Findings_ID'!C12 | I13: ='01B_Findings_ID'!H12
A14: Penanggung jawab | B14: =IFERROR(INDEX('01B_Findings_ID'!$L$5:$L$66,MATCH($B$5,'01B_Findings_ID'!$A$5:$A$66,0)),"tidak ditemukan") | C14: =IFERROR(INDEX('01_Findings'!$L$5:$L$66,MATCH($B$5,'01_Findings'!$A$5:$A$66,0)),"tidak ditemukan") | E14: ='01B_Findings_ID'!A13 | F14: ='01B_Findings_ID'!F13 | G14: ='01B_Findings_ID'!G13 | H14: ='01B_Findings_ID'!C13 | I14: ='01B_Findings_ID'!H13
A15: Target selesai | B15: =IFERROR(INDEX('01B_Findings_ID'!$M$5:$M$66,MATCH($B$5,'01B_Findings_ID'!$A$5:$A$66,0)),"tidak ditemukan") | C15: =IFERROR(INDEX('01_Findings'!$M$5:$M$66,MATCH($B$5,'01_Findings'!$A$5:$A$66,0)),"tidak ditemukan") | E15: ='01B_Findings_ID'!A14 | F15: ='01B_Findings_ID'!F14 | G15: ='01B_Findings_ID'!G14 | H15: ='01B_Findings_ID'!C14 | I15: ='01B_Findings_ID'!H14
A16: Status | B16: =IFERROR(INDEX('01B_Findings_ID'!$N$5:$N$66,MATCH($B$5,'01B_Findings_ID'!$A$5:$A$66,0)),"tidak ditemukan") | C16: =IFERROR(INDEX('01_Findings'!$N$5:$N$66,MATCH($B$5,'01_Findings'!$A$5:$A$66,0)),"tidak ditemukan") | E16: ='01B_Findings_ID'!A15 | F16: ='01B_Findings_ID'!F15 | G16: ='01B_Findings_ID'!G15 | H16: ='01B_Findings_ID'!C15 | I16: ='01B_Findings_ID'!H15
A17: Rincian | E17: ='01B_Findings_ID'!A16 | F17: ='01B_Findings_ID'!F16 | G17: ='01B_Findings_ID'!G16 | H17: ='01B_Findings_ID'!C16 | I17: ='01B_Findings_ID'!H16
A18: Temuan | B18: =IFERROR(INDEX('01B_Findings_ID'!$H$5:$H$66,MATCH($B$5,'01B_Findings_ID'!$A$5:$A$66,0)),"tidak ditemukan") | C18: =IFERROR(INDEX('01_Findings'!$H$5:$H$66,MATCH($B$5,'01_Findings'!$A$5:$A$66,0)),"tidak ditemukan") | E18: ='01B_Findings_ID'!A17 | F18: ='01B_Findings_ID'!F17 | G18: ='01B_Findings_ID'!G17 | H18: ='01B_Findings_ID'!C17 | I18: ='01B_Findings_ID'!H17
A19: Bukti yang ditemukan | B19: =IFERROR(INDEX('01B_Findings_ID'!$I$5:$I$66,MATCH($B$5,'01B_Findings_ID'!$A$5:$A$66,0)),"tidak ditemukan") | C19: =IFERROR(INDEX('01_Findings'!$I$5:$I$66,MATCH($B$5,'01_Findings'!$A$5:$A$66,0)),"tidak ditemukan") | E19: ='01B_Findings_ID'!A18 | F19: ='01B_Findings_ID'!F18 | G19: ='01B_Findings_ID'!G18 | H19: ='01B_Findings_ID'!C18 | I19: ='01B_Findings_ID'!H18
A20: Perilaku yang seharusnya | B20: =IFERROR(INDEX('01B_Findings_ID'!$J$5:$J$66,MATCH($B$5,'01B_Findings_ID'!$A$5:$A$66,0)),"tidak ditemukan") | C20: =IFERROR(INDEX('01_Findings'!$J$5:$J$66,MATCH($B$5,'01_Findings'!$A$5:$A$66,0)),"tidak ditemukan") | E20: ='01B_Findings_ID'!A19 | F20: ='01B_Findings_ID'!F19 | G20: ='01B_Findings_ID'!G19 | H20: ='01B_Findings_ID'!C19 | I20: ='01B_Findings_ID'!H19
A21: Dugaan akar masalah | B21: =IFERROR(INDEX('01B_Findings_ID'!$K$5:$K$66,MATCH($B$5,'01B_Findings_ID'!$A$5:$A$66,0)),"tidak ditemukan") | C21: =IFERROR(INDEX('01_Findings'!$K$5:$K$66,MATCH($B$5,'01_Findings'!$A$5:$A$66,0)),"tidak ditemukan") | E21: ='01B_Findings_ID'!A20 | F21: ='01B_Findings_ID'!F20 | G21: ='01B_Findings_ID'!G20 | H21: ='01B_Findings_ID'!C20 | I21: ='01B_Findings_ID'!H20
E22: ='01B_Findings_ID'!A21 | F22: ='01B_Findings_ID'!F21 | G22: ='01B_Findings_ID'!G21 | H22: ='01B_Findings_ID'!C21 | I22: ='01B_Findings_ID'!H21
A23: Pemeriksaan formula terkait | E23: ='01B_Findings_ID'!A22 | F23: ='01B_Findings_ID'!F22 | G23: ='01B_Findings_ID'!G22 | H23: ='01B_Findings_ID'!C22 | I23: ='01B_Findings_ID'!H22
A24: Perhitungan | B24: =IFERROR(INDEX('03_Formula_Checks'!$D$5:$D$66,MATCH($B$5,'03_Formula_Checks'!$G$5:$G$66,0)),"tidak ada pemeriksaan formula untuk nomor ini") | E24: ='01B_Findings_ID'!A23 | F24: ='01B_Findings_ID'!F23 | G24: ='01B_Findings_ID'!G23 | H24: ='01B_Findings_ID'!C23 | I24: ='01B_Findings_ID'!H23
A25: Hasil di aplikasi | B25: =IFERROR(INDEX('03_Formula_Checks'!$E$5:$E$66,MATCH($B$5,'03_Formula_Checks'!$G$5:$G$66,0)),"-") | E25: ='01B_Findings_ID'!A24 | F25: ='01B_Findings_ID'!F24 | G25: ='01B_Findings_ID'!G24 | H25: ='01B_Findings_ID'!C24 | I25: ='01B_Findings_ID'!H24
A26: Verdict | B26: =IFERROR(INDEX('03_Formula_Checks'!$F$5:$F$66,MATCH($B$5,'03_Formula_Checks'!$G$5:$G$66,0)),"-") | E26: ='01B_Findings_ID'!A25 | F26: ='01B_Findings_ID'!F25 | G26: ='01B_Findings_ID'!G25 | H26: ='01B_Findings_ID'!C25 | I26: ='01B_Findings_ID'!H25
E27: ='01B_Findings_ID'!A26 | F27: ='01B_Findings_ID'!F26 | G27: ='01B_Findings_ID'!G26 | H27: ='01B_Findings_ID'!C26 | I27: ='01B_Findings_ID'!H26
E28: ='01B_Findings_ID'!A27 | F28: ='01B_Findings_ID'!F27 | G28: ='01B_Findings_ID'!G27 | H28: ='01B_Findings_ID'!C27 | I28: ='01B_Findings_ID'!H27
A29: Catatan | E29: ='01B_Findings_ID'!A28 | F29: ='01B_Findings_ID'!F28 | G29: ='01B_Findings_ID'!G28 | H29: ='01B_Findings_ID'!C28 | I29: ='01B_Findings_ID'!H28
A30: Kalau kolom B dan C berbunyi 'tidak ditemukan', berarti nomor QC-nya salah ketik. Gunakan daftar di sebelah kanan. | E30: ='01B_Findings_ID'!A29 | F30: ='01B_Findings_ID'!F29 | G30: ='01B_Findings_ID'!G29 | H30: ='01B_Findings_ID'!C29 | I30: ='01B_Findings_ID'!H29
A31: Temuan yang tidak punya pemeriksaan formula akan menampilkan 'tidak ada pemeriksaan formula untuk nomor ini'. Itu normal, tidak semua temuan berupa hitungan. | E31: ='01B_Findings_ID'!A30 | F31: ='01B_Findings_ID'!F30 | G31: ='01B_Findings_ID'!G30 | H31: ='01B_Findings_ID'!C30 | I31: ='01B_Findings_ID'!H30
E32: ='01B_Findings_ID'!A31 | F32: ='01B_Findings_ID'!F31 | G32: ='01B_Findings_ID'!G31 | H32: ='01B_Findings_ID'!C31 | I32: ='01B_Findings_ID'!H31
E33: ='01B_Findings_ID'!A32 | F33: ='01B_Findings_ID'!F32 | G33: ='01B_Findings_ID'!G32 | H33: ='01B_Findings_ID'!C32 | I33: ='01B_Findings_ID'!H32
E34: ='01B_Findings_ID'!A33 | F34: ='01B_Findings_ID'!F33 | G34: ='01B_Findings_ID'!G33 | H34: ='01B_Findings_ID'!C33 | I34: ='01B_Findings_ID'!H33
E35: ='01B_Findings_ID'!A34 | F35: ='01B_Findings_ID'!F34 | G35: ='01B_Findings_ID'!G34 | H35: ='01B_Findings_ID'!C34 | I35: ='01B_Findings_ID'!H34
E36: ='01B_Findings_ID'!A35 | F36: ='01B_Findings_ID'!F35 | G36: ='01B_Findings_ID'!G35 | H36: ='01B_Findings_ID'!C35 | I36: ='01B_Findings_ID'!H35
E37: ='01B_Findings_ID'!A36 | F37: ='01B_Findings_ID'!F36 | G37: ='01B_Findings_ID'!G36 | H37: ='01B_Findings_ID'!C36 | I37: ='01B_Findings_ID'!H36
E38: ='01B_Findings_ID'!A37 | F38: ='01B_Findings_ID'!F37 | G38: ='01B_Findings_ID'!G37 | H38: ='01B_Findings_ID'!C37 | I38: ='01B_Findings_ID'!H37
E39: ='01B_Findings_ID'!A38 | F39: ='01B_Findings_ID'!F38 | G39: ='01B_Findings_ID'!G38 | H39: ='01B_Findings_ID'!C38 | I39: ='01B_Findings_ID'!H38
E40: ='01B_Findings_ID'!A39 | F40: ='01B_Findings_ID'!F39 | G40: ='01B_Findings_ID'!G39 | H40: ='01B_Findings_ID'!C39 | I40: ='01B_Findings_ID'!H39
E41: ='01B_Findings_ID'!A40 | F41: ='01B_Findings_ID'!F40 | G41: ='01B_Findings_ID'!G40 | H41: ='01B_Findings_ID'!C40 | I41: ='01B_Findings_ID'!H40
...

Sheet 00B_Panduan_Bahasa
A1: Panduan QC Tracker - AI Finance Forum
A2: Dokumen ini menjelaskan isi workbook QC dan cara memakainya. Ditinjau 28 Juli 2026.
A4: 1. APA ITU WORKBOOK INI
A5: Workbook ini adalah hasil pemeriksaan mutu (quality control) atas mockup AI Finance Forum, plus alat pelacak
A6: perbaikannya. Isinya dua hal: daftar temuan yang harus diperbaiki, dan daftar pengujian yang masih harus
A7: dijalankan secara manual sebelum demo di depan para CFO.
A9: 2. BAGAIMANA PEMERIKSAAN INI DILAKUKAN, DAN APA BATASNYA
A10: Pemeriksaan dilakukan langsung terhadap API aplikasi yang sedang berjalan. Semua endpoint GET dibaca:
A11: dashboard keempat agent, KPI, konfigurasi grafik, 47 alert, 47 action card, dan riwayat percakapan.
A12: Batas yang penting untuk Anda ketahui: tombol, menu, slider simulator, kotak chat, serta tombol approve dan
A13: simulate pada action semuanya berjalan lewat POST atau di sisi browser. Semua itu TIDAK bisa diuji dari luar.
A14: Karena itu 31 pengujian manual disiapkan di sheet 02. Bagian tersebut masih berstatus belum diuji.
... A97: Ketiga asumsi ini ditandai kuning di workbook dataset.

Sheet 01_Findings
A1: Testing listing - findings tracker
A2: AI Finance Forum mockup. Reviewed 28 July 2026 against the live API. Update Status, Target date and Retest columns as fixes land.
A4: ID | B4: Date found | C4: Agent | D4: QC area | E4: Type | F4: Severity | G4: Demo blocker | H4: Finding | I4: Evidence observed | J4: Expected behaviour | K4: Likely root cause | L4: Fix owner | M4: Target date | N4: Status | O4: Retest date | P4: Retest result | Q4: Notes
A5: QC-001 | B5: 2026-07-28 | C5: Leakage | D5: a. Formula consistency | E5: Data | F5: Critical | G5: Yes | H5: Leakage category chart returns all zeros | I5: GET /api/html/dashboard/finance.leakage returns views.categories.data with every value 0.0 (Bank-change fraud 0, Duplicate payment 0, Overbilling 0, Lost discount 0, Split/threshold 0). The side donut 'Leakage mix' is also all zeros, the worklist Amount column is '0' for all 10 rows, and the vendor radar 'At risk' column is '0' for all 8 vendors. Meanwhile the KPI tiles show 7,845 / 3,800 / 3,050 / 4,300. | J5: Category amounts should sum to the 7,845 mn shown on the 'Flagged this cycle' KPI. | K5: The amount column is not mapped for import batch 17. Aggregate KPIs are computed from a different query than the per-category breakdown. | L5: Backend / data | M5: 2026-07-31 | N5: Fixed - awaiting retest | Q5: Fixed 30 Jul 2026 (branch bug-fix-trial, commit 53daa2c). category_breakdowns.amount_at_risk_idr_mn was probed as amount_idr_mn, so _row_get returned None and every value became 0.0 with no error. Verified on live DB batch 17: bars 3,800 / 3,050 / 900 / 95 sum to 7,845 = the Flagged this cycle card.
A6: QC-002 | B6: 2026-07-28 | C6: All | D6: a. Formula consistency | E6: Architecture | F6: Critical | G6: Yes | H6: The four agents run on four unrelated data batches | I6: import_batch_id is 19 for Finance, 17 for Leakage, 11 for Collection and 2 for Treasury. | J6: One shared ledger, so any number can be traced across agents. | K6: No single source of truth. Each agent was seeded independently. | L6: Backend / data | M6: 2026-07-31 | N6: Open
A7: QC-003 | B7: 2026-07-28 | C7: Finance + Collection | D7: a. Formula consistency | E7: Formula | F7: Critical | G7: Yes | H7: Collection revenue base is about 15 times the Finance revenue | I7: Collection raw.summary.annual_credit_sales_idr_mn = 700,000. Finance KPI revenue = 46,510. AR of 110,000 is 2.4 times the entire Finance annual revenue. | J7: DSO must be divided by the same revenue the Finance agent reports. | K7: Two unrelated seed datasets (see the batch finding above). | L7: Backend / data | M7: 2026-07-31 | N7: Open
A8: QC-004 | B8: 2026-07-28 | C8: Treasury | D8: a. Formula consistency | E8: Formula | F8: Critical | G8: Yes | H8: Deferral action moves headroom the wrong way | I8: Action 'Defer noncritical Week 5 payable' shows impact 'week6 headroom: 1012.5 +3000 -> 4012.5'. Moving a payable INTO Week 6 must reduce Week 6 headroom, not increase it. Its own spec also claims Week 5 cash rises above IDR 10,000 mn; 6,997.5 + 3,000 = 9,997.5. | J8: Week 5 headroom -1,002.5 -> +1,997.5 and Week 6 headroom 1,012.5 -> -1,987.5, so the trade-off is visible. | K8: The impact string is authored text, not computed from the forecast. Sign and week label are both wrong. | L8: Backend / agent logic | M8: 2026-07-31 | N8: Open
A9: QC-005 | B9: 2026-07-28 | C9: Treasury | D9: a. Formula consistency | E9: Formula | F9: Critical | G9: Yes | H9: Action mixes headroom with closing cash in one before-and-after | I9: Action 'Accelerate Customer A collection' shows 'cash buffer: -1002.5 -> +6997.5'. -1,002.5 is headroom, 6,997.5 is closing cash. Its own spec says recover at least IDR 1,100 mn, which would give +97.5 headroom. | J9: One unit per metric. Either headroom -1,002.5 -> +97.5, or closing cash 6,997.5 -> 8,097.5. | K9: Impact strings are free text with no unit validation. | L9: Backend / agent logic | M9: 2026-07-31 | N9: Open
A10: QC-006 | B10: 2026-07-28 | C10: All | D10: d. Prompt & response | E10: Content | F10: Critical | G10: Yes | H10: Conversation history is full of developer test messages | I10: GET /api/html/conversations returns roughly 190 saved conversations including 'test', 'asdsad', 'hello world', 'Test test test', 'selamat pagi', 'does all the right tools work?', 'gimme data', 'show me the cahrt'. | J10: A curated history containing only credible CFO questions, or the history panel hidden for the event. | K10: No separation between the development environment and the demo environment. | L10: Demo owner | M10: 2026-07-31 | N10: Open
A11: QC-007 | B11: 2026-07-28 | C11: Collection | D11: a. Formula consistency | E11: Formula | F11: High | G11: Yes | H11: High-risk KPI and the risk tier chart disagree on the same screen | I11: KPI 'High-risk exposure' = 2,500 mn with the label 'provision / high tier'. The 'Risk exposure by tier' chart shows High = 5,000 mn. | J11: Either the KPI is renamed 'High-risk provision', or it shows 5,000 to match the chart. | K11: The KPI reads the provision field while the chart reads the exposure field. Same label, two meanings. | L11: Backend / agent logic | M11: 2026-08-04 | N11: Fixed - awaiting retest | Q11: Fixed 30 Jul 2026 (commit 53daa2c). The card showed high_risk_provision (2,500) under a label reading 'exposure'. It now shows the High tier exposure (5,000), which equals the chart bar, with the provision moved to the caption.
A12: QC-008 | B12: 2026-07-28 | C12: Collection | D12: a. Formula consistency | E12: Definition | F12: High | G12: Yes | H12: 'Top 5' is defined three different ways inside one agent | I12: Options chart 'Top 5 - 46d' uses worklist rows 1 to 5 (21,300 mn recovery). Alert 'DSO gap and overdue concentration' uses top 5 by overdue amount (27,000 mn, 71.17%). Alert 'Mid-tier accounts can unlock most DSO gap' uses top 5 by expected recovery (23,225 mn). | J12: One definition, stated on screen. | K12: Each surface computes its own ranking. | L12: Backend / agent logic | M12: 2026-08-04 | N12: Open
A13: QC-009 | B13: 2026-07-28 | C13: Finance | D13: a. Formula consistency | E13: Formula | F13: High | G13: Yes | H13: Two different EBITDA margin targets are in use | I13: The KPI tile and the simulator gauge both say 'target 15%'. The alert 'Price recovery opportunity' says the budget margin is 15.7% (budget EBITDA 7,200 / budget revenue 46,000 = 15.65%). | J13: One target. If budget is the reference, use 15.7% everywhere. | K13: The gauge target is hardcoded to a round 15% while the alerts compute it from the budget. | L13: Backend / agent logic | M13: 2026-08-04 | N13: Fixed - awaiting retest | Q13: Fixed 30 Jul 2026 (commit f448e66). The target now comes from the budget row (7,200 / 46,000 = 15.65%) and is threaded through the card caption, gauge label, simulator baseline and the recalculate endpoint. NOTE: formula check #18 expects 9.2/15 = 0.6133; with one target it becomes 9.2/15.65 = 0.586, so that check needs updating.
A14: QC-010 | B14: 2026-07-28 | C14: Finance | D14: a. Formula consistency | E14: Formula | F14: High | G14: Yes | H14: Price variance is roughly ten times too small for the stated price decline | I14: Alerts state blended price fell 7.6%, from IDR 127.7k to IDR 118.0k per unit. The EBITDA waterfall shows a price step of only -390 mn on revenue of 46,510 mn. A 7.6% blended price decline implies roughly -3,800 mn. | J14: The price step and the stated percentage decline must be derived from the same calculation. | K14: The waterfall steps and the alert narrative are generated from different sources. Needs verification against the underlying model. | L14: Backend / agent logic | M14: 2026-08-04 | N14: Open
A15: QC-011 | B15: 2026-07-28 | C15: Finance | D15: a. Formula consistency | E15: Formula | F15: High | G15: Yes | H15: COGS variance is stated as two different numbers | I15: Alerts and actions use IDR 2,930 mn of COGS overrun. The EBITDA waterfall shows the Cost and FX step as -1,880 mn. | J15: One cost variance figure across the waterfall, the alerts and the action cards. | K15: The waterfall may net FX into cost while the alert reports gross cost. Not reconciled either way. | L15: Backend / agent logic | M15: 2026-08-04 | N15: Open
A16: QC-012 | B16: 2026-07-28 | C16: Finance | D16: d. Prompt & response | E16: Content | F16: High | G16: No | H16: Two near-identical numbers mean two different things | I16: Cost and FX step = -1,880 mn. Mix plus price = -1,491 + -390 = -1,881 mn, and an alert reports 'IDR 1,881mn combined profitability loss'. | J16: Separate the two on screen, or round them differently so they cannot be confused live. | K16: Coincidence in the seed data, but it will cause confusion on stage. | L16: Demo owner | M16: 2026-08-04 | N16: Open
A17: QC-013 | B17: 2026-07-28 | C17: Leakage | D17: a. Formula consistency | E17: Formula | F17: Medium | G17: No | H17: The bar labelled 'Current 95%' does not show the current position | I17: In the Leakage 'Recovery scenario' chart the third bar is labelled 'Current 95%' and equals 7,577.5. It applies 95% to duplicates and overbilling together. The real current position applies 95% to duplicates and 90% to overbilling, which gives 7,557.5. That is the figure the 'Total protected' KPI (7,558) and the side chart 'Protected vs at risk' (7,557.5) both carry. Difference = 400 x 5% = 20 mn. IMPORTANT: this is not visible to the eye. The KPI and the side chart agree with each other, so a side-by-side glance looks correct. Only the recovery chart differs, and 20 out of 7,578 is 0.26%. It surfaces in a tooltip, a data label, or when someone asks the agent for the number. | J17: The 'Current' bar uses the same assumption set as the KPI and reads 7,557.5. Alternatively rename the bar to '95% across the board' so it stops claiming to be the current position. | K17: The recovery chart hardcodes one claw-back rate across all recoverable items. The simulator baseline uses two separate rates. Neither is wrong on its own; the label 'Current' is what makes the chart incorrect. | L17: Backend / agent logic | M17: 2026-08-11 | N17: Fixed - awaiting retest | Q17: Severity lowered from High to Medium on 28 Jul 2026 after re-checking with Susan. Reason: the gap is not visible to the eye and is not a demo blocker. The defect is still real and still needs fixing. | Fixed 30 Jul 2026 (commit 53daa2c). The bar is now labelled 'Current 95/90%' and reuses the Total protected card value (7,557.5) instead of recomputing it at 95/95 (7,577.5).
A18: QC-014 | B18: 2026-07-28 | C18: Leakage | D18: a. Formula consistency | E18: Formula | F18: High | G18: Yes | H18: Flag count on the KPI does not match the tables | I18: KPI 'Flagged this cycle' says '22 flags'. The action worklist lists 10 rows and the vendor radar totals 10 flags across 8 vendors. | J18: The count on the KPI equals the number of rows a user can actually open. | K18: The KPI counts raw exceptions while the tables show a filtered top-N with no 'showing 10 of 22' label. | L18: Backend / agent logic | M18: 2026-08-04 | N18: Fixed - awaiting retest | Q18: Fixed 30 Jul 2026 (commit 53daa2c). The KPI now reads summary.items_flagged (10). The 22 came from len(anomalies), which is LIMIT 30 and includes rows that are not flagged.
A19: QC-015 | B19: 2026-07-28 | C19: Leakage | D19: a. Formula consistency | E19: Formula | F19: High | G19: Yes | H19: Split-invoice exposure sits in the chart but outside the total | I19: At risk = 7,845 = fraud 3,800 + duplicates 3,050 + overbilling 400 + other blocked 500 + lost 95. The alert 'Split invoice threshold evasion' reports IDR 1,950 mn, and 'Split / threshold' is one of the five chart categories, yet 1,950 is not in the 7,845. | J19: Either at risk becomes 9,795, or split invoices are excluded from the chart and explained. | K19: The at-risk aggregate was built before split-threshold detection was added. | L19: Backend / agent logic | M19: 2026-08-04 | N19: In progress | Q19: Partly fixed 30 Jul 2026 (commit 53daa2c). The dashboard no longer contradicts itself: rows with is_direct_loss = false are out of the category bar and mix donut, so both sum to 7,845, and the 1,950 is named in the chart note. The alert wording has NOT been checked yet.
A20: QC-016 | B20: 2026-07-28 | C20: Collection | D20: a. Formula consistency | E20: Formula | F20: High | G20: Yes | H20: Action impact does not match its own recommendation | I20: Action 'Accelerate top overdue collections' spec says collect at least IDR 20,000 mn. Impact says 'DSO: 57.36 -5.21 -> 52.14'. -5.21 days corresponds to 10,000 mn (10,000 / 1,917.8). 20,000 mn gives -10.43 days. | J20: Impact recomputed from the amount in the spec. | K20: Impact string copied from a different action. | L20: Backend / agent logic | M20: 2026-08-04 | N20: Open
A21: QC-017 | B21: 2026-07-28 | C21: Treasury | D21: a. Formula consistency | E21: Formula | F21: High | G21: Yes | H21: Combined action shows only part of its own effect | I21: Action 'Bridge Week 5 funding gap' spec says accelerate 2,000 mn plus defer 3,000 mn, which is 5,000 mn. Impact shows 'headroom: -1002.5 -> +1997.5', a movement of only 3,000 mn. | J21: -1,002.5 -> +3,997.5. | K21: Only the deferral leg is being computed. | L21: Backend / agent logic | M21: 2026-08-04 | N21: Open
A22: QC-018 | B22: 2026-07-28 | C22: Collection | D22: a. Formula consistency | E22: Labelling | F22: High | G22: No | H22: Action labels the top-2 concentration as the overall overdue share | I22: Action 'Escalate concentrated exposures' shows 'Overdue share: 43.5% -10% -> 33.5%'. The dashboard overdue share is 34.5% (37,935 / 110,000). 43.5% is the top-2 share of overdue (16,500 / 37,935). | J22: Label it 'Top-2 share of overdue'. | K22: Reused metric name for a different denominator. | L22: Backend / agent logic | M22: 2026-08-04 | N22: Open
A23: QC-019 | B23: 2026-07-28 | C23: Treasury | D23: a. Formula consistency | E23: Formula | F23: High | G23: Yes | H23: Credit line action is anchored to the wrong week | I23: Action 'Pre-arrange contingent credit capacity' uses baseline 1,012.5, which is Week 6 headroom. The breach is in Week 5 at -1,002.5. Its spec then targets a buffer above 4,000 mn. | J23: Baseline -1,002.5 (Week 5), result +1,997.5 after a 3,000 mn draw. | K23: Wrong week selected as the baseline. | L23: Backend / agent logic | M23: 2026-08-04 | N23: Open
A24: QC-020 | B24: 2026-07-28 | C24: All | D24: c. Button / menu / function | E24: Integration | F24: High | G24: Yes | H24: Agent keys are inconsistent between endpoints | I24: /api/html/agents returns finance.collection and finance.treasury. The dashboard payload returns agent 'collections' and 'treasury'. /api/actions and /api/alerts use 'collection' and 'cashflow'. | J24: One canonical key per agent across every endpoint. | K24: Naming drift between the agent registry, the dashboard service and the alert or action service. Any join on agent name will silently return an empty list for Treasury. | L24: Backend | M24: 2026-08-04 | N24: Open
A25: QC-021 | B25: 2026-07-28 | C25: All | D25: d. Prompt & response | E25: Content | F25: High | G25: Yes | H25: 47 action cards with heavy duplication | I25: Finance has at least five near-identical actions to rebalance mix toward higher-margin SKUs. Leakage has three near-identical 'Launch duplicate payment recovery' cards. Collection has four cards on the same two customers. | J25: Deduplicate to roughly three to five distinct actions per agent for the demo. | K25: Actions are generated per alert with no clustering step, and the alerts are themselves duplicated. | L25: Backend / agent logic | M25: 2026-08-04 | N25: Open
A26: QC-022 | B26: 2026-07-28 | C26: All | D26: a. Formula consistency | E26: Logic | F26: High | G26: Yes | H26: Action impacts stack with no double-count guard | I26: Approving the Finance set adds +1,500, +1,000, +390, +300 and two percentage-point moves to the same EBITDA base of 4,300, and several of them address the same driver. | J26: A portfolio view that nets overlapping actions and shows a single combined impact. | K26: Each action is scored in isolation against the baseline. | L26: Backend / agent logic | M26: 2026-08-04 | N26: Open
A27: QC-023 | B27: 2026-07-28 | C27: All | D27: d. Prompt & response | E27: Content | F27: High | G27: No | H27: 47 alerts telling roughly eight distinct stories | I27: Finance has 12 alerts, essentially all describing mix, price and cost. Cashflow has 12 restating the Week 5 breach. | J27: Cluster to one alert per underlying issue with a severity ranking. | K27: No deduplication in the alert generator. | L27: Backend / agent logic | M27: 2026-08-04 | N27: Open
A28: QC-024 | B28: 2026-07-28 | C28: Leakage | D28: b. Chart accuracy | E28: Chart | F28: High | G28: Yes | H28: The Leakage agent opens on an empty chart | I28: default_view is 'categories', which is the all-zero chart described in the first finding. | J28: Open on a populated view. | K28: Same root cause as the zero-amount issue. | L28: Backend / data | M28: 2026-08-04 | N28: Fixed - awaiting retest | Q28: Fixed 30 Jul 2026 (commit 53daa2c). Same root cause as QC-001; the default view 'categories' now renders four bars on open.
A29: QC-025 | B29: 2026-07-28 | C29: Treasury | D29: a. Formula consistency | E29: Labelling | F29: High | G29: No | H29: FX action states exposure falls to the hedge amount | I29: Action 'Increase near-term FX protection' shows 'FX exposure: 3.3m -1.3m -> 2.0m'. Hedging the unhedged 1.3M should take unhedged exposure from 1.3M to zero, or coverage from 61% to 100%. As written, 2.0M is the hedge amount, not the residual exposure. | J29: 'Unhedged exposure: USD 1.3m -> USD 0' or 'Coverage: 61% -> 100%'. | K29: Confuses gross exposure with hedged notional. | L29: Backend / agent logic | M29: 2026-08-04 | N29: Open
A30: QC-026 | B30: 2026-07-28 | C30: Collection | D30: a. Formula consistency | E30: Logic | F30: Medium | G30: No | H30: Recovery rate ignores how old the debt is | I30: Expected recovery is driven only by risk tier: High 40%, Medium 85%, Low 95%. CV Berkah Jaya at 90+ days recovers at 40% while PT Sumber Makmur at 61-90 days recovers at 85%, the same rate as a 31-60 day account. | J30: Recovery rate should be a function of both tier and ageing bucket. | K30: Single-factor recovery model. | L30: Backend / agent logic | M30: 2026-08-11 | N30: Open
A31: QC-027 | B31: 2026-07-28 | C31: Finance | D31: a. Formula consistency | E31: Formula | F31: Medium | G31: No | H31: One margin percentage rounds down where others round normally | I31: Precision gross margin displays 36.2%. 4,930 / 13,600 = 36.25%, which should display 36.3%. Industrial 23.81% -> 23.8 and Standard 16.67% -> 16.7 both round correctly. | J31: Consistent rounding, half up. | K31: Truncation rather than rounding on this path. | L31: Frontend | M31: 2026-08-11 | N31: Fixed - awaiting retest | Q31: Fixed 30 Jul 2026 (commit f448e66). Python and IEEE round half to even, so round(36.25, 1) is 36.2. Added _round_half_up and routed _fmt and _pct through it. Product GM% is now 23.8 / 36.3 / 16.7.
A32: QC-028 | B32: 2026-07-28 | C32: Collection | D32: b. Chart accuracy | E32: Chart | F32: Medium | G32: No | H32: DSO gauge shows 120% progress on a metric where lower is better | I32: DSO KPI has progress 1.2 (57 / 47). | J32: Invert the gauge, or show days over target rather than a progress percentage. | K32: Generic progress calculation applied to an inverse metric. | L32: Frontend | M32: 2026-08-11 | N32: Fixed - awaiting retest | Q32: Fixed 30 Jul 2026 (commit f448e66). Added a lower_is_better flag so enrichment inverts the ratio. DSO progress is now 0.8246 (47/57) instead of the clamped 1.2.
A33: QC-029 | B33: 2026-07-28 | C33: Treasury | D33: d. Prompt & response | E33: Formatting | F33: Medium | G33: No | H33: Inconsistent number formats in one KPI row | I33: 'Net USD exposure 3.3 M USD' sits next to 'Recommended hedge 2,000,000 USD'. The Week 5 shortfall appears as 1,002, 1,002.5 and 1,003 in different places. | J33: One format per unit across the app. | K33: No shared formatting helper. | L33: Frontend | M33: 2026-08-11 | N33: Fixed - awaiting retest | Q33: Fixed 30 Jul 2026 (commit f448e66). One USD scale across the KPI row: 3.3 M USD beside 2.0 M USD, instead of 3.3 M USD beside 2,000,000 USD which hid that 2.0 is less than 3.3.
A34: QC-030 | B34: 2026-07-28 | C34: Collection | D34: a. Formula consistency | E34: Labelling | F34: Medium | G34: No | H34: Action labels a two-customer balance as total overdue AR | I34: Action 'Tighten exposure controls' shows 'Overdue AR: 16500 -3000 -> 13500'. Total overdue AR is 37,935. 16,500 is the top two customers. | J34: 'Top-2 overdue: 16,500 -> 13,500'. | K34: Reused metric name. | L34: Backend / agent logic | M34: 2026-08-11 | N34: Open
A35: QC-031 | B35: 2026-07-28 | C35: Leakage | D35: a. Formula consistency | E35: Labelling | F35: Medium | G35: No | H35: Action uses the annualised figure while the dashboard shows the cycle figure | I35: Action 'Tighten early-payment discount capture' shows 'Discount leakage: 2470 -50% -> 1235'. The dashboard 'Lost' amount is 95 mn. The alert clarifies 95 mn per cycle annualises to 2,470 mn. | J35: State the basis on the card: 'Discount leakage (annualised)'. | K35: No period label on impact strings. | L35: Backend / agent logic | M35: 2026-08-11 | N35: Open
A36: QC-032 | B36: 2026-07-28 | C36: Leakage | D36: a. Formula consistency | E36: Labelling | F36: Medium | G36: No | H36: The same 900 mn appears under three different names | I36: Alerts call it 'IDR 900mn excess vs PO/GRN'. The simulator baseline splits it as overbill_amount 400 and other_blocked 500. An action calls it 'overbilling risk: 900mn'. | J36: One name, with the split shown as a breakdown underneath. | K36: Field naming drift. | L36: Backend / agent logic | M36: 2026-08-11 | N36: Open
A37: QC-033 | B37: 2026-07-28 | C37: Collection | D37: b. Chart accuracy | E37: Chart | F37: Medium | G37: No | H37: Two charts on the same screen order the same pair in opposite directions | I37: Main 'prize' chart plots Now then Target. The side chart 'DSO vs target' plots Target then Now. | J37: One order. | K37: Independently authored chart configs. | L37: Frontend | M37: 2026-08-11 | N37: Fixed - awaiting retest | Q37: Fixed 30 Jul 2026 (commit f448e66). Both charts now order [Now, Target]. Aligning them turned the pair into exact duplicates, so side:bottom was changed to Overdue vs expected recovery.
A38: QC-034 | B38: 2026-07-28 | C38: Treasury | D38: b. Chart accuracy | E38: Chart | F38: Medium | G38: No | H38: A zero bar next to a value bar reads as a rendering failure | I38: The 'FX impact if we do nothing' chart plots Base = 0 against Adverse = 1,777.05. | J38: Show a single value with a reference line, or label the zero bar explicitly. | K38: Chart type choice. | L38: Frontend | M38: 2026-08-11 | N38: Fixed - awaiting retest | Q38: Fixed 30 Jul 2026 (commit f448e66). The zero 'Base' bar is gone. The chart now compares Do nothing 1,777.05 against Hedge 2.0M 700.05 - both non-zero, and the first equals the FX loss card.
A39: QC-035 | B39: 2026-07-28 | C39: All | D39: b. Chart accuracy | E39: Chart | F39: Medium | G39: Yes | H39: No chart states its period | I39: None of the four dashboards labels whether a figure is monthly, year to date or full year. | J39: Every chart title carries the period, for example 'Oct 2025 to Sep 2026'. | K39: Period is not part of the payload. | L39: Frontend + backend | M39: 2026-08-11 | N39: Open
A40: QC-036 | B40: 2026-07-28 | C40: Finance | D40: b. Chart accuracy | E40: Chart | F40: Medium | G40: No | H40: The side chart duplicates the main chart exactly | I40: side.top 'Margin by product' has identical data to the 'product' view. | J40: Use the side slot for something the main view does not show. | K40: Layout placeholder never replaced. | L40: Frontend | M40: 2026-08-11 | N40: Fixed - awaiting retest | Q40: Fixed 30 Jul 2026 (commit f448e66). Finance side:top was byte-identical to view:product. It now shows the gross margin pool in IDR (4,550 / 4,930 / 2,300 = 11,780) rather than repeating the rate.
A41: QC-037 | B41: 2026-07-28 | C41: Treasury | D41: b. Chart accuracy | E41: Chart | F41: Medium | G41: Yes | H41: The cash chart cannot answer why Week 5 is low | I41: The forecast view carries closing balance only, with no inflow or outflow detail. | J41: Weekly inflows, outflows and the largest lines behind them, so the obvious follow-up question is answerable on screen. | K41: Only the balance series is stored. | L41: Backend + frontend | M41: 2026-08-11 | N41: Open
...

Sheet 01B_Findings_ID
A1: Daftar temuan pengujian (Bahasa Indonesia)
A2: Nomor QC sama persis dengan sheet 01_Findings. Kolom kuning diisi oleh tim. Sheet 00_Summary menghitung dari sheet 01, jadi status wajib diperbarui di kedua sheet atau pilih satu sheet sebagai acuan.
A4: No QC | B4: Tanggal temuan | C4: Agent | D4: Area QC | E4: Jenis | F4: Tingkat | G4: Penghambat demo | H4: Temuan | I4: Bukti yang ditemukan | J4: Perilaku yang seharusnya | K4: Dugaan akar masalah | L4: Penanggung jawab | M4: Target selesai | N4: Status | O4: Tanggal uji ulang | P4: Hasil uji ulang | Q4: Catatan
A5: QC-001 | B5: 2026-07-28 | C5: Leakage | D5: a. Kesesuaian formula | E5: Data | F5: Kritis | G5: Ya | H5: Grafik kategori Leakage menampilkan nol semua | I5: Endpoint dashboard finance.leakage mengembalikan views.categories.data dengan semua nilai 0.0 (Bank-change fraud 0, Duplicate payment 0, Overbilling 0, Lost discount 0, Split/threshold 0). Donut 'Leakage mix' juga nol semua, kolom Amount pada worklist berisi '0' untuk 10 baris, dan kolom 'At risk' pada vendor radar berisi '0' untuk 8 vendor. Padahal KPI tile menampilkan 7.845 / 3.800 / 3.050 / 4.300. | J5: Jumlah per kategori harus sama dengan 7.845 mn yang tampil di KPI 'Flagged this cycle'. | K5: Kolom amount tidak ter-mapping untuk import batch 17. KPI agregat dihitung dari query yang berbeda dengan query rincian per kategori. | L5: Backend / data | M5: 2026-07-31 | N5: Sudah diperbaiki - menunggu uji ulang | Q5: Fixed 30 Jul 2026 (branch bug-fix-trial, commit 53daa2c). category_breakdowns.amount_at_risk_idr_mn was probed as amount_idr_mn, so _row_get returned None and every value became 0.0 with no error. Verified on live DB batch 17: bars 3,800 / 3,050 / 900 / 95 sum to 7,845 = the Flagged this cycle card.
A6: QC-002 | B6: 2026-07-28 | C6: Semua agent | D6: a. Kesesuaian formula | E6: Arsitektur | F6: Kritis | G6: Ya | H6: Empat agent berjalan di atas empat batch data yang tidak berhubungan | I6: import_batch_id = 19 untuk Finance, 17 untuk Leakage, 11 untuk Collection, dan 2 untuk Treasury. | J6: Satu ledger bersama, sehingga setiap angka bisa ditelusuri lintas agent. | K6: Tidak ada single source of truth. Setiap agent di-seed secara terpisah. | L6: Backend / data | M6: 2026-07-31 | N6: Terbuka
A7: QC-003 | B7: 2026-07-28 | C7: Finance + Collection | D7: a. Kesesuaian formula | E7: Formula | F7: Kritis | G7: Ya | H7: Basis pendapatan Collection sekitar 15 kali lipat pendapatan Finance | I7: Collection raw.summary.annual_credit_sales_idr_mn = 700.000. KPI revenue Finance = 46.510. Piutang 110.000 setara 2,4 kali seluruh pendapatan tahunan Finance. | J7: DSO harus dibagi dengan pendapatan yang sama dengan yang dilaporkan agent Finance. | K7: Dua dataset seed yang tidak berhubungan (lihat temuan batch di atas). | L7: Backend / data | M7: 2026-07-31 | N7: Terbuka
A8: QC-004 | B8: 2026-07-28 | C8: Treasury | D8: a. Kesesuaian formula | E8: Formula | F8: Kritis | G8: Ya | H8: Aksi penundaan pembayaran menggerakkan headroom ke arah yang salah | I8: Aksi 'Defer noncritical Week 5 payable' menampilkan dampak 'week6 headroom: 1012.5 +3000 -> 4012.5'. Memindahkan utang KE Minggu 6 seharusnya MENURUNKAN headroom Minggu 6, bukan menaikkan. Spec-nya juga mengklaim kas Minggu 5 naik di atas IDR 10.000 mn, padahal 6.997,5 + 3.000 = 9.997,5. | J8: Headroom Minggu 5: -1.002,5 -> +1.997,5 dan headroom Minggu 6: 1.012,5 -> -1.987,5, sehingga trade-off-nya terlihat. | K8: Teks dampak ditulis manual, bukan dihitung dari forecast. Tanda (+/-) dan label minggu dua-duanya salah. | L8: Backend / logika agent | M8: 2026-07-31 | N8: Terbuka
A9: QC-005 | B9: 2026-07-28 | C9: Treasury | D9: a. Kesesuaian formula | E9: Formula | F9: Kritis | G9: Ya | H9: Aksi mencampur headroom dengan saldo kas dalam satu perbandingan | I9: Aksi 'Accelerate Customer A collection' menampilkan 'cash buffer: -1002.5 -> +6997.5'. Angka -1.002,5 adalah headroom, sedangkan 6.997,5 adalah saldo kas akhir. Spec-nya sendiri menyebut penagihan minimal IDR 1.100 mn, yang hanya menghasilkan +97,5. | J9: Satu satuan untuk satu metrik. Pilih headroom -1.002,5 -> +97,5, atau saldo kas 6.997,5 -> 8.097,5. | K9: Teks dampak berupa free text tanpa validasi satuan. | L9: Backend / logika agent | M9: 2026-07-31 | N9: Terbuka
A10: QC-006 | B10: 2026-07-28 | C10: Semua agent | D10: d. Prompt dan respons | E10: Konten | F10: Kritis | G10: Ya | H10: Riwayat percakapan penuh dengan pesan uji coba developer | I10: Endpoint conversations mengembalikan sekitar 190 percakapan tersimpan, termasuk 'test', 'asdsad', 'hello world', 'Test test test', 'selamat pagi', 'does all the right tools work?', 'gimme data', dan 'show me the cahrt'. | J10: Riwayat yang sudah dikurasi, hanya berisi pertanyaan CFO yang kredibel, atau panel riwayat disembunyikan saat event. | K10: Tidak ada pemisahan antara environment development dan environment demo. | L10: Pemilik demo | M10: 2026-07-31 | N10: Terbuka
A11: QC-007 | B11: 2026-07-28 | C11: Collection | D11: a. Kesesuaian formula | E11: Formula | F11: Tinggi | G11: Ya | H11: KPI high-risk dan grafik risk tier tidak sama di layar yang sama | I11: KPI 'High-risk exposure' = 2.500 mn dengan label 'provision / high tier'. Grafik 'Risk exposure by tier' menampilkan High = 5.000 mn. | J11: Ganti nama KPI menjadi 'High-risk provision', atau tampilkan 5.000 agar sama dengan grafik. | K11: KPI membaca field pencadangan, grafik membaca field eksposur. Satu label, dua arti. | L11: Backend / logika agent | M11: 2026-08-04 | N11: Sudah diperbaiki - menunggu uji ulang | Q11: Fixed 30 Jul 2026 (commit 53daa2c). The card showed high_risk_provision (2,500) under a label reading 'exposure'. It now shows the High tier exposure (5,000), which equals the chart bar, with the provision moved to the caption.
A12: QC-008 | B12: 2026-07-28 | C12: Collection | D12: a. Kesesuaian formula | E12: Definisi | F12: Tinggi | G12: Ya | H12: Definisi 'Top 5' berbeda tiga kali di dalam satu agent | I12: Grafik options 'Top 5 - 46d' memakai baris 1-5 worklist (recovery 21.300 mn). Alert 'DSO gap and overdue concentration' memakai top 5 berdasarkan nilai overdue (27.000 mn, 71,17%). Alert 'Mid-tier accounts' memakai top 5 berdasarkan expected recovery (23.225 mn). | J12: Satu definisi saja, dan ditulis di layar. | K12: Setiap tampilan menghitung ranking-nya sendiri. | L12: Backend / logika agent | M12: 2026-08-04 | N12: Terbuka
A13: QC-009 | B13: 2026-07-28 | C13: Finance | D13: a. Kesesuaian formula | E13: Formula | F13: Tinggi | G13: Ya | H13: Ada dua target margin EBITDA yang dipakai bersamaan | I13: KPI tile dan gauge simulator sama-sama menulis 'target 15%'. Alert 'Price recovery opportunity' menyebut margin anggaran 15,7% (EBITDA anggaran 7.200 / pendapatan anggaran 46.000 = 15,65%). | J13: Satu target saja. Kalau acuannya anggaran, pakai 15,7% di semua tempat. | K13: Target gauge di-hardcode ke angka bulat 15%, sedangkan alert menghitung dari anggaran. | L13: Backend / logika agent | M13: 2026-08-04 | N13: Sudah diperbaiki - menunggu uji ulang | Q13: Fixed 30 Jul 2026 (commit f448e66). The target now comes from the budget row (7,200 / 46,000 = 15.65%) and is threaded through the card caption, gauge label, simulator baseline and the recalculate endpoint. NOTE: formula check #18 expects 9.2/15 = 0.6133; with one target it becomes 9.2/15.65 = 0.586, so that check needs updating.
A14: QC-010 | B14: 2026-07-28 | C14: Finance | D14: a. Kesesuaian formula | E14: Formula | F14: Tinggi | G14: Ya | H14: Varians harga sekitar sepuluh kali lebih kecil dari penurunan harga yang diklaim | I14: Alert menyebut harga blended turun 7,6%, dari IDR 127,7k menjadi IDR 118,0k per unit. Waterfall EBITDA hanya menampilkan langkah harga -390 mn atas pendapatan 46.510 mn. Penurunan harga 7,6% seharusnya berdampak sekitar -3.800 mn. | J14: Langkah harga di waterfall dan persentase penurunan di alert harus berasal dari perhitungan yang sama. | K14: Langkah waterfall dan narasi alert dihasilkan dari sumber berbeda. Perlu diverifikasi ke model dasarnya. | L14: Backend / logika agent | M14: 2026-08-04 | N14: Terbuka
A15: QC-011 | B15: 2026-07-28 | C15: Finance | D15: a. Kesesuaian formula | E15: Formula | F15: Tinggi | G15: Ya | H15: Varians COGS disebut dengan dua angka berbeda | I15: Alert dan action memakai COGS overrun IDR 2.930 mn. Waterfall EBITDA menampilkan langkah Cost dan FX sebesar -1.880 mn. | J15: Satu angka varians biaya di seluruh waterfall, alert, dan action card. | K15: Waterfall mungkin sudah menetkan FX ke dalam biaya, sedangkan alert melaporkan biaya bruto. Keduanya belum direkonsiliasi. | L15: Backend / logika agent | M15: 2026-08-04 | N15: Terbuka
A16: QC-012 | B16: 2026-07-28 | C16: Finance | D16: d. Prompt dan respons | E16: Konten | F16: Tinggi | G16: Tidak | H16: Dua angka yang hampir sama artinya berbeda | I16: Langkah Cost dan FX = -1.880 mn. Mix ditambah price = -1.491 + -390 = -1.881 mn, dan sebuah alert melaporkan 'IDR 1.881mn combined profitability loss'. | J16: Pisahkan keduanya di layar, atau bulatkan berbeda supaya tidak tertukar saat presentasi. | K16: Kebetulan pada data seed, tetapi berpotensi membingungkan di atas panggung. | L16: Pemilik demo | M16: 2026-08-04 | N16: Terbuka
A17: QC-013 | B17: 2026-07-28 | C17: Leakage | D17: a. Kesesuaian formula | E17: Formula | F17: Sedang | G17: Tidak | H17: Batang berlabel 'Current 95%' tidak menunjukkan posisi saat ini | I17: Pada grafik 'Recovery scenario' di agent Leakage, batang ketiga berlabel 'Current 95%' bernilai 7.577,5. Batang itu menerapkan 95% ke duplikat dan overbilling sekaligus. Posisi sebenarnya menerapkan 95% ke duplikat dan 90% ke overbilling, hasilnya 7.557,5. Angka itulah yang dipakai KPI 'Total protected' (7.558) dan grafik samping 'Protected vs at risk' (7.557,5). Selisihnya = 400 x 5% = 20 juta. PENTING: selisih ini tidak terlihat mata. KPI dan grafik samping justru sudah cocok satu sama lain, jadi kalau dilihat sekilas memang terasa benar. Yang berbeda hanya grafik recovery, dan 20 dari 7.578 hanya 0,26%. Baru kelihatan lewat tooltip, label angka pada batang, atau kalau ada yang menanyakan angkanya ke agent. | J17: Batang 'Current' memakai set asumsi yang sama dengan KPI, sehingga bernilai 7.557,5. Alternatif lain, ganti namanya menjadi '95% untuk semua' supaya tidak lagi mengaku sebagai posisi saat ini. | K17: Grafik recovery meng-hardcode satu tarif claw-back untuk semua item yang bisa ditarik. Baseline simulator memakai dua tarif berbeda. Keduanya tidak salah secara terpisah. Yang membuat grafiknya keliru adalah label 'Current'. | L17: Backend / logika agent | M17: 2026-08-11 | N17: Sudah diperbaiki - menunggu uji ulang | Q17: Severity diturunkan dari Tinggi ke Sedang pada 28 Juli 2026 setelah diperiksa ulang bersama Susan. Alasan: selisihnya tidak terlihat mata dan bukan penghambat demo. Cacatnya tetap nyata dan tetap perlu diperbaiki. | Fixed 30 Jul 2026 (commit 53daa2c). The bar is now labelled 'Current 95/90%' and reuses the Total protected card value (7,557.5) instead of recomputing it at 95/95 (7,577.5).
A18: QC-014 | B18: 2026-07-28 | C18: Leakage | D18: a. Kesesuaian formula | E18: Formula | F18: Tinggi | G18: Ya | H18: Jumlah flag di KPI tidak cocok dengan tabelnya | I18: KPI 'Flagged this cycle' menulis '22 flags'. Worklist hanya berisi 10 baris dan vendor radar berjumlah 10 flag pada 8 vendor. | J18: Angka pada KPI harus sama dengan jumlah baris yang benar-benar bisa dibuka pengguna. | K18: KPI menghitung exception mentah, sedangkan tabel menampilkan top-N tanpa keterangan 'menampilkan 10 dari 22'. | L18: Backend / logika agent | M18: 2026-08-04 | N18: Sudah diperbaiki - menunggu uji ulang | Q18: Fixed 30 Jul 2026 (commit 53daa2c). The KPI now reads summary.items_flagged (10). The 22 came from len(anomalies), which is LIMIT 30 and includes rows that are not flagged.
A19: QC-015 | B19: 2026-07-28 | C19: Leakage | D19: a. Kesesuaian formula | E19: Formula | F19: Tinggi | G19: Ya | H19: Eksposur split invoice muncul di grafik tetapi di luar total | I19: At risk = 7.845 = fraud 3.800 + duplikat 3.050 + overbilling 400 + other blocked 500 + lost 95. Alert 'Split invoice threshold evasion' melaporkan IDR 1.950 mn, dan 'Split / threshold' adalah salah satu dari lima kategori grafik, tetapi 1.950 tidak masuk ke 7.845. | J19: Pilih: at risk menjadi 9.795, atau split invoice dikeluarkan dari grafik dan dijelaskan. | K19: Agregat at-risk dibuat sebelum deteksi split-threshold ditambahkan. | L19: Backend / logika agent | M19: 2026-08-04 | N19: Sedang dikerjakan | Q19: Partly fixed 30 Jul 2026 (commit 53daa2c). The dashboard no longer contradicts itself: rows with is_direct_loss = false are out of the category bar and mix donut, so both sum to 7,845, and the 1,950 is named in the chart note. The alert wording has NOT been checked yet.
A20: QC-016 | B20: 2026-07-28 | C20: Collection | D20: a. Kesesuaian formula | E20: Formula | F20: Tinggi | G20: Ya | H20: Dampak aksi tidak cocok dengan rekomendasinya sendiri | I20: Aksi 'Accelerate top overdue collections' menyebut penagihan minimal IDR 20.000 mn. Dampaknya tertulis 'DSO: 57.36 -5.21 -> 52.14'. Angka -5,21 hari setara 10.000 mn (10.000 / 1.917,8). Untuk 20.000 mn seharusnya -10,43 hari. | J20: Dampak dihitung ulang dari nilai yang ada di spec. | K20: Teks dampak tersalin dari aksi lain. | L20: Backend / logika agent | M20: 2026-08-04 | N20: Terbuka
A21: QC-017 | B21: 2026-07-28 | C21: Treasury | D21: a. Kesesuaian formula | E21: Formula | F21: Tinggi | G21: Ya | H21: Aksi gabungan hanya menampilkan sebagian dampaknya sendiri | I21: Aksi 'Bridge Week 5 funding gap' menyebut percepatan 2.000 mn ditambah penundaan 3.000 mn, total 5.000 mn. Dampaknya tertulis 'headroom: -1002.5 -> +1997.5', hanya bergerak 3.000 mn. | J21: -1.002,5 -> +3.997,5. | K21: Hanya kaki penundaan yang dihitung. | L21: Backend / logika agent | M21: 2026-08-04 | N21: Terbuka
A22: QC-018 | B22: 2026-07-28 | C22: Collection | D22: a. Kesesuaian formula | E22: Penamaan | F22: Tinggi | G22: Tidak | H22: Aksi memberi label konsentrasi top-2 sebagai porsi overdue keseluruhan | I22: Aksi 'Escalate concentrated exposures' menampilkan 'Overdue share: 43.5% -10% -> 33.5%'. Porsi overdue di dashboard adalah 34,5% (37.935 / 110.000). Angka 43,5% adalah porsi dua pelanggan terbesar terhadap overdue (16.500 / 37.935). | J22: Beri label 'Porsi top-2 terhadap overdue'. | K22: Nama metrik dipakai ulang untuk penyebut yang berbeda. | L22: Backend / logika agent | M22: 2026-08-04 | N22: Terbuka
A23: QC-019 | B23: 2026-07-28 | C23: Treasury | D23: a. Kesesuaian formula | E23: Formula | F23: Tinggi | G23: Ya | H23: Aksi credit line berpatokan pada minggu yang salah | I23: Aksi 'Pre-arrange contingent credit capacity' memakai baseline 1.012,5, yaitu headroom Minggu 6. Pelanggaran buffer terjadi di Minggu 5 pada -1.002,5. Spec-nya lalu menargetkan buffer di atas 4.000 mn. | J23: Baseline -1.002,5 (Minggu 5), hasil +1.997,5 setelah penarikan 3.000 mn. | K23: Minggu yang dipilih sebagai baseline salah. | L23: Backend / logika agent | M23: 2026-08-04 | N23: Terbuka
A24: QC-020 | B24: 2026-07-28 | C24: Semua agent | D24: c. Tombol / menu / fungsi | E24: Integrasi | F24: Tinggi | G24: Ya | H24: Kunci nama agent tidak konsisten antar endpoint | I24: Endpoint agents mengembalikan finance.collection dan finance.treasury. Payload dashboard mengembalikan agent 'collections' dan 'treasury'. Endpoint actions dan alerts memakai 'collection' dan 'cashflow'. | J24: Satu kunci kanonik per agent di semua endpoint. | K24: Penamaan bergeser antara agent registry, dashboard service, dan alert/action service. Join berdasarkan nama agent akan mengembalikan daftar kosong untuk Treasury. | L24: Backend | M24: 2026-08-04 | N24: Terbuka
A25: QC-021 | B25: 2026-07-28 | C25: Semua agent | D25: d. Prompt dan respons | E25: Konten | F25: Tinggi | G25: Ya | H25: 47 action card dengan duplikasi berat | I25: Finance memiliki minimal lima aksi hampir identik tentang rebalance mix ke SKU bermargin tinggi. Leakage memiliki tiga aksi hampir identik 'Launch duplicate payment recovery'. Collection memiliki empat aksi pada dua pelanggan yang sama. | J25: Rapikan menjadi sekitar tiga sampai lima aksi berbeda per agent untuk demo. | K25: Aksi dibuat per alert tanpa tahap clustering, dan alert-nya sendiri sudah duplikatif. | L25: Backend / logika agent | M25: 2026-08-04 | N25: Terbuka
A26: QC-022 | B26: 2026-07-28 | C26: Semua agent | D26: a. Kesesuaian formula | E26: Logika | F26: Tinggi | G26: Ya | H26: Dampak aksi bertumpuk tanpa pengaman double counting | I26: Menyetujui seluruh set Finance menambahkan +1.500, +1.000, +390, +300, dan dua pergerakan poin persentase pada basis EBITDA yang sama yaitu 4.300, padahal beberapa di antaranya menyasar driver yang sama. | J26: Tampilan portofolio yang menetkan aksi yang tumpang tindih dan menampilkan satu dampak gabungan. | K26: Setiap aksi dinilai terpisah terhadap baseline. | L26: Backend / logika agent | M26: 2026-08-04 | N26: Terbuka
A27: QC-023 | B27: 2026-07-28 | C27: Semua agent | D27: d. Prompt dan respons | E27: Konten | F27: Tinggi | G27: Tidak | H27: 47 alert yang sebenarnya menceritakan sekitar delapan hal | I27: Finance memiliki 12 alert yang pada dasarnya semuanya membahas mix, harga, dan biaya. Cashflow memiliki 12 alert yang mengulang pelanggaran buffer Minggu 5. | J27: Kelompokkan menjadi satu alert per isu dasar, dengan peringkat severity. | K27: Tidak ada deduplikasi pada generator alert. | L27: Backend / logika agent | M27: 2026-08-04 | N27: Terbuka
