Workbook

Sheet 00_Summary
A1: AI Finance Forum mockup - QC summary
A2: Reviewed 28 July 2026 against the live API. 47 findings raised, 62 calculations reconciled, 31 manual tests to run.
A3: All counts below recalculate from 01_Findings. Update that sheet and this page follows.
A5: Headline
A6: Total findings | D6: Demo blockers | G6: Critical | J6: Still open
A7: =COUNTA('01_Findings'!$F$5:$F$66) -> 62 | D7: =COUNTIF('01_Findings'!$G$5:$G$66,"Yes") -> 39 | G7: =COUNTIF('01_Findings'!$F$5:$F$66,"Critical") -> 8 | J7: =COUNTIF('01_Findings'!$N$5:$N$66,"Open") -> 62
A8: of 47 | D8: of 47 | G8: of 47 | J8: of 47
A10: By severity | G10: By agent
A11: Severity | B11: Total | C11: Blockers | D11: Open | E11: Closed | G11: Agent | H11: Total | I11: Blockers | J11: Open
A12: Critical | B12: =COUNTIF('01_Findings'!$F$5:$F$66,A12) -> 8 | C12: =COUNTIFS('01_Findings'!$F$5:$F$66,A12,'01_Findings'!$G$5:$G$66,"Yes") -> 8 | D12: =COUNTIFS('01_Findings'!$F$5:$F$66,A12,'01_Findings'!$N$5:$N$66,"Open") -> 8 | E12: =COUNTIFS('01_Findings'!$F$5:$F$66,A12,'01_Findings'!$N$5:$N$66,"Closed") -> 0 | G12: Finance | H12: =COUNTIF('01_Findings'!$C$5:$C$66,G12) -> 6 | I12: =COUNTIFS('01_Findings'!$C$5:$C$66,G12,'01_Findings'!$G$5:$G$66,"Yes") -> 3 | J12: =COUNTIFS('01_Findings'!$C$5:$C$66,G12,'01_Findings'!$N$5:$N$66,"Open") -> 6
A13: High | B13: =COUNTIF('01_Findings'!$F$5:$F$66,A13) -> 31 | C13: =COUNTIFS('01_Findings'!$F$5:$F$66,A13,'01_Findings'!$G$5:$G$66,"Yes") -> 26 | D13: =COUNTIFS('01_Findings'!$F$5:$F$66,A13,'01_Findings'!$N$5:$N$66,"Open") -> 31 | E13: =COUNTIFS('01_Findings'!$F$5:$F$66,A13,'01_Findings'!$N$5:$N$66,"Closed") -> 0 | G13: Collection | H13: =COUNTIF('01_Findings'!$C$5:$C$66,G13) -> 9 | I13: =COUNTIFS('01_Findings'!$C$5:$C$66,G13,'01_Findings'!$G$5:$G$66,"Yes") -> 3 | J13: =COUNTIFS('01_Findings'!$C$5:$C$66,G13,'01_Findings'!$N$5:$N$66,"Open") -> 9
A14: Medium | B14: =COUNTIF('01_Findings'!$F$5:$F$66,A14) -> 22 | C14: =COUNTIFS('01_Findings'!$F$5:$F$66,A14,'01_Findings'!$G$5:$G$66,"Yes") -> 5 | D14: =COUNTIFS('01_Findings'!$F$5:$F$66,A14,'01_Findings'!$N$5:$N$66,"Open") -> 22 | E14: =COUNTIFS('01_Findings'!$F$5:$F$66,A14,'01_Findings'!$N$5:$N$66,"Closed") -> 0 | G14: Leakage | H14: =COUNTIF('01_Findings'!$C$5:$C$66,G14) -> 8 | I14: =COUNTIFS('01_Findings'!$C$5:$C$66,G14,'01_Findings'!$G$5:$G$66,"Yes") -> 4 | J14: =COUNTIFS('01_Findings'!$C$5:$C$66,G14,'01_Findings'!$N$5:$N$66,"Open") -> 8
A15: Low | B15: =COUNTIF('01_Findings'!$F$5:$F$66,A15) -> 1 | C15: =COUNTIFS('01_Findings'!$F$5:$F$66,A15,'01_Findings'!$G$5:$G$66,"Yes") -> 0 | D15: =COUNTIFS('01_Findings'!$F$5:$F$66,A15,'01_Findings'!$N$5:$N$66,"Open") -> 1 | E15: =COUNTIFS('01_Findings'!$F$5:$F$66,A15,'01_Findings'!$N$5:$N$66,"Closed") -> 0 | G15: Treasury | H15: =COUNTIF('01_Findings'!$C$5:$C$66,G15) -> 10 | I15: =COUNTIFS('01_Findings'!$C$5:$C$66,G15,'01_Findings'!$G$5:$G$66,"Yes") -> 6 | J15: =COUNTIFS('01_Findings'!$C$5:$C$66,G15,'01_Findings'!$N$5:$N$66,"Open") -> 10
A16: Total | B16: =SUM(B12:B15) -> 62 | C16: =SUM(C12:C15) -> 39 | D16: =SUM(D12:D15) -> 62 | E16: =SUM(E12:E15) -> 0 | G16: All | H16: =COUNTIF('01_Findings'!$C$5:$C$66,G16) -> 27 | I16: =COUNTIFS('01_Findings'!$C$5:$C$66,G16,'01_Findings'!$G$5:$G$66,"Yes") -> 21 | J16: =COUNTIFS('01_Findings'!$C$5:$C$66,G16,'01_Findings'!$N$5:$N$66,"Open") -> 27
G17: Finance + Collection | H17: =COUNTIF('01_Findings'!$C$5:$C$66,G17) -> 1 | I17: =COUNTIFS('01_Findings'!$C$5:$C$66,G17,'01_Findings'!$G$5:$G$66,"Yes") -> 1 | J17: =COUNTIFS('01_Findings'!$C$5:$C$66,G17,'01_Findings'!$N$5:$N$66,"Open") -> 1
G18: Collection + Treasury | H18: =COUNTIF('01_Findings'!$C$5:$C$66,G18) -> 1 | I18: =COUNTIFS('01_Findings'!$C$5:$C$66,G18,'01_Findings'!$G$5:$G$66,"Yes") -> 1 | J18: =COUNTIFS('01_Findings'!$C$5:$C$66,G18,'01_Findings'!$N$5:$N$66,"Open") -> 1
A19: By QC area from the brief
A20: QC area | B20: Total | C20: Blockers | D20: Open
A21: a. Formula consistency | B21: =COUNTIF('01_Findings'!$D$5:$D$66,A21) -> 27 | C21: =COUNTIFS('01_Findings'!$D$5:$D$66,A21,'01_Findings'!$G$5:$G$66,"Yes") -> 17 | D21: =COUNTIFS('01_Findings'!$D$5:$D$66,A21,'01_Findings'!$N$5:$N$66,"Open") -> 27
A22: b. Chart accuracy | B22: =COUNTIF('01_Findings'!$D$5:$D$66,A22) -> 8 | C22: =COUNTIFS('01_Findings'!$D$5:$D$66,A22,'01_Findings'!$G$5:$G$66,"Yes") -> 3 | D22: =COUNTIFS('01_Findings'!$D$5:$D$66,A22,'01_Findings'!$N$5:$N$66,"Open") -> 8
A23: c. Button / menu / function | B23: =COUNTIF('01_Findings'!$D$5:$D$66,A23) -> 16 | C23: =COUNTIFS('01_Findings'!$D$5:$D$66,A23,'01_Findings'!$G$5:$G$66,"Yes") -> 12 | D23: =COUNTIFS('01_Findings'!$D$5:$D$66,A23,'01_Findings'!$N$5:$N$66,"Open") -> 16
A24: d. Prompt & response | B24: =COUNTIF('01_Findings'!$D$5:$D$66,A24) -> 9 | C24: =COUNTIFS('01_Findings'!$D$5:$D$66,A24,'01_Findings'!$G$5:$G$66,"Yes") -> 5 | D24: =COUNTIFS('01_Findings'!$D$5:$D$66,A24,'01_Findings'!$N$5:$N$66,"Open") -> 9
A25: f. Dataset | B25: =COUNTIF('01_Findings'!$D$5:$D$66,A25) -> 1 | C25: =COUNTIFS('01_Findings'!$D$5:$D$66,A25,'01_Findings'!$G$5:$G$66,"Yes") -> 1 | D25: =COUNTIFS('01_Findings'!$D$5:$D$66,A25,'01_Findings'!$N$5:$N$66,"Open") -> 1
A26: g. Filters | B26: =COUNTIF('01_Findings'!$D$5:$D$66,A26) -> 1 | C26: =COUNTIFS('01_Findings'!$D$5:$D$66,A26,'01_Findings'!$G$5:$G$66,"Yes") -> 1 | D26: =COUNTIFS('01_Findings'!$D$5:$D$66,A26,'01_Findings'!$N$5:$N$66,"Open") -> 1
A29: Progress
A30: Status | B30: Count | C30: % of all
A31: Terbuka | B31: =COUNTIF('01B_Findings_ID'!$N$5:$N$66,A31) -> 58 | C31: =IFERROR(B31/COUNTA('01_Findings'!$F$5:$F$66),0) -> 0.93548387
A32: Sedang dikerjakan | B32: =COUNTIF('01B_Findings_ID'!$N$5:$N$66,A32) -> 0 | C32: =IFERROR(B32/COUNTA('01_Findings'!$F$5:$F$66),0) -> 0
A33: Sudah diperbaiki - menunggu uji ulang | B33: =COUNTIF('01B_Findings_ID'!$N$5:$N$66,A33) -> 0 | C33: =IFERROR(B33/COUNTA('01_Findings'!$F$5:$F$66),0) -> 0
A34: Uji ulang lulus | B34: =COUNTIF('01B_Findings_ID'!$N$5:$N$66,A34) -> 0 | C34: =IFERROR(B34/COUNTA('01_Findings'!$F$5:$F$66),0) -> 0
A35: Selesai | B35: =COUNTIF('01B_Findings_ID'!$N$5:$N$66,A35) -> 3 | C35: =IFERROR(B35/COUNTA('01_Findings'!$F$5:$F$66),0) -> 0.048387097
A36: Ditunda | B36: =COUNTIF('01B_Findings_ID'!$N$5:$N$66,A36) -> 0 | C36: =IFERROR(B36/COUNTA('01_Findings'!$F$5:$F$66),0) -> 0
A37: Bukan cacat | B37: =COUNTIF('01B_Findings_ID'!$N$5:$N$66,A37) -> 1 | C37: =IFERROR(B37/COUNTA('01_Findings'!$F$5:$F$66),0) -> 0.016129032
A38: Blockers cleared | B38: =COUNTIFS('01B_Findings_ID'!$G$5:$G$66,"Ya",'01B_Findings_ID'!$N$5:$N$66,"Selesai")+COUNTIFS('01B_Findings_ID'!$G$5:$G$66,"Ya",'01B_Findings_ID'!$N$5:$N$66,"Uji ulang lulus") -> 1 | C38: =IFERROR(B38/COUNTIF('01_Findings'!$G$5:$G$66,"Yes"),0) -> 0.025641026
A39: Demo ready when this reaches 100%
A42: How to use this workbook
A43: 01_Findings every defect, with evidence, expected behaviour, likely root cause, owner, target date and status. Yellow columns are QC Tester result to fill in.
A44: 02_Manual_Test_Checklist 31 tests from outside the app. Buttons, menus, sliders, chat and stability. Run these before the event.
A45: 03_Formula_Checks every calculation that reconciled, including the ones that PASS or FAIL.
A46: 04_Dataset_Requirements the client's data volumes against what the mockup has, and where the replacement sits.
...

Sheet 0A_Cari_Cepat
A1: Cari cepat temuan QC
A2: Ketik atau pilih nomor QC di kotak kuning. Seluruh detailnya muncul di bawah. Daftar ringkas semua temuan ada di sebelah kanan.
E4: Daftar ringkas 47 temuan
A5: Nomor QC | B5: QC-062 | C5: =IF(COUNTIF('01_Findings'!$A$5:$A$66,$B$5)=0,"Nomor tidak ada. Isi antara QC-001 sampai QC-047.","Ditemukan di 01_Findings baris "&(MATCH($B$5,'01_Findings'!$A$5:$A$66,0)+4)) -> Ditemukan di 01_Findings baris 66 | E5: No QC | F5: Tingkat | G5: Blocker | H5: Agent | I5: Judul temuan
E6: ='01B_Findings_ID'!A5 -> QC-001 | F6: ='01B_Findings_ID'!F5 -> Kritis | G6: ='01B_Findings_ID'!G5 -> Ya | H6: ='01B_Findings_ID'!C5 -> Leakage | I6: ='01B_Findings_ID'!H5 -> Grafik kategori Leakage menampilkan nol semua
A7: Ringkasan | E7: ='01B_Findings_ID'!A6 -> QC-002 | F7: ='01B_Findings_ID'!F6 -> Kritis | G7: ='01B_Findings_ID'!G6 -> Ya | H7: ='01B_Findings_ID'!C6 -> Semua agent | I7: ='01B_Findings_ID'!H6 -> Empat agent berjalan di atas empat batch data yang tidak berhubungan
B8: Bahasa Indonesia | C8: English | E8: ='01B_Findings_ID'!A7 -> QC-003 | F8: ='01B_Findings_ID'!F7 -> Kritis | G8: ='01B_Findings_ID'!G7 -> Ya | H8: ='01B_Findings_ID'!C7 -> Finance + Collection | I8: ='01B_Findings_ID'!H7 -> Basis pendapatan Collection sekitar 15 kali lipat pendapatan Finance
A9: Tingkat keparahan | B9: =IFERROR(INDEX('01B_Findings_ID'!$F$5:$F$66,MATCH($B$5,'01B_Findings_ID'!$A$5:$A$66,0)),"tidak ditemukan") -> Sedang | C9: =IFERROR(INDEX('01_Findings'!$F$5:$F$66,MATCH($B$5,'01_Findings'!$A$5:$A$66,0)),"tidak ditemukan") -> Medium | E9: ='01B_Findings_ID'!A8 -> QC-004 | F9: ='01B_Findings_ID'!F8 -> Kritis | G9: ='01B_Findings_ID'!G8 -> Ya | H9: ='01B_Findings_ID'!C8 -> Treasury | I9: ='01B_Findings_ID'!H8 -> Aksi penundaan pembayaran menggerakkan headroom ke arah yang salah
A10: Penghambat demo | B10: =IFERROR(INDEX('01B_Findings_ID'!$G$5:$G$66,MATCH($B$5,'01B_Findings_ID'!$A$5:$A$66,0)),"tidak ditemukan") -> Tidak | C10: =IFERROR(INDEX('01_Findings'!$G$5:$G$66,MATCH($B$5,'01_Findings'!$A$5:$A$66,0)),"tidak ditemukan") -> No | E10: ='01B_Findings_ID'!A9 -> QC-005 | F10: ='01B_Findings_ID'!F9 -> Kritis | G10: ='01B_Findings_ID'!G9 -> Ya | H10: ='01B_Findings_ID'!C9 -> Treasury | I10: ='01B_Findings_ID'!H9 -> Aksi mencampur headroom dengan saldo kas dalam satu perbandingan
A11: Agent | B11: =IFERROR(INDEX('01B_Findings_ID'!$C$5:$C$66,MATCH($B$5,'01B_Findings_ID'!$A$5:$A$66,0)),"tidak ditemukan") -> Semua agent | C11: =IFERROR(INDEX('01_Findings'!$C$5:$C$66,MATCH($B$5,'01_Findings'!$A$5:$A$66,0)),"tidak ditemukan") -> All | E11: ='01B_Findings_ID'!A10 -> QC-006 | F11: ='01B_Findings_ID'!F10 -> Kritis | G11: ='01B_Findings_ID'!G10 -> Ya | H11: ='01B_Findings_ID'!C10 -> Semua agent | I11: ='01B_Findings_ID'!H10 -> Riwayat percakapan penuh dengan pesan uji coba developer
A12: Area QC | B12: =IFERROR(INDEX('01B_Findings_ID'!$D$5:$D$66,MATCH($B$5,'01B_Findings_ID'!$A$5:$A$66,0)),"tidak ditemukan") -> c. Tombol / menu / fungsi | C12: =IFERROR(INDEX('01_Findings'!$D$5:$D$66,MATCH($B$5,'01_Findings'!$A$5:$A$66,0)),"tidak ditemukan") -> c. Button / menu / function | E12: ='01B_Findings_ID'!A11 -> QC-007 | F12: ='01B_Findings_ID'!F11 -> Tinggi | G12: ='01B_Findings_ID'!G11 -> Ya | H12: ='01B_Findings_ID'!C11 -> Collection | I12: ='01B_Findings_ID'!H11 -> KPI high-risk dan grafik risk tier tidak sama di layar yang sama
A13: Jenis | B13: =IFERROR(INDEX('01B_Findings_ID'!$E$5:$E$66,MATCH($B$5,'01B_Findings_ID'!$A$5:$A$66,0)),"tidak ditemukan") -> Fitur hilang | C13: =IFERROR(INDEX('01_Findings'!$E$5:$E$66,MATCH($B$5,'01_Findings'!$A$5:$A$66,0)),"tidak ditemukan") -> Feature gap | E13: ='01B_Findings_ID'!A12 -> QC-008 | F13: ='01B_Findings_ID'!F12 -> Tinggi | G13: ='01B_Findings_ID'!G12 -> Ya | H13: ='01B_Findings_ID'!C12 -> Collection | I13: ='01B_Findings_ID'!H12 -> Definisi 'Top 5' berbeda tiga kali di dalam satu agent
A14: Penanggung jawab | B14: =IFERROR(INDEX('01B_Findings_ID'!$L$5:$L$66,MATCH($B$5,'01B_Findings_ID'!$A$5:$A$66,0)),"tidak ditemukan") -> Pemilik demo | C14: =IFERROR(INDEX('01_Findings'!$L$5:$L$66,MATCH($B$5,'01_Findings'!$A$5:$A$66,0)),"tidak ditemukan") -> Demo owner | E14: ='01B_Findings_ID'!A13 -> QC-009 | F14: ='01B_Findings_ID'!F13 -> Tinggi | G14: ='01B_Findings_ID'!G13 -> Ya | H14: ='01B_Findings_ID'!C13 -> Finance | I14: ='01B_Findings_ID'!H13 -> Ada dua target margin EBITDA yang dipakai bersamaan
A15: Target selesai | B15: =IFERROR(INDEX('01B_Findings_ID'!$M$5:$M$66,MATCH($B$5,'01B_Findings_ID'!$A$5:$A$66,0)),"tidak ditemukan") -> 2026-08-04 | C15: =IFERROR(INDEX('01_Findings'!$M$5:$M$66,MATCH($B$5,'01_Findings'!$A$5:$A$66,0)),"tidak ditemukan") -> 2026-08-04 | E15: ='01B_Findings_ID'!A14 -> QC-010 | F15: ='01B_Findings_ID'!F14 -> Tinggi | G15: ='01B_Findings_ID'!G14 -> Ya | H15: ='01B_Findings_ID'!C14 -> Finance | I15: ='01B_Findings_ID'!H14 -> Varians harga sekitar sepuluh kali lebih kecil dari penurunan harga yang diklaim
A16: Status | B16: =IFERROR(INDEX('01B_Findings_ID'!$N$5:$N$66,MATCH($B$5,'01B_Findings_ID'!$A$5:$A$66,0)),"tidak ditemukan") -> Selesai | C16: =IFERROR(INDEX('01_Findings'!$N$5:$N$66,MATCH($B$5,'01_Findings'!$A$5:$A$66,0)),"tidak ditemukan") -> Open | E16: ='01B_Findings_ID'!A15 -> QC-011 | F16: ='01B_Findings_ID'!F15 -> Tinggi | G16: ='01B_Findings_ID'!G15 -> Ya | H16: ='01B_Findings_ID'!C15 -> Finance | I16: ='01B_Findings_ID'!H15 -> Varians COGS disebut dengan dua angka berbeda
A17: Rincian | E17: ='01B_Findings_ID'!A16 -> QC-012 | F17: ='01B_Findings_ID'!F16 -> Tinggi | G17: ='01B_Findings_ID'!G16 -> Tidak | H17: ='01B_Findings_ID'!C16 -> Finance | I17: ='01B_Findings_ID'!H16 -> Dua angka yang hampir sama artinya berbeda
A18: Temuan | B18: =IFERROR(INDEX('01B_Findings_ID'!$H$5:$H$66,MATCH($B$5,'01B_Findings_ID'!$A$5:$A$66,0)),"tidak ditemukan") -> Belum bisa dipastikan apakah chat bisa menampilkan grafik dan tabel | C18: =IFERROR(INDEX('01_Findings'!$H$5:$H$66,MATCH($B$5,'01_Findings'!$A$5:$A$66,0)),"tidak ditemukan") -> Chat cannot be verified to render charts and tables | E18: ='01B_Findings_ID'!A17 -> QC-013 | F18: ='01B_Findings_ID'!F17 -> Sedang | G18: ='01B_Findings_ID'!G17 -> Tidak | H18: ='01B_Findings_ID'!C17 -> Leakage | I18: ='01B_Findings_ID'!H17 -> Batang berlabel 'Current 95%' tidak menunjukkan posisi saat ini
A19: Bukti yang ditemukan | B19: =IFERROR(INDEX('01B_Findings_ID'!$I$5:$I$66,MATCH($B$5,'01B_Findings_ID'!$A$5:$A$66,0)),"tidak ditemukan") -> Mockup menjawab CFO challenge dengan grafik yang dirender ditambah tabel dan lencana keyakinan. Endpoint chat Azure hanya POST dan tidak bisa diuji dari review read-only, jadi status ini belum diketahui, bukan dipastikan hilang. | C19: =IFERROR(INDEX('01_Findings'!$I$5:$I$66,MATCH($B$5,'01_Findings'!$A$5:$A$66,0)),"tidak ditemukan") -> The mockup answers a CFO challenge with a rendered chart plus a table and a confidence badge. The Azure chat endpoint is POST only and cannot be exercised from a read-only review, so this is unknown rather than confirmed missing. | E19: ='01B_Findings_ID'!A18 -> QC-014 | F19: ='01B_Findings_ID'!F18 -> Tinggi | G19: ='01B_Findings_ID'!G18 -> Ya | H19: ='01B_Findings_ID'!C18 -> Leakage | I19: ='01B_Findings_ID'!H18 -> Jumlah flag di KPI tidak cocok dengan tabelnya
A20: Perilaku yang seharusnya | B20: =IFERROR(INDEX('01B_Findings_ID'!$J$5:$J$66,MATCH($B$5,'01B_Findings_ID'!$A$5:$A$66,0)),"tidak ditemukan") -> Konfirmasi lewat uji manual MT-019. Kalau chat hanya mengembalikan teks, ini menjadi kesenjangan nyata. | C20: =IFERROR(INDEX('01_Findings'!$J$5:$J$66,MATCH($B$5,'01_Findings'!$A$5:$A$66,0)),"tidak ditemukan") -> Confirm by running manual test MT-019. If chat returns text only, this becomes a real gap. | E20: ='01B_Findings_ID'!A19 -> QC-015 | F20: ='01B_Findings_ID'!F19 -> Tinggi | G20: ='01B_Findings_ID'!G19 -> Ya | H20: ='01B_Findings_ID'!C19 -> Leakage | I20: ='01B_Findings_ID'!H19 -> Eksposur split invoice muncul di grafik tetapi di luar total
A21: Dugaan akar masalah | B21: =IFERROR(INDEX('01B_Findings_ID'!$K$5:$K$66,MATCH($B$5,'01B_Findings_ID'!$A$5:$A$66,0)),"tidak ditemukan") -> Aplikasi yang di-deploy dibangun dengan lingkup lebih sempit daripada mockup acuan. | C21: =IFERROR(INDEX('01_Findings'!$K$5:$K$66,MATCH($B$5,'01_Findings'!$A$5:$A$66,0)),"tidak ditemukan") -> The deployed app was built to a narrower scope than the reference mockup. | E21: ='01B_Findings_ID'!A20 -> QC-016 | F21: ='01B_Findings_ID'!F20 -> Tinggi | G21: ='01B_Findings_ID'!G20 -> Ya | H21: ='01B_Findings_ID'!C20 -> Collection | I21: ='01B_Findings_ID'!H20 -> Dampak aksi tidak cocok dengan rekomendasinya sendiri
E22: ='01B_Findings_ID'!A21 -> QC-017 | F22: ='01B_Findings_ID'!F21 -> Tinggi | G22: ='01B_Findings_ID'!G21 -> Ya | H22: ='01B_Findings_ID'!C21 -> Treasury | I22: ='01B_Findings_ID'!H21 -> Aksi gabungan hanya menampilkan sebagian dampaknya sendiri
A23: Pemeriksaan formula terkait | E23: ='01B_Findings_ID'!A22 -> QC-018 | F23: ='01B_Findings_ID'!F22 -> Tinggi | G23: ='01B_Findings_ID'!G22 -> Tidak | H23: ='01B_Findings_ID'!C22 -> Collection | I23: ='01B_Findings_ID'!H22 -> Aksi memberi label konsentrasi top-2 sebagai porsi overdue keseluruhan
A24: Perhitungan | B24: =IFERROR(INDEX('03_Formula_Checks'!$D$5:$D$66,MATCH($B$5,'03_Formula_Checks'!$G$5:$G$66,0)),"tidak ada pemeriksaan formula untuk nomor ini") -> tidak ada pemeriksaan formula untuk nomor ini | E24: ='01B_Findings_ID'!A23 -> QC-019 | F24: ='01B_Findings_ID'!F23 -> Tinggi | G24: ='01B_Findings_ID'!G23 -> Ya | H24: ='01B_Findings_ID'!C23 -> Treasury | I24: ='01B_Findings_ID'!H23 -> Aksi credit line berpatokan pada minggu yang salah
A25: Hasil di aplikasi | B25: =IFERROR(INDEX('03_Formula_Checks'!$E$5:$E$66,MATCH($B$5,'03_Formula_Checks'!$G$5:$G$66,0)),"-") -> - | E25: ='01B_Findings_ID'!A24 -> QC-020 | F25: ='01B_Findings_ID'!F24 -> Tinggi | G25: ='01B_Findings_ID'!G24 -> Ya | H25: ='01B_Findings_ID'!C24 -> Semua agent | I25: ='01B_Findings_ID'!H24 -> Kunci nama agent tidak konsisten antar endpoint
A26: Verdict | B26: =IFERROR(INDEX('03_Formula_Checks'!$F$5:$F$66,MATCH($B$5,'03_Formula_Checks'!$G$5:$G$66,0)),"-") -> - | E26: ='01B_Findings_ID'!A25 -> QC-021 | F26: ='01B_Findings_ID'!F25 -> Tinggi | G26: ='01B_Findings_ID'!G25 -> Ya | H26: ='01B_Findings_ID'!C25 -> Semua agent | I26: ='01B_Findings_ID'!H25 -> 47 action card dengan duplikasi berat
E27: ='01B_Findings_ID'!A26 -> QC-022 | F27: ='01B_Findings_ID'!F26 -> Tinggi | G27: ='01B_Findings_ID'!G26 -> Ya | H27: ='01B_Findings_ID'!C26 -> Semua agent | I27: ='01B_Findings_ID'!H26 -> Dampak aksi bertumpuk tanpa pengaman double counting
E28: ='01B_Findings_ID'!A27 -> QC-023 | F28: ='01B_Findings_ID'!F27 -> Tinggi | G28: ='01B_Findings_ID'!G27 -> Tidak | H28: ='01B_Findings_ID'!C27 -> Semua agent | I28: ='01B_Findings_ID'!H27 -> 47 alert yang sebenarnya menceritakan sekitar delapan hal
A29: Catatan | E29: ='01B_Findings_ID'!A28 -> QC-024 | F29: ='01B_Findings_ID'!F28 -> Tinggi | G29: ='01B_Findings_ID'!G28 -> Ya | H29: ='01B_Findings_ID'!C28 -> Leakage | I29: ='01B_Findings_ID'!H28 -> Agent Leakage terbuka pada grafik kosong
A30: Kalau kolom B dan C berbunyi 'tidak ditemukan', berarti nomor QC-nya salah ketik. Gunakan daftar di sebelah kanan. | E30: ='01B_Findings_ID'!A29 -> QC-025 | F30: ='01B_Findings_ID'!F29 -> Tinggi | G30: ='01B_Findings_ID'!G29 -> Tidak | H30: ='01B_Findings_ID'!C29 -> Treasury | I30: ='01B_Findings_ID'!H29 -> Aksi FX menyatakan eksposur turun menjadi sebesar nilai hedge
A31: Temuan yang tidak punya pemeriksaan formula akan menampilkan 'tidak ada pemeriksaan formula untuk nomor ini'. Itu normal, tidak semua temuan berupa hitungan. | E31: ='01B_Findings_ID'!A30 -> QC-026 | F31: ='01B_Findings_ID'!F30 -> Sedang | G31: ='01B_Findings_ID'!G30 -> Tidak | H31: ='01B_Findings_ID'!C30 -> Collection | I31: ='01B_Findings_ID'!H30 -> Tingkat recovery mengabaikan umur piutang
E32: ='01B_Findings_ID'!A31 -> QC-027 | F32: ='01B_Findings_ID'!F31 -> Sedang | G32: ='01B_Findings_ID'!G31 -> Tidak | H32: ='01B_Findings_ID'!C31 -> Finance | I32: ='01B_Findings_ID'!H31 -> Satu persentase margin dibulatkan ke bawah, yang lain dibulatkan normal
E33: ='01B_Findings_ID'!A32 -> QC-028 | F33: ='01B_Findings_ID'!F32 -> Sedang | G33: ='01B_Findings_ID'!G32 -> Tidak | H33: ='01B_Findings_ID'!C32 -> Collection | I33: ='01B_Findings_ID'!H32 -> Gauge DSO menampilkan progres 120% pada metrik yang justru lebih baik bila rendah
E34: ='01B_Findings_ID'!A33 -> QC-029 | F34: ='01B_Findings_ID'!F33 -> Sedang | G34: ='01B_Findings_ID'!G33 -> Tidak | H34: ='01B_Findings_ID'!C33 -> Treasury | I34: ='01B_Findings_ID'!H33 -> Format angka tidak konsisten dalam satu baris KPI
E35: ='01B_Findings_ID'!A34 -> QC-030 | F35: ='01B_Findings_ID'!F34 -> Sedang | G35: ='01B_Findings_ID'!G34 -> Tidak | H35: ='01B_Findings_ID'!C34 -> Collection | I35: ='01B_Findings_ID'!H34 -> Aksi memberi label saldo dua pelanggan sebagai total piutang overdue
E36: ='01B_Findings_ID'!A35 -> QC-031 | F36: ='01B_Findings_ID'!F35 -> Sedang | G36: ='01B_Findings_ID'!G35 -> Tidak | H36: ='01B_Findings_ID'!C35 -> Leakage | I36: ='01B_Findings_ID'!H35 -> Aksi memakai angka setahun sementara dashboard menampilkan angka per siklus
E37: ='01B_Findings_ID'!A36 -> QC-032 | F37: ='01B_Findings_ID'!F36 -> Sedang | G37: ='01B_Findings_ID'!G36 -> Tidak | H37: ='01B_Findings_ID'!C36 -> Leakage | I37: ='01B_Findings_ID'!H36 -> Angka 900 mn yang sama muncul dengan tiga nama berbeda
E38: ='01B_Findings_ID'!A37 -> QC-033 | F38: ='01B_Findings_ID'!F37 -> Sedang | G38: ='01B_Findings_ID'!G37 -> Tidak | H38: ='01B_Findings_ID'!C37 -> Collection | I38: ='01B_Findings_ID'!H37 -> Dua grafik di layar yang sama mengurutkan pasangan data ke arah berlawanan
E39: ='01B_Findings_ID'!A38 -> QC-034 | F39: ='01B_Findings_ID'!F38 -> Sedang | G39: ='01B_Findings_ID'!G38 -> Tidak | H39: ='01B_Findings_ID'!C38 -> Treasury | I39: ='01B_Findings_ID'!H38 -> Batang bernilai nol di sebelah batang bernilai terbaca seperti gagal render
E40: ='01B_Findings_ID'!A39 -> QC-035 | F40: ='01B_Findings_ID'!F39 -> Sedang | G40: ='01B_Findings_ID'!G39 -> Ya | H40: ='01B_Findings_ID'!C39 -> Semua agent | I40: ='01B_Findings_ID'!H39 -> Tidak ada grafik yang mencantumkan periodenya
E41: ='01B_Findings_ID'!A40 -> QC-036 | F41: ='01B_Findings_ID'!F40 -> Sedang | G41: ='01B_Findings_ID'!G40 -> Tidak | H41: ='01B_Findings_ID'!C40 -> Finance | I41: ='01B_Findings_ID'!H40 -> Grafik samping menduplikasi grafik utama persis
...

Sheet 00B_Panduan_Bahasa
A1: Panduan QC Tracker - AI Finance Forum
A2: Dokumen ini menjelaskan isi workbook QC dan cara memakainya. Ditinjau 28 Juli 2026.
A4: 1. APA ITU WORKBOOK INI
A5: Workbook ini adalah hasil pemeriksaan mutu (quality control) atas mockup AI Finance Forum, plus alat pelacak
A6: perbaikannya. Isinya dua hal: daftar temuan yang harus diperbaiki, dan daftar pengujian yang masih harus
A7: dijalankan secara manual sebelum demo di depan para CFO.
A9: 2. BAGAIMANA PEMERIKSAAN INI DILAKUKAN, DAN APA BATASNYA
A10: Pemeriksaan dilakukan langsung terhadap API aplikasi yang sedang berjalan. Semua endpoint GET dibaca:
A11: dashboard keempat agent, KPI, konfigurasi grafik, 47 alert, 47 action card, dan riwayat percakapan.
A12: Batas yang penting untuk Anda ketahui: tombol, menu, slider simulator, kotak chat, serta tombol approve dan
A13: simulate pada action semuanya berjalan lewat POST atau di sisi browser. Semua itu TIDAK bisa diuji dari luar.
A14: Karena itu 31 pengujian manual disiapkan di sheet 02. Bagian tersebut masih berstatus belum diuji.
... A97: Ketiga asumsi ini ditandai kuning di workbook dataset.

Sheet 01_Findings
A1: Testing listing - findings tracker
A2: AI Finance Forum mockup. Reviewed 28 July 2026 against the live API. Update Status, Target date and Retest columns as fixes land.
A4: ID | B4: Date found | C4: Agent | D4: QC area | E4: Type | F4: Severity | G4: Demo blocker | H4: Finding | I4: Evidence observed | J4: Expected behaviour | K4: Likely root cause | L4: Fix owner | M4: Target date | N4: Status | O4: Retest date | P4: Retest result | Q4: Notes
A5: QC-001 | B5: 2026-07-28 | C5: Leakage | D5: a. Formula consistency | E5: Data | F5: Critical | G5: Yes | H5: Leakage category chart returns all zeros | I5: GET /api/html/dashboard/finance.leakage returns views.categories.data with every value 0.0 (Bank-change fraud 0, Duplicate payment 0, Overbilling 0, Lost discount 0, Split/threshold 0). The side donut 'Leakage mix' is also all zeros, the worklist Amount column is '0' for all 10 rows, and the vendor radar 'At risk' column is '0' for all 8 vendors. Meanwhile the KPI tiles show 7,845 / 3,800 / 3,050 / 4,300. | J5: Category amounts should sum to the 7,845 mn shown on the 'Flagged this cycle' KPI. | K5: The amount column is not mapped for import batch 17. Aggregate KPIs are computed from a different query than the per-category breakdown. | L5: Backend / data | M5: 2026-07-31 | N5: Open
A6: QC-002 | B6: 2026-07-28 | C6: All | D6: a. Formula consistency | E6: Architecture | F6: Critical | G6: Yes | H6: The four agents run on four unrelated data batches | I6: import_batch_id is 19 for Finance, 17 for Leakage, 11 for Collection and 2 for Treasury. | J6: One shared ledger, so any number can be traced across agents. | K6: No single source of truth. Each agent was seeded independently. | L6: Backend / data | M6: 2026-07-31 | N6: Open
A7: QC-003 | B7: 2026-07-28 | C7: Finance + Collection | D7: a. Formula consistency | E7: Formula | F7: Critical | G7: Yes | H7: Collection revenue base is about 15 times the Finance revenue | I7: Collection raw.summary.annual_credit_sales_idr_mn = 700,000. Finance KPI revenue = 46,510. AR of 110,000 is 2.4 times the entire Finance annual revenue. | J7: DSO must be divided by the same revenue the Finance agent reports. | K7: Two unrelated seed datasets (see the batch finding above). | L7: Backend / data | M7: 2026-07-31 | N7: Open
A8: QC-004 | B8: 2026-07-28 | C8: Treasury | D8: a. Formula consistency | E8: Formula | F8: Critical | G8: Yes | H8: Deferral action moves headroom the wrong way | I8: Action 'Defer noncritical Week 5 payable' shows impact 'week6 headroom: 1012.5 +3000 -> 4012.5'. Moving a payable INTO Week 6 must reduce Week 6 headroom, not increase it. Its own spec also claims Week 5 cash rises above IDR 10,000 mn; 6,997.5 + 3,000 = 9,997.5. | J8: Week 5 headroom -1,002.5 -> +1,997.5 and Week 6 headroom 1,012.5 -> -1,987.5, so the trade-off is visible. | K8: The impact string is authored text, not computed from the forecast. Sign and week label are both wrong. | L8: Backend / agent logic | M8: 2026-07-31 | N8: Open
A9: QC-005 | B9: 2026-07-28 | C9: Treasury | D9: a. Formula consistency | E9: Formula | F9: Critical | G9: Yes | H9: Action mixes headroom with closing cash in one before-and-after | I9: Action 'Accelerate Customer A collection' shows 'cash buffer: -1002.5 -> +6997.5'. -1,002.5 is headroom, 6,997.5 is closing cash. Its own spec says recover at least IDR 1,100 mn, which would give +97.5 headroom. | J9: One unit per metric. Either headroom -1,002.5 -> +97.5, or closing cash 6,997.5 -> 8,097.5. | K9: Impact strings are free text with no unit validation. | L9: Backend / agent logic | M9: 2026-07-31 | N9: Open
A10: QC-006 | B10: 2026-07-28 | C10: All | D10: d. Prompt & response | E10: Content | F10: Critical | G10: Yes | H10: Conversation history is full of developer test messages | I10: GET /api/html/conversations returns roughly 190 saved conversations including 'test', 'asdsad', 'hello world', 'Test test test', 'selamat pagi', 'does all the right tools work?', 'gimme data', 'show me the cahrt'. | J10: A curated history containing only credible CFO questions, or the history panel hidden for the event. | K10: No separation between the development environment and the demo environment. | L10: Demo owner | M10: 2026-07-31 | N10: Open
A11: QC-007 | B11: 2026-07-28 | C11: Collection | D11: a. Formula consistency | E11: Formula | F11: High | G11: Yes | H11: High-risk KPI and the risk tier chart disagree on the same screen | I11: KPI 'High-risk exposure' = 2,500 mn with the label 'provision / high tier'. The 'Risk exposure by tier' chart shows High = 5,000 mn. | J11: Either the KPI is renamed 'High-risk provision', or it shows 5,000 to match the chart. | K11: The KPI reads the provision field while the chart reads the exposure field. Same label, two meanings. | L11: Backend / agent logic | M11: 2026-08-04 | N11: Open
A12: QC-008 | B12: 2026-07-28 | C12: Collection | D12: a. Formula consistency | E12: Definition | F12: High | G12: Yes | H12: 'Top 5' is defined three different ways inside one agent | I12: Options chart 'Top 5 - 46d' uses worklist rows 1 to 5 (21,300 mn recovery). Alert 'DSO gap and overdue concentration' uses top 5 by overdue amount (27,000 mn, 71.17%). Alert 'Mid-tier accounts can unlock most DSO gap' uses top 5 by expected recovery (23,225 mn). | J12: One definition, stated on screen. | K12: Each surface computes its own ranking. | L12: Backend / agent logic | M12: 2026-08-04 | N12: Open
A13: QC-009 | B13: 2026-07-28 | C13: Finance | D13: a. Formula consistency | E13: Formula | F13: High | G13: Yes | H13: Two different EBITDA margin targets are in use | I13: The KPI tile and the simulator gauge both say 'target 15%'. The alert 'Price recovery opportunity' says the budget margin is 15.7% (budget EBITDA 7,200 / budget revenue 46,000 = 15.65%). | J13: One target. If budget is the reference, use 15.7% everywhere. | K13: The gauge target is hardcoded to a round 15% while the alerts compute it from the budget. | L13: Backend / agent logic | M13: 2026-08-04 | N13: Open
A14: QC-010 | B14: 2026-07-28 | C14: Finance | D14: a. Formula consistency | E14: Formula | F14: High | G14: Yes | H14: Price variance is roughly ten times too small for the stated price decline | I14: Alerts state blended price fell 7.6%, from IDR 127.7k to IDR 118.0k per unit. The EBITDA waterfall shows a price step of only -390 mn on revenue of 46,510 mn. A 7.6% blended price decline implies roughly -3,800 mn. | J14: The price step and the stated percentage decline must be derived from the same calculation. | K14: The waterfall steps and the alert narrative are generated from different sources. Needs verification against the underlying model. | L14: Backend / agent logic | M14: 2026-08-04 | N14: Open
A15: QC-011 | B15: 2026-07-28 | C15: Finance | D15: a. Formula consistency | E15: Formula | F15: High | G15: Yes | H15: COGS variance is stated as two different numbers | I15: Alerts and actions use IDR 2,930 mn of COGS overrun. The EBITDA waterfall shows the Cost and FX step as -1,880 mn. | J15: One cost variance figure across the waterfall, the alerts and the action cards. | K15: The waterfall may net FX into cost while the alert reports gross cost. Not reconciled either way. | L15: Backend / agent logic | M15: 2026-08-04 | N15: Open
A16: QC-012 | B16: 2026-07-28 | C16: Finance | D16: d. Prompt & response | E16: Content | F16: High | G16: No | H16: Two near-identical numbers mean two different things | I16: Cost and FX step = -1,880 mn. Mix plus price = -1,491 + -390 = -1,881 mn, and an alert reports 'IDR 1,881mn combined profitability loss'. | J16: Separate the two on screen, or round them differently so they cannot be confused live. | K16: Coincidence in the seed data, but it will cause confusion on stage. | L16: Demo owner | M16: 2026-08-04 | N16: Open
A17: QC-013 | B17: 2026-07-28 | C17: Leakage | D17: a. Formula consistency | E17: Formula | F17: Medium | G17: No | H17: The bar labelled 'Current 95%' does not show the current position | I17: In the Leakage 'Recovery scenario' chart the third bar is labelled 'Current 95%' and equals 7,577.5. It applies 95% to duplicates and overbilling together. The real current position applies 95% to duplicates and 90% to overbilling, which gives 7,557.5. That is the figure the 'Total protected' KPI (7,558) and the side chart 'Protected vs at risk' (7,557.5) both carry. Difference = 400 x 5% = 20 mn. IMPORTANT: this is not visible to the eye. The KPI and the side chart agree with each other, so a side-by-side glance looks correct. Only the recovery chart differs, and 20 out of 7,578 is 0.26%. It surfaces in a tooltip, a data label, or when someone asks the agent for the number. | J17: The 'Current' bar uses the same assumption set as the KPI and reads 7,557.5. Alternatively rename the bar to '95% across the board' so it stops claiming to be the current position. | K17: The recovery chart hardcodes one claw-back rate across all recoverable items. The simulator baseline uses two separate rates. Neither is wrong on its own; the label 'Current' is what makes the chart incorrect. | L17: Backend / agent logic | M17: 2026-08-11 | N17: Open | Q17: Severity lowered from High to Medium on 28 Jul 2026 after re-checking with Susan. Reason: the gap is not visible to the eye and is not a demo blocker. The defect is still real and still needs fixing.
A18: QC-014 | B18: 2026-07-28 | C18: Leakage | D18: a. Formula consistency | E18: Formula | F18: High | G18: Yes | H18: Flag count on the KPI does not match the tables | I18: KPI 'Flagged this cycle' says '22 flags'. The action worklist lists 10 rows and the vendor radar totals 10 flags across 8 vendors. | J18: The count on the KPI equals the number of rows a user can actually open. | K18: The KPI counts raw exceptions while the tables show a filtered top-N with no 'showing 10 of 22' label. | L18: Backend / agent logic | M18: 2026-08-04 | N18: Open
A19: QC-015 | B19: 2026-07-28 | C19: Leakage | D19: a. Formula consistency | E19: Formula | F19: High | G19: Yes | H19: Split-invoice exposure sits in the chart but outside the total | I19: At risk = 7,845 = fraud 3,800 + duplicates 3,050 + overbilling 400 + other blocked 500 + lost 95. The alert 'Split invoice threshold evasion' reports IDR 1,950 mn, and 'Split / threshold' is one of the five chart categories, yet 1,950 is not in the 7,845. | J19: Either at risk becomes 9,795, or split invoices are excluded from the chart and explained. | K19: The at-risk aggregate was built before split-threshold detection was added. | L19: Backend / agent logic | M19: 2026-08-04 | N19: Open
A20: QC-016 | B20: 2026-07-28 | C20: Collection | D20: a. Formula consistency | E20: Formula | F20: High | G20: Yes | H20: Action impact does not match its own recommendation | I20: Action 'Accelerate top overdue collections' spec says collect at least IDR 20,000 mn. Impact says 'DSO: 57.36 -5.21 -> 52.14'. -5.21 days corresponds to 10,000 mn (10,000 / 1,917.8). 20,000 mn gives -10.43 days. | J20: Impact recomputed from the amount in the spec. | K20: Impact string copied from a different action. | L20: Backend / agent logic | M20: 2026-08-04 | N20: Open
A21: QC-017 | B21: 2026-07-28 | C21: Treasury | D21: a. Formula consistency | E21: Formula | F21: High | G21: Yes | H21: Combined action shows only part of its own effect | I21: Action 'Bridge Week 5 funding gap' spec says accelerate 2,000 mn plus defer 3,000 mn, which is 5,000 mn. Impact shows 'headroom: -1002.5 -> +1997.5', a movement of only 3,000 mn. | J21: -1,002.5 -> +3,997.5. | K21: Only the deferral leg is being computed. | L21: Backend / agent logic | M21: 2026-08-04 | N21: Open
A22: QC-018 | B22: 2026-07-28 | C22: Collection | D22: a. Formula consistency | E22: Labelling | F22: High | G22: No | H22: Action labels the top-2 concentration as the overall overdue share | I22: Action 'Escalate concentrated exposures' shows 'Overdue share: 43.5% -10% -> 33.5%'. The dashboard overdue share is 34.5% (37,935 / 110,000). 43.5% is the top-2 share of overdue (16,500 / 37,935). | J22: Label it 'Top-2 share of overdue'. | K22: Reused metric name for a different denominator. | L22: Backend / agent logic | M22: 2026-08-04 | N22: Open
A23: QC-019 | B23: 2026-07-28 | C23: Treasury | D23: a. Formula consistency | E23: Formula | F23: High | G23: Yes | H23: Credit line action is anchored to the wrong week | I23: Action 'Pre-arrange contingent credit capacity' uses baseline 1,012.5, which is Week 6 headroom. The breach is in Week 5 at -1,002.5. Its spec then targets a buffer above 4,000 mn. | J23: Baseline -1,002.5 (Week 5), result +1,997.5 after a 3,000 mn draw. | K23: Wrong week selected as the baseline. | L23: Backend / agent logic | M23: 2026-08-04 | N23: Open
A24: QC-020 | B24: 2026-07-28 | C24: All | D24: c. Button / menu / function | E24: Integration | F24: High | G24: Yes | H24: Agent keys are inconsistent between endpoints | I24: /api/html/agents returns finance.collection and finance.treasury. The dashboard payload returns agent 'collections' and 'treasury'. /api/actions and /api/alerts use 'collection' and 'cashflow'. | J24: One canonical key per agent across every endpoint. | K24: Naming drift between the agent registry, the dashboard service and the alert or action service. Any join on agent name will silently return an empty list for Treasury. | L24: Backend | M24: 2026-08-04 | N24: Open
A25: QC-021 | B25: 2026-07-28 | C25: All | D25: d. Prompt & response | E25: Content | F25: High | G25: Yes | H25: 47 action cards with heavy duplication | I25: Finance has at least five near-identical actions to rebalance mix toward higher-margin SKUs. Leakage has three near-identical 'Launch duplicate payment recovery' cards. Collection has four cards on the same two customers. | J25: Deduplicate to roughly three to five distinct actions per agent for the demo. | K25: Actions are generated per alert with no clustering step, and the alerts are themselves duplicated. | L25: Backend / agent logic | M25: 2026-08-04 | N25: Open
A26: QC-022 | B26: 2026-07-28 | C26: All | D26: a. Formula consistency | E26: Logic | F26: High | G26: Yes | H26: Action impacts stack with no double-count guard | I26: Approving the Finance set adds +1,500, +1,000, +390, +300 and two percentage-point moves to the same EBITDA base of 4,300, and several of them address the same driver. | J26: A portfolio view that nets overlapping actions and shows a single combined impact. | K26: Each action is scored in isolation against the baseline. | L26: Backend / agent logic | M26: 2026-08-04 | N26: Open
A27: QC-023 | B27: 2026-07-28 | C27: All | D27: d. Prompt & response | E27: Content | F27: High | G27: No | H27: 47 alerts telling roughly eight distinct stories | I27: Finance has 12 alerts, essentially all describing mix, price and cost. Cashflow has 12 restating the Week 5 breach. | J27: Cluster to one alert per underlying issue with a severity ranking. | K27: No deduplication in the alert generator. | L27: Backend / agent logic | M27: 2026-08-04 | N27: Open
A28: QC-024 | B28: 2026-07-28 | C28: Leakage | D28: b. Chart accuracy | E28: Chart | F28: High | G28: Yes | H28: The Leakage agent opens on an empty chart | I28: default_view is 'categories', which is the all-zero chart described in the first finding. | J28: Open on a populated view. | K28: Same root cause as the zero-amount issue. | L28: Backend / data | M28: 2026-08-04 | N28: Open
A29: QC-025 | B29: 2026-07-28 | C29: Treasury | D29: a. Formula consistency | E29: Labelling | F29: High | G29: No | H29: FX action states exposure falls to the hedge amount | I29: Action 'Increase near-term FX protection' shows 'FX exposure: 3.3m -1.3m -> 2.0m'. Hedging the unhedged 1.3M should take unhedged exposure from 1.3M to zero, or coverage from 61% to 100%. As written, 2.0M is the hedge amount, not the residual exposure. | J29: 'Unhedged exposure: USD 1.3m -> USD 0' or 'Coverage: 61% -> 100%'. | K29: Confuses gross exposure with hedged notional. | L29: Backend / agent logic | M29: 2026-08-04 | N29: Open
... A51: QC-047 | B51: 2026-07-28 | C51: Collection + Treasury | D51: a. Formula consistency | E51: Logic | F51: High | G51: Yes | H51: Treasury collection lever is not linked to the Collection book | I51: The Treasury simulator caps 'Accelerate collection' at IDR 8,000 mn. The Collection agent says the single largest customer alone frees 8,500 mn and all overdue frees 32,163 mn. | J51: The Treasury lever maximum should be derived from the Collection worklist, and pulling cash in Treasury should reduce AR in Collection. | K51: The two simulators are independent, so the cross-agent handover is narrative only, not computed. | L51: Backend / agent logic | M51: 2026-08-04 | N51: Open
A52: QC-048 | B52: 2026-07-28 | C52: All | D52: a. Formula consistency | E52: Architecture | F52: Medium | G52: No | H52: The mockup and the deployed app disagree on the numbers | I52: The standalone file 03_CFO_FinanceAI_Suite_Mockup_v9.4 and the deployed Azure app carry different figures. Week 5 cash: 6,698 vs 6,997.5. Forecast length: 14 weeks vs 13. Week 5 shortfall: -1,302 vs -1,002.5. Leakage category chart: populated vs all zeros. Recovery chart third bar: live 'Now' vs hardcoded 'Current 95%'. CLARIFIED 28 Jul: the Azure link is the build under test; the HTML file is the design reference that gets its dataset refreshed. So this is not two competing products, it is a reference that the app has drifted away from. | J52: After both are updated to the replacement dataset, the app's figures should match the reference mockup. Any remaining difference should be a deliberate, documented choice. | K52: The two tracks were updated at different times. The HTML reference is ahead of the deployed app on at least two fixes (leakage categories, recovery bar). | L52: Demo owner + Backend | M52: 2026-08-11 | N52: Open | Q52: Re-graded from Critical to Medium on 28 Jul 2026 after Susan clarified the roles: the Azure link is what gets tested, the mockup only needs its dataset refreshed. Not a demo blocker because the HTML is not shown to the audience. Still worth tracking so the app does not keep drifting from its own reference. An updated mockup carrying the replacement dataset was delivered as v10.0.
A53: QC-049 | B53: 2026-07-28 | C53: All | D53: c. Button / menu / function | E53: Feature gap | F53: Critical | G53: Yes | H53: No formula explanation panel anywhere in the app | I53: The mockup carries an info registry of about 40 entries. Every KPI, chart, table row and simulator stat has an (i) icon that opens the plain-language meaning plus the exact formula, for example 'Closing = Opening + Net cash flow; W5 = 5,789 vs 8,000 buffer'. The Azure dashboard payload has no equivalent field, and openapi.json exposes no endpoint for it. | J53: Every element on screen can explain its own number on demand, with the formula shown. | K53: The deployed app was built to a narrower scope than the reference mockup. | L53: Backend + frontend | M53: 2026-08-04 | N53: Open | Q53: Added 28 Jul 2026 from a feature comparison of mockup v10.0 against the Azure openapi.json endpoint list.
A54: QC-050 | B54: 2026-07-28 | C54: All | D54: c. Button / menu / function | E54: Feature gap | F54: Critical | G54: Yes | H54: No guided story mode | I54: The mockup has a 'Play the CFO story' control that walks the whole narrative automatically. The Azure app has no equivalent. openapi.json shows chat, dashboard, simulators, alerts and actions only. | J54: A scripted guided run, so the demo does not depend on live typing and can be repeated identically. | K54: The deployed app was built to a narrower scope than the reference mockup. | L54: Frontend | M54: 2026-08-04 | N54: Open | Q54: Added 28 Jul 2026 from a feature comparison of mockup v10.0 against the Azure openapi.json endpoint list.
A55: QC-051 | B55: 2026-07-28 | C55: All | D55: c. Button / menu / function | E55: Feature gap | F55: High | G55: Yes | H55: Simulator cannot save, load or compare a scenario | I55: The mockup has Save scenario, a Load scenario dropdown and Compare (n). The Azure app exposes only four recalculate endpoints, with no persistence and no comparison. | J55: At least save one scenario and compare it against the baseline side by side. | K55: The deployed app was built to a narrower scope than the reference mockup. | L55: Backend + frontend | M55: 2026-08-08 | N55: Open | Q55: Added 28 Jul 2026 from a feature comparison of mockup v10.0 against the Azure openapi.json endpoint list.
A56: QC-052 | B56: 2026-07-28 | C56: All | D56: c. Button / menu / function | E56: Feature gap | F56: High | G56: Yes | H56: Simulator has no presets | I56: The mockup offers four named presets per agent, for example 'Recommended: cover 1.8M @ +3%' and 'Base (95% dup / 90% overbill)'. The Azure simulator payload carries inputs and baseline only. | J56: Three to four named presets per agent, so the presenter never has to drag sliders precisely on camera. | K56: The deployed app was built to a narrower scope than the reference mockup. | L56: Backend + frontend | M56: 2026-08-08 | N56: Open | Q56: Added 28 Jul 2026 from a feature comparison of mockup v10.0 against the Azure openapi.json endpoint list.
A57: QC-053 | B57: 2026-07-28 | C57: All | D57: c. Button / menu / function | E57: Feature gap | F57: High | G57: No | H57: Simulator has no scope selector | I57: The mockup lets the user switch between All lines and FX lines, so a lever can be applied to part of the portfolio. The Azure simulator applies every lever to everything. | J57: A scope control, or a clear statement on screen that levers apply to the whole book. | K57: The deployed app was built to a narrower scope than the reference mockup. | L57: Backend + frontend | M57: 2026-08-11 | N57: Open | Q57: Added 28 Jul 2026 from a feature comparison of mockup v10.0 against the Azure openapi.json endpoint list.
A58: QC-054 | B58: 2026-07-28 | C58: All | D58: c. Button / menu / function | E58: Feature gap | F58: High | G58: Yes | H58: KPI tiles have no trend sparkline | I58: Every mockup KPI carries a five-point sparkline. The Azure KPI object has id, view, label, value, unit, delta, alert, value_num, target_num, progress and status, with no trend series. | J58: A short trend series on each KPI, so a CFO sees direction without opening a chart. | K58: The deployed app was built to a narrower scope than the reference mockup. | L58: Backend + frontend | M58: 2026-08-08 | N58: Open | Q58: Added 28 Jul 2026 from a feature comparison of mockup v10.0 against the Azure openapi.json endpoint list.
A59: QC-055 | B59: 2026-07-28 | C59: All | D59: c. Button / menu / function | E59: Feature gap | F59: High | G59: Yes | H59: Actions carry no confidence level | I59: The mockup labels each recommendation, for example 'High confidence' or 'Medium, customer must agree'. The Azure action object has id, action, agent, routes, alert_id, status, spec, impact, simulation_summary and created_at, with no confidence field. | J59: A confidence level and its basis on every action. A CFO will not approve a recommendation that will not say how sure it is. | K59: The deployed app was built to a narrower scope than the reference mockup. | L59: Backend | M59: 2026-08-08 | N59: Open | Q59: Added 28 Jul 2026 from a feature comparison of mockup v10.0 against the Azure openapi.json endpoint list.
A60: QC-056 | B60: 2026-07-28 | C60: All | D60: c. Button / menu / function | E60: Feature gap | F60: High | G60: Yes | H60: No visible cascade when an action executes | I60: The mockup animates the routing, showing each recipient picking the task up in turn. The Azure app has an approve endpoint that returns a status, with nothing to watch. | J60: A visible execution trail across the recipients. This is the single strongest agentic moment in the demo and it currently has no visual. | K60: The deployed app was built to a narrower scope than the reference mockup. | L60: Frontend | M60: 2026-08-08 | N60: Open | Q60: Added 28 Jul 2026 from a feature comparison of mockup v10.0 against the Azure openapi.json endpoint list.
A61: QC-057 | B61: 2026-07-28 | C61: All | D61: c. Button / menu / function | E61: Feature gap | F61: High | G61: Yes | H61: No status notification feed | I61: The mockup has a bell with a live feed of what the agent did and what awaits approval, plus toast pop-ups. Azure has alerts, which are findings, not activity. There is no endpoint for agent activity. | J61: A separate activity feed, distinct from alerts, showing what the agent executed and when. | K61: The deployed app was built to a narrower scope than the reference mockup. | L61: Backend + frontend | M61: 2026-08-11 | N61: Open | Q61: Added 28 Jul 2026 from a feature comparison of mockup v10.0 against the Azure openapi.json endpoint list.
A62: QC-058 | B62: 2026-07-28 | C62: All | D62: c. Button / menu / function | E62: Feature gap | F62: High | G62: Yes | H62: No Bahasa Indonesia toggle | I62: The mockup has a Bahasa ON switch. The Azure app has no language parameter on any endpoint. | J62: A language switch. The audience is Indonesian, and being able to flip to Bahasa mid-demo is a differentiator no competitor will show. | K62: The deployed app was built to a narrower scope than the reference mockup. | L62: Backend + frontend | M62: 2026-08-08 | N62: Open | Q62: Added 28 Jul 2026 from a feature comparison of mockup v10.0 against the Azure openapi.json endpoint list.
...

Sheet 01B_Findings_ID
A1: Daftar temuan pengujian (Bahasa Indonesia)
A2: Nomor QC sama persis dengan sheet 01_Findings. Kolom kuning diisi oleh tim. Sheet 00_Summary menghitung dari sheet 01, jadi status wajib diperbarui di kedua sheet atau pilih satu sheet sebagai acuan.
A4: No QC | B4: Tanggal temuan | C4: Agent | D4: Area QC | E4: Jenis | F4: Tingkat | G4: Penghambat demo | H4: Temuan | I4: Bukti yang ditemukan | J4: Perilaku yang seharusnya | K4: Dugaan akar masalah | L4: Penanggung jawab | M4: Target selesai | N4: Status | O4: Tanggal uji ulang | P4: Hasil uji ulang | Q4: Catatan
A5: QC-001 | B5: 2026-07-28 | C5: Leakage | D5: a. Kesesuaian formula | E5: Data | F5: Kritis | G5: Ya | H5: Grafik kategori Leakage menampilkan nol semua | I5: Endpoint dashboard finance.leakage mengembalikan views.categories.data dengan semua nilai 0.0 (Bank-change fraud 0, Duplicate payment 0, Overbilling 0, Lost discount 0, Split/threshold 0). Donut 'Leakage mix' juga nol semua, kolom Amount pada worklist berisi '0' untuk 10 baris, dan kolom 'At risk' pada vendor radar berisi '0' untuk 8 vendor. Padahal KPI tile menampilkan 7.845 / 3.800 / 3.050 / 4.300. | J5: Jumlah per kategori harus sama dengan 7.845 mn yang tampil di KPI 'Flagged this cycle'. | K5: Kolom amount tidak ter-mapping untuk import batch 17. KPI agregat dihitung dari query yang berbeda dengan query rincian per kategori. | L5: Backend / data | M5: 2026-07-31 | N5: Terbuka
A6: QC-002 | B6: 2026-07-28 | C6: Semua agent | D6: a. Kesesuaian formula | E6: Arsitektur | F6: Kritis | G6: Ya | H6: Empat agent berjalan di atas empat batch data yang tidak berhubungan | I6: import_batch_id = 19 untuk Finance, 17 untuk Leakage, 11 untuk Collection, dan 2 untuk Treasury. | J6: Satu ledger bersama, sehingga setiap angka bisa ditelusuri lintas agent. | K6: Tidak ada single source of truth. Setiap agent di-seed secara terpisah. | L6: Backend / data | M6: 2026-07-31 | N6: Terbuka
A7: QC-003 | B7: 2026-07-28 | C7: Finance + Collection | D7: a. Kesesuaian formula | E7: Formula | F7: Kritis | G7: Ya | H7: Basis pendapatan Collection sekitar 15 kali lipat pendapatan Finance | I7: Collection raw.summary.annual_credit_sales_idr_mn = 700.000. KPI revenue Finance = 46.510. Piutang 110.000 setara 2,4 kali seluruh pendapatan tahunan Finance. | J7: DSO harus dibagi dengan pendapatan yang sama dengan yang dilaporkan agent Finance. | K7: Dua dataset seed yang tidak berhubungan (lihat temuan batch di atas). | L7: Backend / data | M7: 2026-07-31 | N7: Terbuka
A8: QC-004 | B8: 2026-07-28 | C8: Treasury | D8: a. Kesesuaian formula | E8: Formula | F8: Kritis | G8: Ya | H8: Aksi penundaan pembayaran menggerakkan headroom ke arah yang salah | I8: Aksi 'Defer noncritical Week 5 payable' menampilkan dampak 'week6 headroom: 1012.5 +3000 -> 4012.5'. Memindahkan utang KE Minggu 6 seharusnya MENURUNKAN headroom Minggu 6, bukan menaikkan. Spec-nya juga mengklaim kas Minggu 5 naik di atas IDR 10.000 mn, padahal 6.997,5 + 3.000 = 9.997,5. | J8: Headroom Minggu 5: -1.002,5 -> +1.997,5 dan headroom Minggu 6: 1.012,5 -> -1.987,5, sehingga trade-off-nya terlihat. | K8: Teks dampak ditulis manual, bukan dihitung dari forecast. Tanda (+/-) dan label minggu dua-duanya salah. | L8: Backend / logika agent | M8: 2026-07-31 | N8: Terbuka
A9: QC-005 | B9: 2026-07-28 | C9: Treasury | D9: a. Kesesuaian formula | E9: Formula | F9: Kritis | G9: Ya | H9: Aksi mencampur headroom dengan saldo kas dalam satu perbandingan | I9: Aksi 'Accelerate Customer A collection' menampilkan 'cash buffer: -1002.5 -> +6997.5'. Angka -1.002,5 adalah headroom, sedangkan 6.997,5 adalah saldo kas akhir. Spec-nya sendiri menyebut penagihan minimal IDR 1.100 mn, yang hanya menghasilkan +97,5. | J9: Satu satuan untuk satu metrik. Pilih headroom -1.002,5 -> +97,5, atau saldo kas 6.997,5 -> 8.097,5. | K9: Teks dampak berupa free text tanpa validasi satuan. | L9: Backend / logika agent | M9: 2026-07-31 | N9: Terbuka
A10: QC-006 | B10: 2026-07-28 | C10: Semua agent | D10: d. Prompt dan respons | E10: Konten | F10: Kritis | G10: Ya | H10: Riwayat percakapan penuh dengan pesan uji coba developer | I10: Endpoint conversations mengembalikan sekitar 190 percakapan tersimpan, termasuk 'test', 'asdsad', 'hello world', 'Test test test', 'selamat pagi', 'does all the right tools work?', 'gimme data', dan 'show me the cahrt'. | J10: Riwayat yang sudah dikurasi, hanya berisi pertanyaan CFO yang kredibel, atau panel riwayat disembunyikan saat event. | K10: Tidak ada pemisahan antara environment development dan environment demo. | L10: Pemilik demo | M10: 2026-07-31 | N10: Terbuka
A11: QC-007 | B11: 2026-07-28 | C11: Collection | D11: a. Kesesuaian formula | E11: Formula | F11: Tinggi | G11: Ya | H11: KPI high-risk dan grafik risk tier tidak sama di layar yang sama | I11: KPI 'High-risk exposure' = 2.500 mn dengan label 'provision / high tier'. Grafik 'Risk exposure by tier' menampilkan High = 5.000 mn. | J11: Ganti nama KPI menjadi 'High-risk provision', atau tampilkan 5.000 agar sama dengan grafik. | K11: KPI membaca field pencadangan, grafik membaca field eksposur. Satu label, dua arti. | L11: Backend / logika agent | M11: 2026-08-04 | N11: Terbuka
A12: QC-008 | B12: 2026-07-28 | C12: Collection | D12: a. Kesesuaian formula | E12: Definisi | F12: Tinggi | G12: Ya | H12: Definisi 'Top 5' berbeda tiga kali di dalam satu agent | I12: Grafik options 'Top 5 - 46d' memakai baris 1-5 worklist (recovery 21.300 mn). Alert 'DSO gap and overdue concentration' memakai top 5 berdasarkan nilai overdue (27.000 mn, 71,17%). Alert 'Mid-tier accounts' memakai top 5 berdasarkan expected recovery (23.225 mn). | J12: Satu definisi saja, dan ditulis di layar. | K12: Setiap tampilan menghitung ranking-nya sendiri. | L12: Backend / logika agent | M12: 2026-08-04 | N12: Terbuka
A13: QC-009 | B13: 2026-07-28 | C13: Finance | D13: a. Kesesuaian formula | E13: Formula | F13: Tinggi | G13: Ya | H13: Ada dua target margin EBITDA yang dipakai bersamaan | I13: KPI tile dan gauge simulator sama-sama menulis 'target 15%'. Alert 'Price recovery opportunity' menyebut margin anggaran 15,7% (EBITDA anggaran 7.200 / pendapatan anggaran 46.000 = 15,65%). | J13: Satu target saja. Kalau acuannya anggaran, pakai 15,7% di semua tempat. | K13: Target gauge di-hardcode ke angka bulat 15%, sedangkan alert menghitung dari anggaran. | L13: Backend / logika agent | M13: 2026-08-04 | N13: Terbuka
A14: QC-010 | B14: 2026-07-28 | C14: Finance | D14: a. Kesesuaian formula | E14: Formula | F14: Tinggi | G14: Ya | H14: Varians harga sekitar sepuluh kali lebih kecil dari penurunan harga yang diklaim | I14: Alert menyebut harga blended turun 7,6%, dari IDR 127,7k menjadi IDR 118,0k per unit. Waterfall EBITDA hanya menampilkan langkah harga -390 mn atas pendapatan 46.510 mn. Penurunan harga 7,6% seharusnya berdampak sekitar -3.800 mn. | J14: Langkah harga di waterfall dan persentase penurunan di alert harus berasal dari perhitungan yang sama. | K14: Langkah waterfall dan narasi alert dihasilkan dari sumber berbeda. Perlu diverifikasi ke model dasarnya. | L14: Backend / logika agent | M14: 2026-08-04 | N14: Terbuka
A15: QC-011 | B15: 2026-07-28 | C15: Finance | D15: a. Kesesuaian formula | E15: Formula | F15: Tinggi | G15: Ya | H15: Varians COGS disebut dengan dua angka berbeda | I15: Alert dan action memakai COGS overrun IDR 2.930 mn. Waterfall EBITDA menampilkan langkah Cost dan FX sebesar -1.880 mn. | J15: Satu angka varians biaya di seluruh waterfall, alert, dan action card. | K15: Waterfall mungkin sudah menetkan FX ke dalam biaya, sedangkan alert melaporkan biaya bruto. Keduanya belum direkonsiliasi. | L15: Backend / logika agent | M15: 2026-08-04 | N15: Terbuka
A16: QC-012 | B16: 2026-07-28 | C16: Finance | D16: d. Prompt dan respons | E16: Konten | F16: Tinggi | G16: Tidak | H16: Dua angka yang hampir sama artinya berbeda | I16: Langkah Cost dan FX = -1.880 mn. Mix ditambah price = -1.491 + -390 = -1.881 mn, dan sebuah alert melaporkan 'IDR 1.881mn combined profitability loss'. | J16: Pisahkan keduanya di layar, atau bulatkan berbeda supaya tidak tertukar saat presentasi. | K16: Kebetulan pada data seed, tetapi berpotensi membingungkan di atas panggung. | L16: Pemilik demo | M16: 2026-08-04 | N16: Terbuka
A17: QC-013 | B17: 2026-07-28 | C17: Leakage | D17: a. Kesesuaian formula | E17: Formula | F17: Sedang | G17: Tidak | H17: Batang berlabel 'Current 95%' tidak menunjukkan posisi saat ini | I17: Pada grafik 'Recovery scenario' di agent Leakage, batang ketiga berlabel 'Current 95%' bernilai 7.577,5. Batang itu menerapkan 95% ke duplikat dan overbilling sekaligus. Posisi sebenarnya menerapkan 95% ke duplikat dan 90% ke overbilling, hasilnya 7.557,5. Angka itulah yang dipakai KPI 'Total protected' (7.558) dan grafik samping 'Protected vs at risk' (7.557,5). Selisihnya = 400 x 5% = 20 juta. PENTING: selisih ini tidak terlihat mata. KPI dan grafik samping justru sudah cocok satu sama lain, jadi kalau dilihat sekilas memang terasa benar. Yang berbeda hanya grafik recovery, dan 20 dari 7.578 hanya 0,26%. Baru kelihatan lewat tooltip, label angka pada batang, atau kalau ada yang menanyakan angkanya ke agent. | J17: Batang 'Current' memakai set asumsi yang sama dengan KPI, sehingga bernilai 7.557,5. Alternatif lain, ganti namanya menjadi '95% untuk semua' supaya tidak lagi mengaku sebagai posisi saat ini. | K17: Grafik recovery meng-hardcode satu tarif claw-back untuk semua item yang bisa ditarik. Baseline simulator memakai dua tarif berbeda. Keduanya tidak salah secara terpisah. Yang membuat grafiknya keliru adalah label 'Current'. | L17: Backend / logika agent | M17: 2026-08-11 | N17: Terbuka | Q17: Severity diturunkan dari Tinggi ke Sedang pada 28 Juli 2026 setelah diperiksa ulang bersama Susan. Alasan: selisihnya tidak terlihat mata dan bukan penghambat demo. Cacatnya tetap nyata dan tetap perlu diperbaiki.
A18: QC-014 | B18: 2026-07-28 | C18: Leakage | D18: a. Kesesuaian formula | E18: Formula | F18: Tinggi | G18: Ya | H18: Jumlah flag di KPI tidak cocok dengan tabelnya | I18: KPI 'Flagged this cycle' menulis '22 flags'. Worklist hanya berisi 10 baris dan vendor radar berjumlah 10 flag pada 8 vendor. | J18: Angka pada KPI harus sama dengan jumlah baris yang benar-benar bisa dibuka pengguna. | K18: KPI menghitung exception mentah, sedangkan tabel menampilkan top-N tanpa keterangan 'menampilkan 10 dari 22'. | L18: Backend / logika agent | M18: 2026-08-04 | N18: Terbuka
A19: QC-015 | B19: 2026-07-28 | C19: Leakage | D19: a. Kesesuaian formula | E19: Formula | F19: Tinggi | G19: Ya | H19: Eksposur split invoice muncul di grafik tetapi di luar total | I19: At risk = 7.845 = fraud 3.800 + duplikat 3.050 + overbilling 400 + other blocked 500 + lost 95. Alert 'Split invoice threshold evasion' melaporkan IDR 1.950 mn, dan 'Split / threshold' adalah salah satu dari lima kategori grafik, tetapi 1.950 tidak masuk ke 7.845. | J19: Pilih: at risk menjadi 9.795, atau split invoice dikeluarkan dari grafik dan dijelaskan. | K19: Agregat at-risk dibuat sebelum deteksi split-threshold ditambahkan. | L19: Backend / logika agent | M19: 2026-08-04 | N19: Terbuka
