Workbook

Sheet 00 Guidance
B1: CASH FLOW INTELLIGENCE AGENT — DEMO DATA ENGINE
B2: Companion to your storyline sheet. This is the data behind the story: a complete, linked 14-week cash forecast for Aug 2026 that a CFO's treasury team can drill into.
B4: SHEET MAP
B5: 01 Storyline Demo — all demos story line
B6: 02 Assumptions — all inputs in one place (BLUE cells). Change here to run scenarios.
B7: 03 AR Collections — open customer invoices -> expected collection week.
B8: 04 AP USD Payables — vendor bills incl. USD imports -> payment week and FX exposure.
B9: 05 Other Outflows — payroll, opex, tax, loan by week.
B10: 06 Cash Forecast 14W — the 13-week forecast. Flags the Week-5 buffer breach.
B11: 07 FX Scenarios — net USD exposure + interactive FX impact simulator.
B12: 08 Recommendation — the agent's decision card and illustrative journal.
B14: WHAT I CHANGED VS YOUR STORYLINE (honest review notes)
... B38: BLUE = input you can change. GREEN = pulled from another sheet. BLACK = calculated. YELLOW = key assumption.

Sheet Summary Future Finance AI
A3: AGENT AI
A4: AGENT 01 | B4: Agent 1, Cash Flow. Will I have enough cash. It finds a shortfall four weeks early and fixes it.
A5: AGENT 02 | B5: Agent 2, Collections. Why is my cash stuck. It finds the overdue cash and who to chase first
A6: AGENT 03 | B6: Agent 3, Leakage and Fraud. Is money leaking out. It blocks a fraud and finds duplicate payments
A7: AGENT 04 | B7: Agent 4, Financial Performance. Why did profit fall. It explains it in one chart and tests the fix
A9: AGENT AI DRIVER
A10: OPENING | B10: Most finance teams are busy, but they are always one step behind. They find cash problems too late. They chase the wrong customers first. Money leaks out in small ways. And when profit falls, it takes days to find out why. Now imagine a small AI finance team that works for you all day and night. It watches your numbers. It explains why things happen. It tests a fix before you act. Then it acts. But it never does anything without your approval. That is what I will show you today. We built four of these agents inside your Dynamics 365 Finance system. They share the same data, and they work together. To keep it real, we use one example company. An Indonesian manufacturer that imports raw materials in US dollars. Everything you see uses the same company, so the four agents tell one connected story. And all the numbers today are illustrative, just to show how it works.
A11: AGENT 01 | B11: First question. Will I have enough cash. 1. This agent builds a 14-week cash forecast from your live data. Look here. It found a problem in Week 5, four weeks early. Cash drops below your safety buffer. 2. Why. Two reasons. A large US dollar payment for imported materials lands that week. And your biggest customer pays late. 3. The agent does not just warn you. It recommends a fix. Move one flexible payment to a later week. Pull one customer payment earlier. That closes the gap. 4. It also handles the currency risk. It suggests locking the US dollar rate with a forward, so a weaker rupiah does not hurt you. 5. And here is the key part. It asks for your approval before doing anything. Transition: Good. Cash is safe. But some of your cash is stuck. Let us see where.
A12: AGENT 02 | B12: Second question. Why is my cash stuck, and who is risky. 1. This agent looks at everyone who owes you money. It found IDR 38 billion overdue. 2. Then it does something useful. It ranks who to chase first. The top five customers hold about 70 percent of the overdue cash. So your team stops guessing, and starts with the ones that matter. 3. It also scores each customer for risk. This one customer is high risk. It has a dispute, and it is sliding toward default. The agent says hold new shipments, and set aside a provision. 4. And here is the prize for you. If we cut the collection time from 57 days to 47 days, we free about IDR 20 billion in cash. Transition: So we found stuck cash. Now, is money leaking out the back door.
A13: AGENT 03 | B13: Third question. Is money leaving by mistake, or by fraud. 1. This agent scans every vendor payment. This cycle it scanned 1,850 invoices, and flagged only 10. A short, focused list. 2. Look at the top one. A vendor bank account changed two days before a payment of IDR 3.8 billion. That is a classic fraud pattern. The agent blocked it before the money left, and asked the team to verify by phone. 3. It also found IDR 3 billion in duplicate payments already made, ready to claw back. And smaller leaks, like missed early-payment discounts. 4. In total, IDR 7.8 billion of risk caught this cycle. Most of it before it left the building. Transition: Cash is safe, unstuck, and protected. Last question, the one that keeps a CFO awake.
A14: AGENT 04 | B14: Fourth question. My revenue is on plan, so why did my profit fall. 1. Look. Revenue is on target. But profit, the EBITDA, dropped from about 16 percent to about 9 percent. 2. Most tools stop at the number. This agent explains why, in one chart. 3. Selling more helped. But two things hurt. Input cost went up, mostly from the weaker rupiah on imported materials. And the product mix shifted to lower-margin products. So this is a margin problem, not a sales problem. 4. Then it lets you test a fix. If we raise price 4 percent, profit improves, but not enough. So the agent recommends three moves together. Raise price where the market allows. Sell more of the high-margin products. And hedge the currency, which it hands to the cash flow agent.
A15: CONNECTIONS | B15: Now here is the real power. These are not four separate tools. They share one set of data, and they hand work to each other. The performance agent found a currency problem, and handed it to the treasury agent. The treasury agent already knew your customer was paying late, because the collections agent flagged it. The leakage agent feeds cost savings back into performance. Together, they are one finance brain. It watches, it explains, and it acts.
A16: CLOSING | B16: Three things make this different from a generic AI tool. First, you are always in control. Every agent asks for approval before it acts, and it logs everything for audit. It is not a black box. Second, it is built inside your Dynamics 365 Finance system, using Microsoft Copilot Studio. It reads and writes your real data. No copy and paste, no separate app. Third, it is tuned to your world. Local tax rules, local accounting standards, your currency. So instead of a finance team that reacts in days, you get a finance team that responds in minutes, and never sleeps. And you decide every action. Thank you. What questions can I answer.
A17: NEED TO BE HIGHLIGHTED | B17: ● If they ask: "Is it safe. Can it act on its own." >> No agent acts without your approval. Every action is logged for audit. You set what it can and cannot do. ● If they ask: "Are these real numbers." >> These are illustrative, to show how it works. In a pilot, we connect your real data. ● If they ask: "How accurate is the AI." >> The heavy math, like the cash forecast and the profit bridge, is normal finance logic, not a guess. The AI helps read data, explain it, and set priorities. And a human approves every action. ● If they ask: "What does it cost. What license do we need." >> That depends on Microsoft's licensing at the time. I will confirm the exact terms for you. (Do not quote a price.) ● If they ask: "How long does it take to build." >> We start with one agent as a pilot on your data, then add more. I can propose a plan. ● If they ask: "Does it work on our version of D365." >> I will confirm the features available on your exact release.

Sheet Storyline Demo
A1: DEMO SCENARIO | C1: CASH FLOW INTELLIGENCE AGENT
A2: TAG LINE | C2: From Cash Visibility to Autonomous Treasury Decision
A3: BUSINESS VALUE | C3: The value is not only that CFO can see cash forecast. The value is that the CFO receives a recommended decision, understands the financial impact, approves the action, and sees the treasury and ERP impact updated in real time. This is the shift from finance reporting to autonomous finance decisioning.
A4: TRADITIONAL CASH FLOW FORECAST | C4: Report → Review → Manual Analysis → Manual Decision → Manual Follow-up
A5: AGENTIC CASH FLOW FORECAST | C5: From Cash Visibility to Autonomous Treasury Decision
A6: PURPOSE | C6: This agent does not only forecast cash : - It continuously monitors ERP transactions - Identifies upcoming liquidity risk - Connects the risk with real-time currency movement - Recommends the best treasury action - Asks CFO approval - Triggers Treasury Agent execution - Updates ERP financial impact.
A7: CFO ISSUES | C7: PT Future Manufacturing Tbk has upcoming USD vendor payments for imported raw materials.
A8: CFO PAIN POINT | C8: - Cash forecast is manual and delayed - FX exposure is monitored separately - Shortage risk is discovered late - Treasury action is disconnected from forecast - Journal and ERP impact are not immediately visible
A9: CFO POINT OF VIEW | C9: The CFO wants to know: - Do we have enough cash for the next 14 weeks? - When will cash shortage happen? - How much USD do we need? - Should we buy USD now, wait, hedge, or sell excess USD? - What is the financial impact of each option? - Can the approved decision trigger Treasury execution and ERP posting?
A10: AGENTIC CASH FLOW FORECAST SOLUTION | C10: Continuously monitor cash flow ↓ Detect liquidity and FX risk ↓ Simulate financial impact ↓ Recommend best treasury action ↓ Request CFO approval ↓ Trigger Treasury Agent ↓ Update ERP and forecast impact
A11: AGENTIC CASH FLOW FORECAST WORKFLOW | C11: Trigger → Perceive → Reason → Recommend → Approve → Execute → Learn
A12: Step | B12: What Happens | C12: CFO Sees | D12: Agent Output | E12: Business Value | F12: System Touchpoint
A13: 1. Trigger | B13: Agent detects future cash shortage and FX exposure | C13: Alert: Week 5 shortage risk | D13: Risk notification | E13: 1. Autonomous CFO Office changes cash flow forecasting from a static report into an agentic financial decision process. 2. The agent has detected a projected cash shortage in Week 5. 3. The main driver is a large USD vendor payment combined with delayed customer collection. | F13: D365, FX feed
A14: 2. Perceive | B14: Agent reads ERP and external data | C14: Source data summary | D14: AR/AP, PO, SO, expenses, FX rate | E14: Before recommending anything, the agent shows the data it used: - open customer invoices, - vendor payments, - purchase orders, - recurring expenses, - bank balance, - today’s USD/IDR rate | F14: D365 Finance, external rate
A15: 3. Reason | B15: Agent calculates forecast and simulations | C15: Scenario comparison | D15: Base, buy now, hedge, wait | E15: The agent now simulates three options: buy USD today, hedge partially, or wait. Each option has cash impact, FX impact, risk level, and confidence. | F15: Forecast engine, scenario model
A16: 4. Recommend | B16: Agent ranks best action | C16: Decision card | D16: Buy USD / hedge / wait options | E16: The recommended action is to buy USD 750,000 today and hedge part of the remaining exposure. The expected value protected is IDR 9.8 billion with 88% confidence. | F16: Copilot Studio / dashboard
A17: 5. Approve | B17: CFO approves or modifies | C17: Approval card | D17: Approved decision record | E17: The CFO can approve, modify, simulate, ask why, delegate to treasury, or reject. This keeps the process governed and auditable. | F17: Teams / Power Automate
A18: 6. Execute | B18: Treasury Agent prepares action | C18: Execution status | D18: Bank instruction, journal preview | E18: After approval, the Treasury Agent prepares the bank instruction, updates the cash forecast, notifies Treasury, and prepares the ERP journal preview. | F18: Treasury, D365 Finance
A19: 7. Learn | B19: Agent compares actual vs forecast | C19: Accuracy and outcome report | D19: Updated assumptions | E19: After actual settlement, the agent compares forecast versus actual result and improves future forecast assumptions. | F19: Analytics layer
A20: HIGHLIGHT SCENARIO | B20: TRIGGER | C20: Agent detects liquidity and FX exposure risk. | D20: Trigger Type | E20: Example Trigger | F20: Why It Matters | G20: Remarks
D21: Real Time Currency trigger | E21: USD/IDR moved above CFO tolerance | F21: Detects FX exposure risk | G21: 1. The agent detected that projected cash balance will fall below the IDR 8 billion minimum buffer in Week 5 because of upcoming vendor USD payments and delayed customer collections. 2. Instead of waiting for finance team to manually consolidate Excel reports, the agent continuously monitors ERP data and alerts the CFO when future liquidity risk appears.
D22: Scheduled trigger | E22: Daily 7 AM cash forecast refresh | F22: CFO gets daily executive briefing | G22: The agent detected that projected cash balance will fall below the IDR 8 billion minimum buffer in Week 5 because of upcoming vendor payments and delayed customer collections.
D23: Threshold trigger | E23: Forecasted cash balance below minimum buffer | F23: Detects liquidity risk before crisis | G23: 8000000000
D24: Payment trigger | E24: Large vendor payment due in 14 days | F24: Prevents unexpected cash pressure
D25: Customer delay trigger | E25: Top customer overdue payment > 30 days | F25: Updates cash forecast risk
D26: Scenario trigger | E26: Demand forecast or purchase order changes | F26: Recalculates cash requirement
B27: PERCEIVE | C27: Agent analyzed 12 week projected inflows and outflows using open AR, AP, purchase orders, recurring expenses, and latest USD/IDR rate. Agent also applied CFO policy: minimum cash buffer must remain above IDR 8 billion. | D27: Data Area | E27: Example Data Used by Agent | F27: Source | G27: Remarks
D28: Cash & Bank | E28: Opening bank balance, liquidity accounts | F28: D365 Finance
D29: Accounts Receivable | E29: Open customer invoices, expected collection date | F29: D365 Finance
D30: Accounts Payable | E30: Vendor invoices, due dates, payment schedule | F30: D365 Finance
D31: Purchase Orders | E31: Upcoming import purchase obligations | F31: D365 Finance / Supply Chain
D32: Sales Orders | E32: Expected future inflow from sales | F32: D365 Finance / Supply Chain
D33: Budget / Expense | E33: Payroll, rent, tax, operating expenses | F33: D365 Finance
D34: External FX Rate | E34: Daily USD/IDR spot and forward rate | F34: External data source / bank feed
D35: Risk Inputs | E35: Payment delay, FX volatility, vendor exposure | F35: Agent risk logic
B36: REASON | C36: Agent calculates forecast, detects shortage, simulates FX scenarios, and compares options. The agent does not give one answer only. The agent compares several financial paths and shows their cash, risk, and profit impact. | D36: Logic | E36: Calculation Logic
D37: Cash Forecast | E37: Opening Cash + Expected Customer Payments + Other Cash Inflows - Vendor Payments - Payroll / Opex - Tax / Loan / Other Expenses - FX-adjusted USD Payables = Forecasted Closing Cash
D38: Cash Shortage Detection | E38: If Forecasted Closing Cash < Minimum Cash Buffer Then Shortage Alert = Yes
D39: USD Exposure | E39: USD Net Exposure = USD Payables - USD Receivables
D40: FX Impact Simulation | E40: FX Impact = USD Net Exposure × FX Rate Movement
...

Sheet 00 Mock Up
A1: #VALUE! | C1: Part 1. The alert (two items) - What happens: The agent messages the CFO first. Item 1, the hedge the Performance agent handed over is ready. Item 2, the 14-week forecast shows Week 5 falls below the cash buffer. - Terms: Cash buffer, minimum cash, the floor cash must not go under. Handover between agents. - Highlight : This is the connected story >>"the last decision flowed straight here." It shows the agents work as one team. Part 2. CFO challenge, liquidity vs currency - What happens: The CFO asks if hedging and buying dollars will make the Week 5 cash gap worse. - Terms: Liquidity (likuiditas), having enough cash on hand. Forward, a deal to lock a future exchange rate. Spot purchase (beli spot), buying dollars today. - Why it matters: A forward needs no cash now, so it does not hurt Week 5. Buying dollars spot does. The agent keeps the two problems separate. Part 3. AI shows the 14-week cash line - What happens: A line chart of closing cash each week against the buffer. Week 5 dips below. - Terms: Closing cash (saldo kas akhir) per week. Cash forecast (proyeksi arus kas). - Numbers: Week 5 closing 6,698 vs the 8,000 buffer, short by 1,302. Drivers are a USD 750k import payment in Week 5 and the top customer's collection slipping to Week 7.
A3: #VALUE! | C3: Part 4. CFO asks for options and cost - What happens: The CFO wants choices, and he does not want to pay interest if he can avoid it. - Term: Committed credit line (fasilitas kredit siaga), a pre-agreed loan the company can draw. Interest is its cost. - Concerns : Shows the CFO cares about cost, not just fixing the gap. Part 5. AI recommendation, three ways - What happens: Three options, each with a confidence level. A, accelerate the customer collection. B, defer a payment. C, draw the credit line. - Terms: Accelerate collection (mempercepat penagihan). Defer payment (menunda pembayaran).
A5: #VALUE! | C5: Part 6. AI fixed simulation - What happens: A bar chart of the Week 5 closing under each option, against the buffer line. - Result to say: Accelerate gives 11,698 at no cost. Defer gives 9,698. Draw gives 8,698 but costs interest. Part 6b. The new part, live "trial and error" simulator - What happens: The CFO says "let me try combinations myself." The agent gives a slider panel. In the app, dragging a lever re-runs Week 5 and Week 7 live. - The levers: how much to accelerate, how much to defer, how much to draw, and the hedge size. - What updates: Week 5 closing, headroom vs buffer, Week 7 closing, an OK or Below-buffer status, and the hedge premium and protection. - The lesson built in: accelerating and deferring both pull cash out of Week 7. If the CFO pushes them too far, Week 7 turns red. The simulator shows this instantly. - Terms: Lever , an input you adjust. Headroom, how far above the buffer you are. Premium, the cost of the hedge. - Highlight "you are not trusting a fixed answer, you are testing your own." That is a strong moment.
A7: #VALUE! | C7: Part 7. CFO deep dive - What happens: The CFO asks what accelerating 5 billion does to Week 7, so he does not create a new hole. - CFO always checks the side effect. Part 8. AI deep dive, before and after - What happens: A grouped bar chart of Weeks 5, 6, 7, now versus after option A. - Result: Week 5 rises to 11,698, Week 6 unchanged, Week 7 falls to 15,513 but stays safe. No new hole. [Medium confidence, the customer must agree to pay early]
A9: #VALUE! | C9: Part 9. CFO asks to calculate first - What happens: Before approving, the CFO asks for exact numbers with his own parameters. - Term: Parameters, the exact inputs the CFO sets. - Why it matters: A CFO confirms the precise figures before signing. Part 10. AI on-demand calculation - What happens: A precise table, not a chart. Week 5 goes from a 1,302 shortfall to a 3,698 headroom. Weeks below buffer go from 1 to 0. Plus the hedge premium 340 and protection 1,077. - Highlight >> "it recalculated with the CFO's exact numbers in seconds." Part 11. CFO final approval - What happens: The CFO approves, and asks what it touches downstream. - Term: Dual control, two people must approve sensitive actions.
A11: #VALUE! | C11: Part 12. AI action and cascade - What happens: The approval fans out. Collections agent chases the customer. The bank places the forward. D365 updates the payment run. The audit log records it. Each waits for a human. - Terms: ERP , here D365. Payment run (proses pembayaran) in the ERP. Audit trail. Cascade. - End by saying "this closes the loop from the Performance agent, and passes the baton to Collections." That sets up agent 3.

Sheet 01 Agent AI Flow
B2: OVERALL ARCHITECTURE | C2: Cash Flow Agent | E2: STEP 01 - AI INITIATES ALERT | G2: STEP 02 - CFO RESPOND | I2: STEP 03 - AI ANALYSIS RESPONSE | K2: STEP 04 - CFO DEEP DIVE | M2: STEP 05 - AI RECOMMENDATION ACTION | Q2: STEP 06 - CFO SIMULATION | T2: =Q2 -> STEP 06 - CFO SIMULATION | V2: STEP 07 - CFO Makes Final Decision | X2: STEP 08 - ERP UPDATED UPDATE RESULT | Z2: CFO
C3: │ | E3: 🔴 HIGH PRIORITY ALERT Good Morning Susan. A liquidity risk has been detected. Predicted Week: Week 5 Projected Cash: IDR 6.99B Minimum Buffer: IDR 8.00B Shortfall: IDR 1.00B FX Exposure: USD 3.3M Business Impact: Treasury policy breach likely in 4 weeks. `` | G3: Why is this happening? | I3: Root Cause Analysis Complete Confidence: High Primary Drivers Identified: 2 Driver #1 USD Vendor Settlement Vendor: Shenzhen Micro Ltd Payment Due: USD 750,000 Week: Week 5 Business Impact: Largest cash outflow within forecast horizon. [03A Cash F...0 20260707 | Excel] Driver #2 Customer Collection Delay Customer: PT Anugerah Prima Amount: IDR 8.0B Status: Delayed 14 days Collection shifted: Week 5 → Week 7. | K3: Show me all liquidity risks. | M3: 3 courses of action are available. | Q3: Simulate if Customer A pays on time. | T3: What if USD appreciates 6%? | V3: Execute Recommended Plan. | X3: Treasury Workbench Updated Collection Case Created Payment Schedule Updated Journal Preview Generated Forecast Recalculated `` | Z3: │
C4: ▼ | Z4: ▼
C5: CFO | Z5: Cash Flow Intelligence Agent
C6: │ | Z6: │
C7: ▼ | Z7: ────────────────────────────────────
C8: Decision Engine | Z8: DETECTED RISK
C9: │ | Z9: ────────────────────────────────────
C10: ┌──────┼──────┐
C11: ▼ ▼ ▼ | Z11: Liquidity Breach
C12: AR AP Treasury | Z12: Week 5
C13: Agent Agent Agent
C14: │ │ │ | Z14: Cash Buffer
C15: └──────┼──────┘ | Z15: 6.99B
C16: ▼
C17: Controller Agent | Z17: FX Exposure
C18: ▼ | Z18: USD 3.3M
C19: D365 F&O
C20: ▼ | Z20: ────────────────────────────────────
C21: Executive Dashboard | Z21: RECOMMENDED ACTION
Z22: ────────────────────────────────────
Z24: ✅ Defer Vendor Payment
Z25: +3.0B
Z26: ✅ Forward Cover USD 2M
Z27: +1.077B Protection
Z29: ✅ Accelerate Collection
I30: Week 5 Impact | K30: Top Risk Ranking | M30: OPTION A | N30: OPTION B | O30: OPTION C | Q30: AI Simulation Result | T30: AI Simulation Result | V30: AI Decision Card | X30: Final Execution Visualization
M31: NO ACTION | N31: Liquidity + Hedge Actions: Defer AP-015 Packaging Bill Forward Cover USD 2M Accelerate Customer Collection | O31: Credit Line Draw | Q31: Scenario Created | T31: Current Exposure | V31: Decision Accepted | Z31: +8.0B
I32: Opening Position +18.6B | K32: 1️⃣ Customer Delay | Q32: Customer A Delay Removed
I33: Customer Delay -8.0B | K33: Impact: | M33: Liquidity Risk: High | N33: Week 5 Buffer Restored | O33: Cash Risk: | T33: USD 3.3M | V33: Decision ID: | Z33: ────────────────────────────────────
I34: USD Payment -13.5B | K34: IDR 8.0B | O34: Low | Q34: Before | R34: After | V34: CF-2026-0815 | Z34: EXECUTION
I35: Other Expenses -1.1B | M35: FX Risk: High | N35: Cash: | T35: Risk Bands | Z35: ────────────────────────────────────
I36: -------------------------------- | K36: 2️⃣ USD Exposure | N36: 9.99B | O36: FX Risk: | Q36: Plain Text | R36: Plain Text | V36: Approval:
I37: Final Position 7.0B | K37: Impact: | M37: Potential FX Loss: | O37: High | Q37: Week 5 Cash | R37: Week 5 Cash | T37: Normal 🟢 GREEN | V37: CFO | Z37: Treasury Agent ✅
K38: USD 3.3M | M38: IDR 1.77B | N38: FX Downside Avoided: | T38: +3% USD 🟠 ORANGE
N39: 1.077B | O39: Interest Expense: | Q39: IDR 6.99B | R39: IDR 14.99B | T39: +6% USD 🔴 RED | V39: Status: | Z39: AR Agent ✅
K40: 3️⃣ Major Import Payment | O40: Increases | T40: ` | V40: Approved
K41: Impact: | Z41: AP Agent ✅
K42: USD 750K | M42: Confidence: 76% (illustrative demo value) | N42: Confidence: Medium-High (illustrative demo value) | Q42: Business Impact
Z43: Controller Agent ✅
...

Sheet 02 Assumptions
A1: PT Future Manufacturing Tbk — Cash Flow Intelligence Agent
A2: Central assumptions. Change BLUE cells to run scenarios. Units: IDR million unless labelled USD. Demo date: Aug 2026.
A4: COMPANY PROFILE (illustrative demo company)
A5: Company | B5: PT Future Manufacturing Tbk
A6: Industry | B6: Electronics & auto-parts assembly | D6: Import-dependent: buys components/raw materials in USD, sells mostly in IDR.
A7: Functional / reporting currency | B7: IDR
A8: Listing | B8: IDX (Tbk) — illustrative
A10: FORECAST SETUP
A11: Week 1 start (Monday) | B11: 46237 | D11: First Monday of Aug 2026. All week dates derive from this cell.
A12: Horizon (weeks) | B12: 13 | D12: 13-week rolling cash forecast (13WCF) is the treasury industry standard.
A13: Presentation units | B13: IDR million | D13: IDR 8,000 million = IDR 8.0 billion.
A15: FX ASSUMPTIONS (VERIFY AT DEMO TIME)
A16: Spot USD/IDR | B16: 17950 | D16: As of early Jul 2026, ~17,950. Rupiah is far weaker than 2024-25. Refresh before every demo.
A17: 13-week forward USD/IDR | B17: 18120 | D17: Indicative only. Forward > spot reflects the IDR-USD rate differential. Confirm with the bank.
A18: Adverse scenario: USD strengthens by | B18: 0.03
A19: Stress scenario: USD strengthens by | B19: 0.06
A20: Adverse rate = spot x (1+adverse) | B20: =B16*(1+B18) -> 18488.5
A21: Stress rate = spot x (1+stress) | B21: =B16*(1+B19) -> 19027
A23: POLICY & LIQUIDITY
A24: Minimum cash buffer (IDR mn) | B24: 8000
A25: Opening cash — Week 1 (IDR mn) | B25: 17000 | D25: Equals IDR 17.0 billion opening bank balance.
A26: Hedge policy | B26: Cover >=50% of net USD exposure within 8 weeks
A27: FX approval matrix | B27: CFO + Treasury Manager (dual control)

Sheet 03 AR Collections
A1: Accounts Receivable — Expected Collections (13 weeks)
A2: Open customer invoices mapped to the week cash is expected. Source: D365 F&O AR ageing (illustrative). Amounts in IDR mn (USD invoices converted at spot).
A4: Inv No | B4: Customer | C4: Segment | D4: Invoice Date | E4: Terms (d) | F4: Due Date | G4: Orig Wk | H4: Expected Wk | I4: Currency | J4: Amount IDR mn | K4: USD Amount | L4: IDR mn value | M4: Delay Flag | N4: Notes
A5: AR-001 | B5: PT Bintang Retail | C5: Domestic | D5: 46209 | E5: 30 | F5: 46239 | G5: 1 | H5: 1 | I5: IDR | J5: 7000 | L5: =IF(I5="USD",K5*'02 Assumptions'!$B$16/1000000,J5) -> 7000
A6: AR-002 | B6: PT Cahaya Niaga | C6: Domestic | D6: 46194 | E6: 45 | F6: 46239 | G6: 1 | H6: 1 | I6: IDR | J6: 6000 | L6: =IF(I6="USD",K6*'02 Assumptions'!$B$16/1000000,J6) -> 6000
A7: AR-003 | B7: PT Dua Samudra | C7: Domestic | D7: 46216 | E7: 30 | F7: 46246 | G7: 2 | H7: 2 | I7: IDR | J7: 8000 | L7: =IF(I7="USD",K7*'02 Assumptions'!$B$16/1000000,J7) -> 8000
A8: AR-004 | B8: PT Estu Jaya | C8: Domestic | D8: 46201 | E8: 45 | F8: 46246 | G8: 2 | H8: 2 | I8: IDR | J8: 6000 | L8: =IF(I8="USD",K8*'02 Assumptions'!$B$16/1000000,J8) -> 6000
A9: AR-005 | B9: PT Fajar Mandiri | C9: Domestic | D9: 46223 | E9: 30 | F9: 46253 | G9: 3 | H9: 3 | I9: IDR | J9: 6500 | L9: =IF(I9="USD",K9*'02 Assumptions'!$B$16/1000000,J9) -> 6500
A10: AR-006 | B10: PT Graha Sentosa | C10: Domestic | D10: 46208 | E10: 45 | F10: 46253 | G10: 3 | H10: 3 | I10: IDR | J10: 6000 | L10: =IF(I10="USD",K10*'02 Assumptions'!$B$16/1000000,J10) -> 6000
A11: AR-007 | B11: PT Harum Sejati | C11: Domestic | D11: 46230 | E11: 30 | F11: 46260 | G11: 4 | H11: 4 | I11: IDR | J11: 7000 | L11: =IF(I11="USD",K11*'02 Assumptions'!$B$16/1000000,J11) -> 7000
A12: AR-008 | B12: PT Indah Karya | C12: Domestic | D12: 46215 | E12: 45 | F12: 46260 | G12: 4 | H12: 4 | I12: IDR | J12: 6000 | L12: =IF(I12="USD",K12*'02 Assumptions'!$B$16/1000000,J12) -> 6000
A13: AR-009 | B13: PT Jaya Abadi | C13: Domestic | D13: 46237 | E13: 30 | F13: 46267 | G13: 5 | H13: 5 | I13: IDR | J13: 6000 | L13: =IF(I13="USD",K13*'02 Assumptions'!$B$16/1000000,J13) -> 6000
A14: AR-010 | B14: PT Kencana Mulia | C14: Domestic | D14: 46244 | E14: 30 | F14: 46274 | G14: 6 | H14: 6 | I14: IDR | J14: 7500 | L14: =IF(I14="USD",K14*'02 Assumptions'!$B$16/1000000,J14) -> 7500
A15: AR-011 | B15: PT Lestari Utama | C15: Domestic | D15: 46229 | E15: 45 | F15: 46274 | G15: 6 | H15: 6 | I15: IDR | J15: 6000 | L15: =IF(I15="USD",K15*'02 Assumptions'!$B$16/1000000,J15) -> 6000
A16: AR-012 | B16: PT Anugerah Prima (Customer A) | C16: Domestic | D16: 46221 | E16: 60 | F16: 46281 | G16: 5 | H16: 7 | I16: IDR | J16: 8000 | L16: =IF(I16="USD",K16*'02 Assumptions'!$B$16/1000000,J16) -> 8000 | M16: Delayed +14d | N16: TOP customer. Was due Week 5, now expected Week 7. Repeated ~14-day delay pattern -> main driver of the Week 5 gap.
A17: AR-013 | B17: Global Components Ltd (Export) | C17: Export | D17: 46236 | E17: 45 | F17: 46281 | G17: 7 | H17: 7 | I17: USD | K17: 400000 | L17: =IF(I17="USD",K17*'02 Assumptions'!$B$16/1000000,J17) -> 7180 | N17: Export receivable in USD -> natural partial hedge against USD payables.
A18: AR-014 | B18: PT Nusantara Dagang | C18: Domestic | D18: 46251 | E18: 30 | F18: 46281 | G18: 7 | H18: 7 | I18: IDR | J18: 6320 | L18: =IF(I18="USD",K18*'02 Assumptions'!$B$16/1000000,J18) -> 6320
A19: AR-015 | B19: Pacific Devices Inc (Export) | C19: Export | D19: 46243 | E19: 45 | F19: 46288 | G19: 8 | H19: 8 | I19: USD | K19: 300000 | L19: =IF(I19="USD",K19*'02 Assumptions'!$B$16/1000000,J19) -> 5385 | N19: Export receivable in USD.
A20: AR-016 | B20: PT Purnama Sejahtera | C20: Domestic | D20: 46258 | E20: 30 | F20: 46288 | G20: 8 | H20: 8 | I20: IDR | J20: 7615 | L20: =IF(I20="USD",K20*'02 Assumptions'!$B$16/1000000,J20) -> 7615
A21: AR-017 | B21: PT Cahaya Niaga | C21: Domestic | D21: 46265 | E21: 30 | F21: 46295 | G21: 9 | H21: 9 | I21: IDR | J21: 8500 | L21: =IF(I21="USD",K21*'02 Assumptions'!$B$16/1000000,J21) -> 8500
A22: AR-018 | B22: PT Quantum Retail | C22: Domestic | D22: 46250 | E22: 45 | F22: 46295 | G22: 9 | H22: 9 | I22: IDR | J22: 6000 | L22: =IF(I22="USD",K22*'02 Assumptions'!$B$16/1000000,J22) -> 6000
A23: AR-019 | B23: PT Dua Samudra | C23: Domestic | D23: 46272 | E23: 30 | F23: 46302 | G23: 10 | H23: 10 | I23: IDR | J23: 7000 | L23: =IF(I23="USD",K23*'02 Assumptions'!$B$16/1000000,J23) -> 7000
A24: AR-020 | B24: PT Rejeki Makmur | C24: Domestic | D24: 46257 | E24: 45 | F24: 46302 | G24: 10 | H24: 10 | I24: IDR | J24: 6000 | L24: =IF(I24="USD",K24*'02 Assumptions'!$B$16/1000000,J24) -> 6000
A25: AR-021 | B25: PT Estu Jaya | C25: Domestic | D25: 46279 | E25: 30 | F25: 46309 | G25: 11 | H25: 11 | I25: IDR | J25: 8000 | L25: =IF(I25="USD",K25*'02 Assumptions'!$B$16/1000000,J25) -> 8000
A26: AR-022 | B26: PT Fajar Mandiri | C26: Domestic | D26: 46264 | E26: 45 | F26: 46309 | G26: 11 | H26: 11 | I26: IDR | J26: 6000 | L26: =IF(I26="USD",K26*'02 Assumptions'!$B$16/1000000,J26) -> 6000
A27: AR-023 | B27: PT Graha Sentosa | C27: Domestic | D27: 46286 | E27: 30 | F27: 46316 | G27: 12 | H27: 12 | I27: IDR | J27: 8500 | L27: =IF(I27="USD",K27*'02 Assumptions'!$B$16/1000000,J27) -> 8500
A28: AR-024 | B28: PT Harum Sejati | C28: Domestic | D28: 46271 | E28: 45 | F28: 46316 | G28: 12 | H28: 12 | I28: IDR | J28: 6000 | L28: =IF(I28="USD",K28*'02 Assumptions'!$B$16/1000000,J28) -> 6000
A29: AR-025 | B29: PT Indah Karya | C29: Domestic | D29: 46293 | E29: 30 | F29: 46323 | G29: 13 | H29: 13 | I29: IDR | J29: 7500 | L29: =IF(I29="USD",K29*'02 Assumptions'!$B$16/1000000,J29) -> 7500
A30: AR-026 | B30: PT Jaya Abadi | C30: Domestic | D30: 46278 | E30: 45 | F30: 46323 | G30: 13 | H30: 13 | I30: IDR | J30: 6000 | L30: =IF(I30="USD",K30*'02 Assumptions'!$B$16/1000000,J30) -> 6000
A32: TOTALS | K32: =SUMIF(I5:I30,"USD",K5:K30) -> 700000 | L32: =SUM(L5:L30) -> 176000 | N32: K = total USD receivables (natural hedge). L = total expected collections (IDR mn).

Sheet 05 Other Outflows
A1: Other Recurring Cash Outflows (13 weeks)
A2: Planned payroll, opex, tax and loan outflows by week. Source: budget / recurring schedules (illustrative). Units: IDR mn. Blue = input.
A4: Category | B4: W1 | C4: W2 | D4: W3 | E4: W4 | F4: W5 | G4: W6 | H4: W7 | I4: W8 | J4: W9 | K4: W10 | L4: W11 | M4: W12 | N4: W13 | O4: Total
A5: Payroll | B5: 0 | C5: 0 | D5: 0 | E5: 3200 | F5: 0 | G5: 0 | H5: 0 | I5: 0 | J5: 3200 | K5: 0 | L5: 0 | M5: 0 | N5: 3200 | O5: =SUM(B5:N5) -> 9600
A6: Rent & utilities | B6: 700 | C6: 700 | D6: 700 | E6: 700 | F6: 700 | G6: 700 | H6: 700 | I6: 700 | J6: 700 | K6: 700 | L6: 700 | M6: 700 | N6: 700 | O6: =SUM(B6:N6) -> 9100
A7: Other opex | B7: 400 | C7: 400 | D7: 400 | E7: 400 | F7: 400 | G7: 400 | H7: 400 | I7: 400 | J7: 400 | K7: 400 | L7: 400 | M7: 400 | N7: 400 | O7: =SUM(B7:N7) -> 5200
A8: Taxes (PPN / PPh) | B8: 0 | C8: 0 | D8: 2800 | E8: 0 | F8: 0 | G8: 0 | H8: 2800 | I8: 0 | J8: 0 | K8: 0 | L8: 2800 | M8: 0 | N8: 0 | O8: =SUM(B8:N8) -> 8400
A9: Loan repayment (P+I) | B9: 0 | C9: 0 | D9: 0 | E9: 0 | F9: 0 | G9: 0 | H9: 0 | I9: 0 | J9: 0 | K9: 4500 | L9: 0 | M9: 0 | N9: 0 | O9: =SUM(B9:N9) -> 4500
A10: Total other outflows | B10: =SUM(B5:B9) -> 1100 | C10: =SUM(C5:C9) -> 1100 | D10: =SUM(D5:D9) -> 3900 | E10: =SUM(E5:E9) -> 4300 | F10: =SUM(F5:F9) -> 1100 | G10: =SUM(G5:G9) -> 1100 | H10: =SUM(H5:H9) -> 3900 | I10: =SUM(I5:I9) -> 1100 | ... N10: =SUM(N5:N9) -> 4300 | O10: =SUM(B10:N10) -> 36800
A12: Note: Payroll = monthly (end Aug/Sep/Oct). Tax = monthly filing (mid-month). Loan = quarterly instalment (W10).

Sheet 06 Cash Forecast 13W
A1: 13-Week Direct Cash Flow Forecast — Aug to Nov 2026
A2: Everything below is calculated from sheets 02/03/04. Green = pulled from other sheets. Units: IDR mn. The agent flags any week where closing cash < the CFO buffer.
A4: Week # | B4: 1 | C4: 2 | D4: 3 | E4: 4 | F4: 5 | G4: 6 | H4: 7 | I4: 8 | J4: 9 | K4: 10 | L4: 11 | M4: 12 | N4: 13 | O4: Total
A5: Week starting | B5: ='02 Assumptions'!$B$11 -> 46237 | C5: =B5+7 -> 46244 | D5: =C5+7 -> 46251 | E5: =D5+7 -> 46258 | F5: =E5+7 -> 46265 | G5: =F5+7 -> 46272 | H5: =G5+7 -> 46279 | I5: =H5+7 -> 46286 | J5: =I5+7 -> 46293 | ... N5: =M5+7 -> 46321
A6: Week ending | B6: =B5+6 -> 46243 | C6: =C5+6 -> 46250 | D6: =D5+6 -> 46257 | E6: =E5+6 -> 46264 | F6: =F5+6 -> 46271 | G6: =G5+6 -> 46278 | H6: =H5+6 -> 46285 | I6: =I5+6 -> 46292 | ... N6: =N5+6 -> 46327
A7: CASH INFLOWS (IDR mn)
A8: Customer collections | B8: =SUMIF('03 AR Collections'!$H:$H,B$4,'03 AR Collections'!$L:$L) -> 13000 | C8: =SUMIF('03 AR Collections'!$H:$H,C$4,'03 AR Collections'!$L:$L) -> 14000 | D8: =SUMIF('03 AR Collections'!$H:$H,D$4,'03 AR Collections'!$L:$L) -> 12500 | E8: =SUMIF('03 AR Collections'!$H:$H,E$4,'03 AR Collections'!$L:$L) -> 13000 | F8: =SUMIF('03 AR Collections'!$H:$H,F$4,'03 AR Collections'!$L:$L) -> 6000 | G8: =SUMIF('03 AR Collections'!$H:$H,G$4,'03 AR Collections'!$L:$L) -> 13500 | H8: =SUMIF('03 AR Collections'!$H:$H,H$4,'03 AR Collections'!$L:$L) -> 21500 | I8: =SUMIF('03 AR Collections'!$H:$H,I$4,'03 AR Collections'!$L:$L) -> 13000 | ... N8: =SUMIF('03 AR Collections'!$H:$H,N$4,'03 AR Collections'!$L:$L) -> 13500 | O8: =SUM(B8:N8) -> 176000
A9: Total cash inflows | B9: =B8 -> 13000 | C9: =C8 -> 14000 | D9: =D8 -> 12500 | E9: =E8 -> 13000 | F9: =F8 -> 6000 | G9: =G8 -> 13500 | H9: =H8 -> 21500 | I9: =I8 -> 13000 | ... N9: =N8 -> 13500 | O9: =SUM(B9:N9) -> 176000
A10: CASH OUTFLOWS (IDR mn)
A11: Vendor payments — IDR (domestic) | B11: =SUMIFS('04 AP USD Payables'!$J:$J,'04 AP USD Payables'!$F:$F,B$4,'04 AP USD Payables'!$G:$G,"IDR") -> 4500 | C11: =SUMIFS('04 AP USD Payables'!$J:$J,'04 AP USD Payables'!$F:$F,C$4,'04 AP USD Payables'!$G:$G,"IDR") -> 5000 | D11: =SUMIFS('04 AP USD Payables'!$J:$J,'04 AP USD Payables'!$F:$F,D$4,'04 AP USD Payables'!$G:$G,"IDR") -> 4500 | E11: =SUMIFS('04 AP USD Payables'!$J:$J,'04 AP USD Payables'!$F:$F,E$4,'04 AP USD Payables'!$G:$G,"IDR") -> 5000 | F11: =SUMIFS('04 AP USD Payables'!$J:$J,'04 AP USD Payables'!$F:$F,F$4,'04 AP USD Payables'!$G:$G,"IDR") -> 3000 | G11: =SUMIFS('04 AP USD Payables'!$J:$J,'04 AP USD Payables'!$F:$F,G$4,'04 AP USD Payables'!$G:$G,"IDR") -> 5000 | H11: =SUMIFS('04 AP USD Payables'!$J:$J,'04 AP USD Payables'!$F:$F,H$4,'04 AP USD Payables'!$G:$G,"IDR") -> 5500 | I11: =SUMIFS('04 AP USD Payables'!$J:$J,'04 AP USD Payables'!$F:$F,I$4,'04 AP USD Payables'!$G:$G,"IDR") -> 4500 | ... N11: =SUMIFS('04 AP USD Payables'!$J:$J,'04 AP USD Payables'!$F:$F,N$4,'04 AP USD Payables'!$G:$G,"IDR") -> 5000 | O11: =SUM(B11:N11) -> 61000
A12: Vendor payments — USD imports (in IDR) | B12: =SUMIFS('04 AP USD Payables'!$J:$J,'04 AP USD Payables'!$F:$F,B$4,'04 AP USD Payables'!$G:$G,"USD") -> 0 | C12: =SUMIFS('04 AP USD Payables'!$J:$J,'04 AP USD Payables'!$F:$F,C$4,'04 AP USD Payables'!$G:$G,"USD") -> 5385 | D12: =SUMIFS('04 AP USD Payables'!$J:$J,'04 AP USD Payables'!$F:$F,D$4,'04 AP USD Payables'!$G:$G,"USD") -> 5385 | E12: =SUMIFS('04 AP USD Payables'!$J:$J,'04 AP USD Payables'!$F:$F,E$4,'04 AP USD Payables'!$G:$G,"USD") -> 10770 | F12: =SUMIFS('04 AP USD Payables'!$J:$J,'04 AP USD Payables'!$F:$F,F$4,'04 AP USD Payables'!$G:$G,"USD") -> 13462.5 | G12: =SUMIFS('04 AP USD Payables'!$J:$J,'04 AP USD Payables'!$F:$F,G$4,'04 AP USD Payables'!$G:$G,"USD") -> 5385 | H12: =SUMIFS('04 AP USD Payables'!$J:$J,'04 AP USD Payables'!$F:$F,H$4,'04 AP USD Payables'!$G:$G,"USD") -> 0 | I12: =SUMIFS('04 AP USD Payables'!$J:$J,'04 AP USD Payables'!$F:$F,I$4,'04 AP USD Payables'!$G:$G,"USD") -> 6282.5 | ... N12: =SUMIFS('04 AP USD Payables'!$J:$J,'04 AP USD Payables'!$F:$F,N$4,'04 AP USD Payables'!$G:$G,"USD") -> 8975 | O12: =SUM(B12:N12) -> 71800
A13: Payroll | B13: ='05 Other Outflows'!B5 -> 0 | C13: ='05 Other Outflows'!C5 -> 0 | D13: ='05 Other Outflows'!D5 -> 0 | E13: ='05 Other Outflows'!E5 -> 3200 | F13: ='05 Other Outflows'!F5 -> 0 | G13: ='05 Other Outflows'!G5 -> 0 | H13: ='05 Other Outflows'!H5 -> 0 | I13: ='05 Other Outflows'!I5 -> 0 | ... N13: ='05 Other Outflows'!N5 -> 3200 | O13: =SUM(B13:N13) -> 9600
A14: Rent, utilities & opex | B14: ='05 Other Outflows'!B6+'05 Other Outflows'!B7 -> 1100 | C14: ='05 Other Outflows'!C6+'05 Other Outflows'!C7 -> 1100 | D14: ='05 Other Outflows'!D6+'05 Other Outflows'!D7 -> 1100 | E14: ='05 Other Outflows'!E6+'05 Other Outflows'!E7 -> 1100 | F14: ='05 Other Outflows'!F6+'05 Other Outflows'!F7 -> 1100 | G14: ='05 Other Outflows'!G6+'05 Other Outflows'!G7 -> 1100 | H14: ='05 Other Outflows'!H6+'05 Other Outflows'!H7 -> 1100 | I14: ='05 Other Outflows'!I6+'05 Other Outflows'!I7 -> 1100 | ... N14: ='05 Other Outflows'!N6+'05 Other Outflows'!N7 -> 1100 | O14: =SUM(B14:N14) -> 14300
A15: Taxes (PPN / PPh) | B15: ='05 Other Outflows'!B8 -> 0 | C15: ='05 Other Outflows'!C8 -> 0 | D15: ='05 Other Outflows'!D8 -> 2800 | E15: ='05 Other Outflows'!E8 -> 0 | F15: ='05 Other Outflows'!F8 -> 0 | G15: ='05 Other Outflows'!G8 -> 0 | H15: ='05 Other Outflows'!H8 -> 2800 | I15: ='05 Other Outflows'!I8 -> 0 | ... N15: ='05 Other Outflows'!N8 -> 0 | O15: =SUM(B15:N15) -> 8400
A16: Loan repayment (P+I) | B16: ='05 Other Outflows'!B9 -> 0 | C16: ='05 Other Outflows'!C9 -> 0 | D16: ='05 Other Outflows'!D9 -> 0 | E16: ='05 Other Outflows'!E9 -> 0 | F16: ='05 Other Outflows'!F9 -> 0 | G16: ='05 Other Outflows'!G9 -> 0 | H16: ='05 Other Outflows'!H9 -> 0 | I16: ='05 Other Outflows'!I9 -> 0 | ... N16: ='05 Other Outflows'!N9 -> 0 | O16: =SUM(B16:N16) -> 4500
A17: Total cash outflows | B17: =SUM(B11:B16) -> 5600 | C17: =SUM(C11:C16) -> 11485 | D17: =SUM(D11:D16) -> 13785 | E17: =SUM(E11:E16) -> 20070 | F17: =SUM(F11:F16) -> 17562.5 | G17: =SUM(G11:G16) -> 11485 | H17: =SUM(H11:H16) -> 9400 | I17: =SUM(I11:I16) -> 11882.5 | ... N17: =SUM(N11:N16) -> 18275 | O17: =SUM(B17:N17) -> 169600
A19: Net cash flow | B19: =B9-B17 -> 7400 | C19: =C9-C17 -> 2515 | D19: =D9-D17 -> -1285 | E19: =E9-E17 -> -7070 | F19: =F9-F17 -> -11562.5 | G19: =G9-G17 -> 2015 | H19: =H9-H17 -> 12100 | I19: =I9-I17 -> 1117.5 | ... N19: =N9-N17 -> -4775 | O19: =SUM(B19:N19) -> 6400
A20: Opening cash | B20: ='02 Assumptions'!$B$25 -> 17000 | C20: =B21 -> 24400 | D20: =C21 -> 26915 | E20: =D21 -> 25630 | F20: =E21 -> 18560 | G20: =F21 -> 6997.5 | H20: =G21 -> 9012.5 | I20: =H21 -> 21112.5 | J20: =I21 -> 22230 | ... N20: =M21 -> 28175
A21: Closing cash | B21: =B20+B19 -> 24400 | C21: =C20+C19 -> 26915 | D21: =D20+D19 -> 25630 | E21: =E20+E19 -> 18560 | F21: =F20+F19 -> 6997.5 | G21: =G20+G19 -> 9012.5 | H21: =H20+H19 -> 21112.5 | I21: =I20+I19 -> 22230 | ... N21: =N20+N19 -> 23400
A22: Minimum cash buffer (policy) | B22: ='02 Assumptions'!$B$24 -> 8000 | C22: ='02 Assumptions'!$B$24 -> 8000 | D22: ='02 Assumptions'!$B$24 -> 8000 | E22: ='02 Assumptions'!$B$24 -> 8000 | F22: ='02 Assumptions'!$B$24 -> 8000 | G22: ='02 Assumptions'!$B$24 -> 8000 | H22: ='02 Assumptions'!$B$24 -> 8000 | I22: ='02 Assumptions'!$B$24 -> 8000 | ... N22: ='02 Assumptions'!$B$24 -> 8000
A23: Surplus / (shortfall) vs buffer | B23: =B21-B22 -> 16400 | C23: =C21-C22 -> 18915 | D23: =D21-D22 -> 17630 | E23: =E21-E22 -> 10560 | F23: =F21-F22 -> -1002.5 | G23: =G21-G22 -> 1012.5 | H23: =H21-H22 -> 13112.5 | I23: =I21-I22 -> 14230 | ... N23: =N21-N22 -> 15400
A24: Status | B24: =IF(B21<B22,"SHORTAGE","OK") -> OK | C24: =IF(C21<C22,"SHORTAGE","OK") -> OK | D24: =IF(D21<D22,"SHORTAGE","OK") -> OK | E24: =IF(E21<E22,"SHORTAGE","OK") -> OK | F24: =IF(F21<F22,"SHORTAGE","OK") -> SHORTAGE | G24: =IF(G21<G22,"SHORTAGE","OK") -> OK | H24: =IF(H21<H22,"SHORTAGE","OK") -> OK | I24: =IF(I21<I22,"SHORTAGE","OK") -> OK | ... N24: =IF(N21<N22,"SHORTAGE","OK") -> OK
A26: READ THIS:
A27: The agent scans all 13 weeks and flags Week 5, where closing cash falls below the IDR 8,000 mn buffer. Drivers: a large USD import payment (Week 5) plus the top customer's collection slipping from Week 5 to Week 7. See sheet 06 for the FX view and sheet 07 for the recommended actions.

Sheet 04 AP USD Payables
A1: Accounts Payable — Vendor Payments & USD Exposure (13 weeks)
A2: Vendor bills mapped to payment week. USD import bills drive FX exposure. Source: D365 F&O AP / open POs (illustrative). Amounts in IDR mn (USD converted at spot).
A4: Bill No | B4: Vendor | C4: Category | D4: Terms (d) | E4: Due Date | F4: Pay Wk | G4: Currency | H4: Amount IDR mn | I4: USD Amount | J4: IDR mn value | K4: Deferrable? | L4: Notes
A5: AP-001 | B5: Shenzhen Micro Ltd | C5: Imported components | D5: 30 | E5: 46246 | F5: 2 | G5: USD | I5: 300000 | J5: =IF(G5="USD",I5*'02 Assumptions'!$B$16/1000000,H5) -> 5385 | K5: No | L5: USD LC settlement
A6: AP-002 | B6: Taipei Semicon Co | C6: Imported components | D6: 30 | E6: 46253 | F6: 3 | G6: USD | I6: 300000 | J6: =IF(G6="USD",I6*'02 Assumptions'!$B$16/1000000,H6) -> 5385 | K6: No
A7: AP-003 | B7: Osaka Precision KK | C7: Imported raw material | D7: 45 | E7: 46260 | F7: 4 | G7: USD | I7: 600000 | J7: =IF(G7="USD",I7*'02 Assumptions'!$B$16/1000000,H7) -> 10770 | K7: No
A8: AP-004 | B8: Shenzhen Micro Ltd | C8: Imported raw material (major shipment) | D8: 30 | E8: 46267 | F8: 5 | G8: USD | I8: 750000 | J8: =IF(G8="USD",I8*'02 Assumptions'!$B$16/1000000,H8) -> 13462.5 | K8: No | L8: LARGE LC settlement. Critical, non-deferrable. Main cash-outflow driver of Week 5.
A9: AP-005 | B9: Taipei Semicon Co | C9: Imported components | D9: 30 | E9: 46274 | F9: 6 | G9: USD | I9: 300000 | J9: =IF(G9="USD",I9*'02 Assumptions'!$B$16/1000000,H9) -> 5385 | K9: No
A10: AP-006 | B10: Osaka Precision KK | C10: Imported components | D10: 45 | E10: 46288 | F10: 8 | G10: USD | I10: 350000 | J10: =IF(G10="USD",I10*'02 Assumptions'!$B$16/1000000,H10) -> 6282.5 | K10: No
A11: AP-007 | B11: Shenzhen Micro Ltd | C11: Imported components | D11: 30 | E11: 46295 | F11: 9 | G11: USD | I11: 300000 | J11: =IF(G11="USD",I11*'02 Assumptions'!$B$16/1000000,H11) -> 5385 | K11: No
A12: AP-008 | B12: Taipei Semicon Co | C12: Imported components | D12: 30 | E12: 46302 | F12: 10 | G12: USD | I12: 250000 | J12: =IF(G12="USD",I12*'02 Assumptions'!$B$16/1000000,H12) -> 4487.5 | K12: No
A13: AP-009 | B13: Osaka Precision KK | C13: Imported components | D13: 45 | E13: 46316 | F13: 12 | G13: USD | I13: 350000 | J13: =IF(G13="USD",I13*'02 Assumptions'!$B$16/1000000,H13) -> 6282.5 | K13: No
A14: AP-010 | B14: Shenzhen Micro Ltd | C14: Imported raw material | D14: 30 | E14: 46323 | F14: 13 | G14: USD | I14: 500000 | J14: =IF(G14="USD",I14*'02 Assumptions'!$B$16/1000000,H14) -> 8975 | K14: No
A15: AP-011 | B15: PT Logistik Nusantara | C15: Logistics & freight | D15: 30 | E15: 46239 | F15: 1 | G15: IDR | H15: 4500 | J15: =IF(G15="USD",I15*'02 Assumptions'!$B$16/1000000,H15) -> 4500 | K15: No
A16: AP-012 | B16: PT Kemasan Prima | C16: Packaging | D16: 30 | E16: 46246 | F16: 2 | G16: IDR | H16: 5000 | J16: =IF(G16="USD",I16*'02 Assumptions'!$B$16/1000000,H16) -> 5000 | K16: Yes | L16: Deferrable within terms
A17: AP-013 | B17: PT Sumber Kimia | C17: Local materials | D17: 30 | E17: 46253 | F17: 3 | G17: IDR | H17: 4500 | J17: =IF(G17="USD",I17*'02 Assumptions'!$B$16/1000000,H17) -> 4500 | K17: No
A18: AP-014 | B18: PT Logistik Nusantara | C18: Logistics & freight | D18: 30 | E18: 46260 | F18: 4 | G18: IDR | H18: 5000 | J18: =IF(G18="USD",I18*'02 Assumptions'!$B$16/1000000,H18) -> 5000 | K18: No
A19: AP-015 | B19: PT Kemasan Prima | C19: Packaging | D19: 45 | E19: 46267 | F19: 5 | G19: IDR | H19: 3000 | J19: =IF(G19="USD",I19*'02 Assumptions'!$B$16/1000000,H19) -> 3000 | K19: Yes | L19: DEFERRABLE — candidate to move from Week 5 to Week 6 to protect the buffer without breaching vendor terms.
A20: AP-016 | B20: PT Sumber Kimia | C20: Local materials | D20: 30 | E20: 46274 | F20: 6 | G20: IDR | H20: 5000 | J20: =IF(G20="USD",I20*'02 Assumptions'!$B$16/1000000,H20) -> 5000 | K20: No
A21: AP-017 | B21: PT Logistik Nusantara | C21: Logistics & freight | D21: 30 | E21: 46281 | F21: 7 | G21: IDR | H21: 5500 | J21: =IF(G21="USD",I21*'02 Assumptions'!$B$16/1000000,H21) -> 5500 | K21: No
A22: AP-018 | B22: PT Kemasan Prima | C22: Packaging | D22: 30 | E22: 46288 | F22: 8 | G22: IDR | H22: 4500 | J22: =IF(G22="USD",I22*'02 Assumptions'!$B$16/1000000,H22) -> 4500 | K22: No
A23: AP-019 | B23: PT Sumber Kimia | C23: Local materials | D23: 30 | E23: 46295 | F23: 9 | G23: IDR | H23: 5000 | J23: =IF(G23="USD",I23*'02 Assumptions'!$B$16/1000000,H23) -> 5000 | K23: No
A24: AP-020 | B24: PT Logistik Nusantara | C24: Logistics & freight | D24: 30 | E24: 46302 | F24: 10 | G24: IDR | H24: 4500 | J24: =IF(G24="USD",I24*'02 Assumptions'!$B$16/1000000,H24) -> 4500 | K24: No
A25: AP-021 | B25: PT Kemasan Prima | C25: Packaging | D25: 30 | E25: 46309 | F25: 11 | G25: IDR | H25: 5000 | J25: =IF(G25="USD",I25*'02 Assumptions'!$B$16/1000000,H25) -> 5000 | K25: No
A26: AP-022 | B26: PT Sumber Kimia | C26: Local materials | D26: 30 | E26: 46316 | F26: 12 | G26: IDR | H26: 4500 | J26: =IF(G26="USD",I26*'02 Assumptions'!$B$16/1000000,H26) -> 4500 | K26: No
A27: AP-023 | B27: PT Logistik Nusantara | C27: Logistics & freight | D27: 30 | E27: 46323 | F27: 13 | G27: IDR | H27: 5000 | J27: =IF(G27="USD",I27*'02 Assumptions'!$B$16/1000000,H27) -> 5000 | K27: No
A29: TOTALS | H29: =SUMIF(G5:G27,"IDR",H5:H27) -> 61000 | I29: =SUMIF(G5:G27,"USD",I5:I27) -> 4000000 | J29: =SUM(J5:J27) -> 132800 | L29: I = total USD payables. H = total IDR payables. J = total payments (IDR mn).

Sheet 07 FX Scenarios
A1: USD Exposure & FX Scenario Simulator
A2: Net USD exposure and the cash impact of currency moves. Change the adverse % on sheet 01 to update every number here. Units: IDR mn (exposure also in USD).
A4: NET USD EXPOSURE
A5: USD payables — total (from sheet 03) | B5: ='04 AP USD Payables'!I29 -> 4000000 | C5: USD
A6: USD receivables — total (from sheet 02) | B6: ='03 AR Collections'!K32 -> 700000 | C6: USD
A7: Net USD exposure = payables - receivables | B7: =B5-B6 -> 3300000 | C7: USD
A8: Net exposure value @ spot (IDR mn) | B8: =B7*'02 Assumptions'!$B$16/1000000 -> 59235 | C8: IDR mn
A10: FX IMPACT IF WE DO NOTHING (impact on the full net exposure)
A11: Scenario | B11: Rate IDR/USD | C11: Move vs spot | D11: FX cash impact (IDR mn) | E11: Note
A12: Base case (spot) | B12: ='02 Assumptions'!$B$16 -> 17950 | C12: =B12-'02 Assumptions'!$B$16 -> 0 | D12: 0 | E12: Current rate, no move.
A13: Adverse: USD +3% | B13: ='02 Assumptions'!$B$20 -> 18488.5 | C13: =B13-'02 Assumptions'!$B$16 -> 538.5 | D13: =$B$7*('02 Assumptions'!$B$16-B13)/1000000 -> -1777.05 | E13: CFO tolerance breached.
A14: Stress: USD +6% | B14: ='02 Assumptions'!$B$21 -> 19027 | C14: =B14-'02 Assumptions'!$B$16 -> 1077 | D14: =$B$7*('02 Assumptions'!$B$16-B14)/1000000 -> -3554.1 | E14: Severe move (stress test).
A15: Forward-cover all | B15: ='02 Assumptions'!$B$17 -> 18120 | C15: =B15-'02 Assumptions'!$B$16 -> 170 | D15: =$B$7*('02 Assumptions'!$B$16-B15)/1000000 -> -561 | E15: Locked cost if fully hedged today (premium).
A16: Negative = extra cash cost. Impact = net exposure x (spot - scenario rate).
A18: RECOMMENDED FX ACTION
A19: Recommended forward-cover amount (USD) | B19: 2000000 | C19: USD
A20: % of net exposure covered | B20: =B19/B7 -> 0.60606061
A21: Locked rate (13-week forward) | B21: ='02 Assumptions'!$B$17 -> 18120
A22: Downside AVOIDED vs adverse move (IDR mn) | B22: =B19*('02 Assumptions'!$B$20-'02 Assumptions'!$B$16)/1000000 -> 1077
A23: Cost of certainty (forward premium, IDR mn) | B23: =B19*('02 Assumptions'!$B$17-'02 Assumptions'!$B$16)/1000000 -> 340
A24: Residual uncovered exposure (USD) | B24: =B7-B19 -> 1300000
A25: Residual downside at adverse (IDR mn) | B25: =(B7-B19)*('02 Assumptions'!$B$16-'02 Assumptions'!$B$20)/1000000 -> -700.05
A27: AGENT OPTION COMPARISON
A28: Option | B28: Action | C28: Downside avoided (IDR mn) | D28: Cost / premium (IDR mn) | E28: Liquidity effect | F28: Confidence*
A29: A. Do nothing | B29: Leave full exposure open | C29: 0 | D29: 0 | E29: Neutral now; full risk open | F29: Low*
A30: B. Forward-cover USD 2.0M (RECOMMENDED) | B30: Lock rate today, settle on due dates | C30: =B22 -> 1077 | D30: =B23 -> 340 | E30: No cash out now (forward) | F30: Med-High*
A31: C. Buy USD 2.0M spot now | B31: Pre-purchase USD today | C31: =B22 -> 1077 | D31: 0 | E31: WORSENS Week-5 cash (pay early) | F31: Medium*
A32: D. Hedge 50% of net | B32: Cover half the net exposure | C32: =B7*0.5*('02 Assumptions'!$B$20-'02 Assumptions'!$B$16)/1000000 -> 888.525 | D32: =B7*0.5*('02 Assumptions'!$B$17-'02 Assumptions'!$B$16)/1000000 -> 280.5 | E32: No cash out now (forward) | F32: Medium*
A34: *Confidence is an ILLUSTRATIVE placeholder for the demo, not a validated model output. Do not present as a measured accuracy.
A35: Key point for the CFO: buying USD early protects FX but HURTS Week-5 liquidity. A forward locks the rate with no cash out today, so it fixes FX without making the liquidity gap worse.

Sheet 08 Recommendation
A1: Agent Recommendation & CFO Decision Card
A2: What the agent recommends, why, and the financial impact — pulled live from sheets 05 and 06. The journal is illustrative and needs Controller sign-off.
A4: SITUATION (from the 13-week forecast)
A5: Lowest projected closing cash (IDR mn) | B5: =MIN('06 Cash Forecast 13W'!B21:N21) -> 6997.5
A6: Week of the low point | B6: Week 5 (31-Aug to 06-Sep 2026)
A7: Minimum cash buffer (policy, IDR mn) | B7: ='02 Assumptions'!$B$24 -> 8000
A8: Shortfall below buffer at Week 5 (IDR mn) | B8: ='06 Cash Forecast 13W'!F23 -> -1002.5
A9: Net USD exposure (USD) | B9: ='07 FX Scenarios'!B7 -> 3300000
A10: FX downside if USD +3% & unhedged (IDR mn) | B10: ='07 FX Scenarios'!D13 -> -1777.05
A12: RECOMMENDATION — two separate problems, two separate fixes
A13: 1) LIQUIDITY (fix the Week-5 buffer breach)
A14: • Defer deferrable IDR vendor payment from W5 to W6 | C14: IDR 3,000 mn packaging bill (AP-015), still within terms | E14: Restores buffer immediately
A15: • Accelerate part of Customer A collection into W5 | C15: Chase the top customer earlier / offer early-pay discount | E15: Adds a second safety margin
A16: • Keep committed credit line as backstop only | C16: Do NOT draw unless the above are insufficient | E16: Avoids interest cost
A18: 2) FX (cap the USD cost, without hurting liquidity)
A19: • Forward-cover USD 2.0M at the 13-week forward | C19: Locks the rate today, no cash out now | E19: Downside avoided ~ see B/below
A20: • Leave the export USD receivables as a natural hedge | C20: USD 0.7M inflow offsets USD payables | E20: Reduces net exposure
A21: • Review the CFO USD/IDR tolerance band | C21: Confirm the +3% trigger is still policy | E21: Governance
A23: EXPECTED IMPACT (calculated)
A24: FX downside avoided by forward-cover (IDR mn) | B24: ='07 FX Scenarios'!B22 -> 1077
A25: Cost of certainty (forward premium, IDR mn) | B25: ='07 FX Scenarios'!B23 -> 340
A26: Week-5 buffer after deferring the IDR bill (IDR mn) | B26: ='06 Cash Forecast 13W'!F21+3000 -> 9997.5 | C26: Closing W5 + IDR 3,000 mn deferred. Now above the 8,000 buffer.
A28: CFO DECISION CARD
A29: Requested by: Cash Flow Forecast Agent | Approval: CFO + Treasury Manager (dual control)
A30: [ Approve ] [ Modify amount ] [ Run simulation ] [ Ask why ] [ Delegate to Treasury ] [ Reject ]
A32: ILLUSTRATIVE JOURNAL — NEEDS CONTROLLER SIGN-OFF
A33: On settlement of the USD purchase / forward (simplified, illustrative only):
A34: Dr | B34: Foreign currency (USD) bank / AP settled | E34: at agreed rate
A35: Cr | B35: IDR bank account | E35: USD amount x settlement rate
A36: Dr/Cr | B36: Realised FX gain / (loss) | E36: difference vs booking rate
A37: Treatment depends on PSAK 10 / IAS 21 and, if hedge-designated, PSAK 71 / IFRS 9. Confirm with the Controller before any demo claim about accounting.
